Workbook
Name _P: #REF!
Name basic: #REF!
Name Company: #REF!
Name CurrYr: [1]HQ!$B$19
Name CurrYr: [2]HQ!$B$19
Name CurrYrFCVersion: [1]HQ!$B$20
Name CurrYrFCVersion: [2]HQ!$B$20
Name dental: #REF!
Name dentcode: #REF!
Name Depart: #REF!
Name Facility: #REF!
Name FillColMatch: '[1]OC-Fill'!$B$1:$NB$1
Name FillColMatch: '[2]OC-Fill'!$B$1:$NB$1
Name FillDataArray: INDIRECT(RIGHT('[1]OC-Fill'!$NI$6,LEN('[1]OC-Fill'!$NI$6)-1))
Name FillDataArray: INDIRECT(RIGHT('[2]OC-Fill'!$NI$6,LEN('[2]OC-Fill'!$NI$6)-1))
Name FillRowMatch: INDIRECT(RIGHT('[1]OC-Fill'!$NI$7,LEN('[1]OC-Fill'!$NI$7)-1))
Name FillRowMatch: INDIRECT(RIGHT('[2]OC-Fill'!$NI$7,LEN('[2]OC-Fill'!$NI$7)-1))
Name FillSNFColMatch: '[1]OC-SNF Fill'!$B$1:$CX$1
Name FillSNFColMatch: '[2]OC-SNF Fill'!$B$1:$ET$1
Name FillSNFDataArray: '[1]OC-SNF Fill'!$B$9:$CX$15
Name FillSNFDataArray: '[2]OC-SNF Fill'!$B$9:$ET$30
Name FillSNFRowMatch: '[1]OC-SNF Fill'!$CZ$9:$CZ$15
Name FillSNFRowMatch: '[2]OC-SNF Fill'!$EV$9:$EV$30
Name health: #REF!
Name jobcode: #REF!
Name MainColMatch: '[1]OC-Main'!$B$1:$LD$1
Name MainColMatch: '[2]OC-Main'!$B$1:$LS$1
Name MainDataArray: '[1]OC-Main'!$B$9:$LD$74
Name MainDataArray: '[2]OC-Main'!$B$9:$LS$74
Name MainRowMatch: '[1]OC-Main'!$LE$9:$LE$74
Name MainRowMatch: '[2]OC-Main'!$LT$9:$LT$74
Name medcode: #REF!
Name NextYr: [1]HQ!$B$21
Name NextYr: [2]HQ!$B$21
Name parttm: #REF!
Name pension: #REF!
Name RaiseColMatch: '[1]OC-Raise'!$B$1:$D$1
Name RaiseColMatch: '[2]OC-Raise'!$B$1:$D$1
Name RaiseDataArray: INDIRECT(RIGHT('[1]OC-Raise'!$I$2,LEN('[1]OC-Raise'!$I$2)-1))
Name RaiseDataArray: INDIRECT(RIGHT('[2]OC-Raise'!$I$2,LEN('[2]OC-Raise'!$I$2)-1))
Name RaiseRowMatch: INDIRECT(RIGHT('[1]OC-Raise'!$I$3,LEN('[1]OC-Raise'!$I$3)-1))
Name RaiseRowMatch: INDIRECT(RIGHT('[2]OC-Raise'!$I$3,LEN('[2]OC-Raise'!$I$3)-1))
Name vachrs: #REF!
Name WASbasic: #REF!
Name WASmeddent: #REF!
Name workcomp: #REF!
Name workcompclass: #REF!

Sheet CrossfireHiddenWorksheet
A3: 84221d58-7537-44f4-90dc-604bd307e526 | B3: 53db68a9-4703-4f32-b1c0-58314592b1f6 | C3: 27bafa95-35d5-46f4-a19f-bec473f489f7
A4: 1 | B4: 7 | C4: 13
A5: ='OC-SNF PMix Anc Days'!$6:$6 -> 100-61 Skilled Nursing Facility | B5: 13 | C5: ='OC-SNF PMix Anc Days'!$D:$D -> Jan-2025 | D5: 1 | E5: ='OC-SNF PMix Anc Days'!$D$4 -> Budget 2025 | F5: 459 | G5: ='OC-Days'!$14:$14 -> Dec-2022 | H5: 1 | I5: ='OC-Days'!$B:$B -> 31 | J5: 37 | M5: ='OC-Res Days'!$6:$6 -> 2185.5 | N5: 13 | O5: ='OC-Res Days'!$B:$B -> Jan-2025 | P5: 1 | Q5: ='OC-Res Days'!$B$4 -> Budget 2025 | R5: 55
A6: ='OC-SNF PMix Anc Days'!$7:$7 -> 100-61 Skilled Nursing Facility | B6: 14 | C6: ='OC-SNF PMix Anc Days'!$E:$E -> 55.86 | D6: 2 | E6: ='OC-SNF PMix Anc Days'!$E$4 -> Budget 2025 | F6: 460 | G6: ='OC-Days'!$13:$13 -> Nov-2022 | H6: 2 | M6: ='OC-Res Days'!$7:$7 -> 1302 | N6: 217 | O6: ='OC-Res Days'!$C:$C -> 1974 | P6: 2 | Q6: ='OC-Res Days'!$C$4 -> Budget 2025 | R6: 56
A7: ='OC-SNF PMix Anc Days'!$8:$8 -> 100-61 Skilled Nursing Facility | B7: 15 | C7: ='OC-SNF PMix Anc Days'!$F:$F -> 0 | D7: 3 | E7: ='OC-SNF PMix Anc Days'!$F$4 -> Budget 2025 | F7: 461 | G7: ='OC-Days'!$12:$12 -> Oct-2022 | H7: 3 | M7: ='OC-Res Days'!$8:$8 -> 2077 | N7: 218 | O7: ='OC-Res Days'!$D:$D -> 1302 | P7: 3 | Q7: ='OC-Res Days'!$D$4 -> Budget 2025 | R7: 57
A8: ='OC-SNF PMix Anc Days'!$9:$9 -> 100-61 Skilled Nursing Facility | B8: 16 | C8: ='OC-SNF PMix Anc Days'!$G:$G -> 2550.009 | D8: 4 | E8: ='OC-SNF PMix Anc Days'!$G$4 -> Budget 2025 | F8: 462 | G8: ='OC-Days'!$11:$11 -> Sep-2022 | H8: 4 | M8: ='OC-Res Days'!$9:$9 -> 5270 | N8: 219 | O8: ='OC-Res Days'!$E:$E -> 1860 | P8: 4 | Q8: ='OC-Res Days'!$E$4 -> Budget 2025 | R8: 58
A9: ='OC-SNF PMix Anc Days'!$10:$10 -> 100-61 Skilled Nursing Facility | B9: 17 | C9: ='OC-SNF PMix Anc Days'!$H:$H -> 0 | D9: 5 | E9: ='OC-SNF PMix Anc Days'!$H$4 -> Budget 2025 | F9: 463 | G9: ='OC-Days'!$10:$10 -> Aug-2022 | H9: 5 | M9: ='OC-Res Days'!$10:$10 -> 2790 | N9: 220 | O9: ='OC-Res Days'!$F:$F -> 5053 | P9: 5 | Q9: ='OC-Res Days'!$F$4 -> Budget 2025 | R9: 59
A10: ='OC-SNF PMix Anc Days'!$11:$11 -> 100-61 Skilled Nursing Facility | B10: 18 | C10: ='OC-SNF PMix Anc Days'!$I:$I -> 1289.967 | D10: 6 | E10: ='OC-SNF PMix Anc Days'!$I$4 -> Budget 2025 | F10: 464 | G10: ='OC-Days'!$9:$9 -> Jul-2022 | H10: 6 | M10: ='OC-Res Days'!$11:$11 -> 1798 | N10: 221 | O10: ='OC-Res Days'!$G:$G -> 2700 | P10: 6 | Q10: ='OC-Res Days'!$G$4 -> Budget 2025 | R10: 60
A11: ='OC-SNF PMix Anc Days'!$12:$12 -> 100-62 Skilled Nursing - TCU | B11: 19 | C11: ='OC-SNF PMix Anc Days'!$J:$J -> 93.1798 | D11: 7 | E11: ='OC-SNF PMix Anc Days'!$J$4 -> Budget 2025 | F11: 465 | G11: ='OC-Days'!$8:$8 -> Jun-2022 | H11: 7 | M11: ='OC-Res Days'!$12:$12 -> 3100 | N11: 222 | O11: ='OC-Res Days'!$H:$H -> 1798 | P11: 7 | Q11: ='OC-Res Days'!$H$4 -> Budget 2025 | R11: 61
A12: ='OC-SNF PMix Anc Days'!$13:$13 -> 100-62 Skilled Nursing - TCU | B12: 20 | C12: ='OC-SNF PMix Anc Days'!$K:$K -> 1054.062 | D12: 8 | E12: ='OC-SNF PMix Anc Days'!$K$4 -> Budget 2025 | F12: 466 | G12: ='OC-Days'!$7:$7 -> May-2022 | H12: 8 | M12: ='OC-Res Days'!$13:$13 -> 2635 | N12: 223 | O12: ='OC-Res Days'!$I:$I -> 3069 | P12: 8 | Q12: ='OC-Res Days'!$I$4 -> Budget 2025 | R12: 62
A13: ='OC-SNF PMix Anc Days'!$14:$14 -> 100-62 Skilled Nursing - TCU | B13: 21 | C13: ='OC-SNF PMix Anc Days'!$L:$L -> 270 | D13: 9 | E13: ='OC-SNF PMix Anc Days'!$L$4 -> Budget 2025 | F13: 467 | G13: ='OC-Days'!$6:$6 -> Apr-2022 | H13: 9 | M13: ='OC-Res Days'!$14:$14 -> 3844 | N13: 224 | O13: ='OC-Res Days'!$J:$J -> 2520 | P13: 9 | Q13: ='OC-Res Days'!$J$4 -> Budget 2025 | R13: 63
A14: ='OC-SNF PMix Anc Days'!$15:$15 -> 100-62 Skilled Nursing - TCU | B14: 22 | C14: ='OC-SNF PMix Anc Days'!$M:$M -> 0 | D14: 10 | E14: ='OC-SNF PMix Anc Days'!$M$4 -> Budget 2025 | F14: 468 | G14: ='OC-Days'!$5:$5 -> Mar-2022 | H14: 10 | M14: ='OC-Res Days'!$15:$15 -> 4123 | N14: 225 | O14: ='OC-Res Days'!$K:$K -> 3844 | P14: 10 | Q14: ='OC-Res Days'!$K$4 -> Budget 2025 | R14: 64
A15: ='OC-SNF PMix Anc Days'!$16:$16 -> 100-62 Skilled Nursing - TCU | B15: 23 | C15: ='OC-SNF PMix Anc Days'!$N:$N -> 59.94 | D15: 11 | E15: ='OC-SNF PMix Anc Days'!$N$4 -> Budget 2025 | F15: 469 | G15: ='OC-Days'!$4:$4 -> Feb-2022 | H15: 11 | M15: ='OC-Res Days'!$16:$16 -> 1395 | N15: 226 | O15: ='OC-Res Days'!$L:$L -> 3990 | P15: 11 | Q15: ='OC-Res Days'!$L$4 -> Budget 2025 | R15: 65
A16: ='OC-SNF PMix Anc Days'!$17:$17 -> 100-62 Skilled Nursing - TCU | B16: 24 | C16: ='OC-SNF PMix Anc Days'!$O:$O -> 0 | D16: 12 | E16: ='OC-SNF PMix Anc Days'!$O$4 -> Budget 2025 | F16: 470 | G16: ='OC-Days'!$3:$3 -> Jan-2022 | H16: 12 | M16: ='OC-Res Days'!$17:$17 -> 30519.5 | N16: 227 | O16: ='OC-Res Days'!$M:$M -> 1395 | P16: 12 | Q16: ='OC-Res Days'!$M$4 -> Budget 2025 | R16: 66
A17: ='OC-SNF PMix Anc Days'!$18:$18 -> 200-61 Skilled Nursing Facility | B17: 25 | E17: ='OC-SNF PMix Anc Days'!$D$5 -> Jan-2025 | F17: 471 | G17: ='OC-Days'!$26:$26 -> Dec-2023 | H17: 13 | M17: ='OC-Res Days'!$18:$18 -> 2201 | N17: 228 | O17: ='OC-Res Days'!$O:$O -> 958.5 | P17: 359 | Q17: ='OC-Res Days'!$B$5 -> Jan-2025 | R17: 67
A18: ='OC-SNF PMix Anc Days'!$19:$19 -> 200-61 Skilled Nursing Facility | B18: 26 | E18: ='OC-SNF PMix Anc Days'!$E$5 -> Feb-2025 | F18: 472 | G18: ='OC-Days'!$25:$25 -> Nov-2023 | H18: 14 | M18: ='OC-Res Days'!$19:$19 -> 4154 | N18: 229 | O18: ='OC-Res Days'!$P:$P -> 71 | P18: 360 | Q18: ='OC-Res Days'!$C$5 -> Feb-2025 | R18: 68
A19: ='OC-SNF PMix Anc Days'!$20:$20 -> 200-61 Skilled Nursing Facility | B19: 27 | E19: ='OC-SNF PMix Anc Days'!$F$5 -> Mar-2025 | F19: 473 | G19: ='OC-Days'!$24:$24 -> Oct-2023 | H19: 15 | M19: ='OC-Res Days'!$20:$20 -> 2573 | N19: 230 | O19: ='OC-Res Days'!$Q:$Q -> 134 | P19: 361 | Q19: ='OC-Res Days'!$D$5 -> Mar-2025 | R19: 69
A20: ='OC-SNF PMix Anc Days'!$21:$21 -> 200-61 Skilled Nursing Facility | B20: 28 | E20: ='OC-SNF PMix Anc Days'!$G$5 -> Apr-2025 | F20: 474 | G20: ='OC-Days'!$23:$23 -> Sep-2023 | H20: 16 | M20: ='OC-Res Days'!$21:$21 -> 728.5 | N20: 231 | O20: ='OC-Res Days'!$R:$R -> 83 | P20: 362 | Q20: ='OC-Res Days'!$E$5 -> Apr-2025 | R20: 70
A21: ='OC-SNF PMix Anc Days'!$22:$22 -> 200-61 Skilled Nursing Facility | B21: 29 | E21: ='OC-SNF PMix Anc Days'!$H$5 -> May-2025 | F21: 475 | G21: ='OC-Days'!$22:$22 -> Aug-2023 | H21: 17 | M21: ='OC-Res Days'!$22:$22 -> 1162.5 | N21: 232 | O21: ='OC-Res Days'!$S:$S -> 23.5 | P21: 363 | Q21: ='OC-Res Days'!$F$5 -> May-2025 | R21: 71
A22: ='OC-SNF PMix Anc Days'!$23:$23 -> 200-61 Skilled Nursing Facility | B22: 30 | E22: ='OC-SNF PMix Anc Days'!$I$5 -> Jun-2025 | F22: 476 | G22: ='OC-Days'!$21:$21 -> Jul-2023 | H22: 18 | M22: ='OC-Res Days'!$23:$23 -> 10819 | N22: 233 | O22: ='OC-Res Days'!$T:$T -> 37.5 | P22: 364 | Q22: ='OC-Res Days'!$G$5 -> Jun-2025 | R22: 72
A23: ='OC-SNF PMix Anc Days'!$24:$24 -> 324-61 Skilled Nursing Facility | B23: 31 | E23: ='OC-SNF PMix Anc Days'!$J$5 -> Jul-2025 | F23: 477 | G23: ='OC-Days'!$20:$20 -> Jun-2023 | H23: 19 | M23: ='OC-Res Days'!$24:$24 -> 1085 | N23: 234 | O23: ='OC-Res Days'!$U:$U -> 349 | P23: 365 | Q23: ='OC-Res Days'!$H$5 -> Jul-2025 | R23: 73
A24: ='OC-SNF PMix Anc Days'!$25:$25 -> 324-61 Skilled Nursing Facility | B24: 32 | E24: ='OC-SNF PMix Anc Days'!$K$5 -> Aug-2025 | F24: 478 | G24: ='OC-Days'!$19:$19 -> May-2023 | H24: 20 | M24: ='OC-Res Days'!$25:$25 -> 3503 | N24: 235 | O24: ='OC-Res Days'!$V:$V -> 35 | P24: 366 | Q24: ='OC-Res Days'!$I$5 -> Aug-2025 | R24: 74
A25: ='OC-SNF PMix Anc Days'!$26:$26 -> 324-61 Skilled Nursing Facility | B25: 33 | E25: ='OC-SNF PMix Anc Days'!$L$5 -> Sep-2025 | F25: 479 | G25: ='OC-Days'!$18:$18 -> Apr-2023 | H25: 21 | M25: ='OC-Res Days'!$26:$26 -> 1023 | N25: 236 | O25: ='OC-Res Days'!$W:$W -> 113 | P25: 367 | Q25: ='OC-Res Days'!$J$5 -> Sep-2025 | R25: 75
A26: ='OC-SNF PMix Anc Days'!$27:$27 -> 324-61 Skilled Nursing Facility | B26: 34 | E26: ='OC-SNF PMix Anc Days'!$M$5 -> Oct-2025 | F26: 480 | G26: ='OC-Days'!$17:$17 -> Mar-2023 | H26: 22 | M26: ='OC-Res Days'!$27:$27 -> 2263 | N26: 237 | O26: ='OC-Res Days'!$X:$X -> 33 | P26: 368 | Q26: ='OC-Res Days'!$K$5 -> Oct-2025 | R26: 76
A27: ='OC-SNF PMix Anc Days'!$28:$28 -> 324-61 Skilled Nursing Facility | B27: 35 | E27: ='OC-SNF PMix Anc Days'!$N$5 -> Nov-2025 | F27: 481 | G27: ='OC-Days'!$16:$16 -> Feb-2023 | H27: 23 | M27: ='OC-Res Days'!$28:$28 -> 7874 | N27: 238 | O27: ='OC-Res Days'!$Y:$Y -> 73 | P27: 369 | Q27: ='OC-Res Days'!$L$5 -> Nov-2025 | R27: 77
A28: ='OC-SNF PMix Anc Days'!$29:$29 -> 324-61 Skilled Nursing Facility | B28: 36 | E28: ='OC-SNF PMix Anc Days'!$O$5 -> Dec-2025 | F28: 482 | G28: ='OC-Days'!$15:$15 -> Jan-2023 | H28: 24 | M28: ='OC-Res Days'!$29:$29 -> 372 | N28: 239 | O28: ='OC-Res Days'!$Z:$Z -> 254 | P28: 370 | Q28: ='OC-Res Days'!$M$5 -> Dec-2025 | R28: 78
A29: ='OC-SNF PMix Anc Days'!$30:$30 -> 810-61 Skilled Nursing Facility | B29: 37 | E29: ='OC-SNF PMix Anc Days'!$B$6 -> Rev_Asm_SNF_Payer_Mix.SNF_Ancillary_Medicare_A | F29: 483 | G29: ='OC-Days'!$30:$30 -> Apr-2024 | H29: 25 | M29: ='OC-Res Days'!$30:$30 -> 2046 | N29: 240 | Q29: ='OC-Res Days'!$A$6 -> 100-21 Villas/Cottages | R29: 163
A30: ='OC-SNF PMix Anc Days'!$31:$31 -> 810-61 Skilled Nursing Facility | B30: 38 | E30: ='OC-SNF PMix Anc Days'!$B$7 -> Rev_Asm_SNF_Payer_Mix.SNF_Ancillary_Medicare_Adv | F30: 484 | G30: ='OC-Days'!$27:$27 -> Jan-2024 | H30: 26 | M30: ='OC-Res Days'!$31:$31 -> 341 | N30: 241 | Q30: ='OC-Res Days'!$B$3 -> Forecasted Resident Days | R30: 205
A31: ='OC-SNF PMix Anc Days'!$32:$32 -> 810-61 Skilled Nursing Facility | B31: 39 | E31: ='OC-SNF PMix Anc Days'!$B$8 -> Rev_Asm_SNF_Payer_Mix.SNF_Ancillary_Medicaid | F31: 485 | G31: ='OC-Days'!$28:$28 -> Feb-2024 | H31: 27 | M31: ='OC-Res Days'!$32:$32 -> 2759 | N31: 242 | Q31: ='OC-Res Days'!$C$3 -> Forecasted Resident Days | R31: 206
A32: ='OC-SNF PMix Anc Days'!$33:$33 -> 810-61 Skilled Nursing Facility | B32: 40 | E32: ='OC-SNF PMix Anc Days'!$B$9 -> Rev_Asm_SNF_Payer_Mix.SNF_Ancillary_Insurance | F32: 486 | G32: ='OC-Days'!$29:$29 -> Mar-2024 | H32: 28 | M32: ='OC-Res Days'!$33:$33 -> 1147 | N32: 243 | Q32: ='OC-Res Days'!$D$3 -> Forecasted Resident Days | R32: 207
A33: ='OC-SNF PMix Anc Days'!$34:$34 -> 810-61 Skilled Nursing Facility | B33: 41 | E33: ='OC-SNF PMix Anc Days'!$B$10 -> Rev_Asm_SNF_Payer_Mix.SNF_Ancillary_Private_Pay | F33: 487 | G33: ='OC-Days'!$31:$31 -> May-2024 | H33: 29 | M33: ='OC-Res Days'!$34:$34 -> 248 | N33: 244 | Q33: ='OC-Res Days'!$E$3 -> Forecasted Resident Days | R33: 208
A34: ='OC-SNF PMix Anc Days'!$35:$35 -> 810-61 Skilled Nursing Facility | B34: 42 | E34: ='OC-SNF PMix Anc Days'!$B$11 -> Rev_Asm_SNF_Payer_Mix.SNF_Ancillary_Hospice | F34: 488 | G34: ='OC-Days'!$32:$32 -> Jun-2024 | H34: 30 | M34: ='OC-Res Days'!$35:$35 -> 1395 | N34: 245 | Q34: ='OC-Res Days'!$F$3 -> Forecasted Resident Days | R34: 209
A35: ='OC-SNF PMix Anc Days'!$36:$36 -> 840-61 Skilled Nursing Facility | B35: 50 | E35: ='OC-SNF PMix Anc Days'!$B$12 -> Rev_Asm_SNF_Payer_Mix.SNF_Ancillary_Medicare_A | F35: 490 | G35: ='OC-Days'!$33:$33 -> Jul-2024 | H35: 31 | M35: ='OC-Res Days'!$36:$36 -> 0 | N35: 246 | Q35: ='OC-Res Days'!$G$3 -> Forecasted Resident Days | R35: 210
A36: ='OC-SNF PMix Anc Days'!$37:$37 -> 840-61 Skilled Nursing Facility | B36: 51 | E36: ='OC-SNF PMix Anc Days'!$B$13 -> Rev_Asm_SNF_Payer_Mix.SNF_Ancillary_Medicare_Adv | F36: 491 | G36: ='OC-Days'!$34:$34 -> Aug-2024 | H36: 32 | M36: ='OC-Res Days'!$37:$37 -> 0 | N36: 247 | Q36: ='OC-Res Days'!$H$3 -> Forecasted Resident Days | R36: 211
A37: ='OC-SNF PMix Anc Days'!$38:$38 -> 840-61 Skilled Nursing Facility | B37: 52 | E37: ='OC-SNF PMix Anc Days'!$B$14 -> Rev_Asm_SNF_Payer_Mix.SNF_Ancillary_Medicaid | F37: 492 | G37: ='OC-Days'!$35:$35 -> Sep-2024 | H37: 33 | M37: ='OC-Res Days'!$38:$38 -> 2883 | N37: 248 | Q37: ='OC-Res Days'!$I$3 -> Forecasted Resident Days | R37: 212
A38: ='OC-SNF PMix Anc Days'!$39:$39 -> 840-61 Skilled Nursing Facility | B38: 53 | E38: ='OC-SNF PMix Anc Days'!$B$15 -> Rev_Asm_SNF_Payer_Mix.SNF_Ancillary_Insurance | F38: 493 | G38: ='OC-Days'!$36:$36 -> Oct-2024 | H38: 34 | M38: ='OC-Res Days'!$39:$39 -> 1426 | N38: 249 | Q38: ='OC-Res Days'!$J$3 -> Forecasted Resident Days | R38: 213
A39: ='OC-SNF PMix Anc Days'!$40:$40 -> 840-61 Skilled Nursing Facility | B39: 54 | E39: ='OC-SNF PMix Anc Days'!$B$16 -> Rev_Asm_SNF_Payer_Mix.SNF_Ancillary_Private_Pay | F39: 494 | G39: ='OC-Days'!$37:$37 -> Nov-2024 | H39: 35 | M39: ='OC-Res Days'!$40:$40 -> 496 | N39: 250 | Q39: ='OC-Res Days'!$K$3 -> Forecasted Resident Days | R39: 214
A40: ='OC-SNF PMix Anc Days'!$41:$41 -> 840-61 Skilled Nursing Facility | B40: 55 | E40: ='OC-SNF PMix Anc Days'!$B$17 -> Rev_Asm_SNF_Payer_Mix.SNF_Ancillary_Hospice | F40: 495 | G40: ='OC-Days'!$38:$38 -> Dec-2024 | H40: 36 | M40: ='OC-Res Days'!$41:$41 -> 2650.5 | N40: 251 | Q40: ='OC-Res Days'!$L$3 -> Forecasted Resident Days | R40: 215
A41: ='OC-SNF PMix Anc Days'!$42:$42 -> 0 | B41: 56 | E41: ='OC-SNF PMix Anc Days'!$B$18 -> Rev_Asm_SNF_Payer_Mix.SNF_Ancillary_Medicare_A | F41: 497 | G41: ='OC-Days'!$39:$39 -> Jan-2025 | H41: 38 | M41: ='OC-Res Days'!$42:$42 -> 4092 | N41: 252 | Q41: ='OC-Res Days'!$M$3 -> Forecasted Resident Days | R41: 216
E42: ='OC-SNF PMix Anc Days'!$B$19 -> Rev_Asm_SNF_Payer_Mix.SNF_Ancillary_Medicare_Adv | F42: 498 | G42: ='OC-Days'!$40:$40 -> Feb-2025 | H42: 39 | M42: ='OC-Res Days'!$43:$43 -> 2991.5 | N42: 253 | Q42: ='OC-Res Days'!$A$7 -> 100-22 Villas/Cottages B (AMV=Courtyard Homes, BV=BV West, APKS=Patio Homes) | R42: 288
...

Sheet OfficeConnectCellHighlights

Sheet 2025 Load
A1: Qlik Load | E1: Qlik Load | G1: Qlik Load | J1: Processing | N1: Processing | P1: Processing | S1: Processing | U1: Processing | X1: Processing | AA1: Check
A2: f(x) | B2: f(x) | C2: f(x) | D2: f(x) | E2: f(x) | F2: f(x) | G2: f(x) | H2: f(x) | J2: Copy/Paste from 2024 CCRC Budget Occupancy.xlsx > 2024 Load tab > Filtered to exclude facilities 61 and 62 | S2: f(x) | V2: Adaptive | Z2: Row Counts
A3: StartDate | B3: EndDate | C3: PayerName | D3: PlanName | E3: CampusName | F3: LevelOfCareName | G3: BuildingName | H3: BudgetPlanDays | J3: StartDate | K3: EndDate | L3: EntityCode | M3: FacilityCode | N3: FullOrgDesc | O3: BudgetAvailablePerDay | P3: BudgetResidentDaysPerDay | Q3: notes | S3: # Ent-Fac-PMix | U3: Ent-Fac-PMix | V3: Entity | W3: Ent | X3: Fac | Y3: PMix | Z3: Should be | AA3: Is | AB3: Delta
A4: =J4 -> 45658 | B4: =K4 -> 46022 | C4: =_xlfn.XLOOKUP($L4&"-"&$M4,REF!$J$2:$J$61,REF!B$2:B$61) -> PRIVATE PAY | D4: =_xlfn.XLOOKUP($L4&"-"&$M4,REF!$J$2:$J$61,REF!C$2:C$61) -> PPM IL | E4: =_xlfn.XLOOKUP($L4&"-"&$M4,REF!$J$2:$J$61,REF!D$2:D$61) -> ASBURY METHODIST VILLAGE | F4: =_xlfn.XLOOKUP($L4&"-"&$M4,REF!$J$2:$J$61,REF!E$2:E$61) -> AMV INDEPENDENT LIVING | G4: =_xlfn.XLOOKUP($L4&"-"&$M4,REF!$J$2:$J$61,REF!F$2:F$61) -> VILLAS | H4: =P4 -> 70.5 | J4: 45658 | K4: 46022 | L4: 100 | M4: 21 | N4: AComm\AComm LTC\MD\AMV\IL AMV\Villas | O4: 73 | P4: 70.5 | U4: =W4&X4&Y4 -> 10061Medicare A | V4: 100-61 Skilled Nursing Facility | W4: =VALUE(LEFT(V4,3)) -> 100 | X4: =VALUE(MID(V4,5,2)) -> 61 | Y4: Medicare A | Z4: 5 | AA4: =COUNTIFS($W$73:$W$136,W4,$X$73:$X$136,X4,$Y$73:$Y$136,Y4) -> 1 | AB4: =AA4-Z4 -> -4
A5: =J5 -> 45658 | B5: =K5 -> 46022 | C5: =_xlfn.XLOOKUP($L5&"-"&$M5,REF!$J$2:$J$61,REF!B$2:B$61) -> PRIVATE PAY | D5: =_xlfn.XLOOKUP($L5&"-"&$M5,REF!$J$2:$J$61,REF!C$2:C$61) -> PPM IL | E5: =_xlfn.XLOOKUP($L5&"-"&$M5,REF!$J$2:$J$61,REF!D$2:D$61) -> ASBURY METHODIST VILLAGE | F5: =_xlfn.XLOOKUP($L5&"-"&$M5,REF!$J$2:$J$61,REF!E$2:E$61) -> AMV INDEPENDENT LIVING | G5: =_xlfn.XLOOKUP($L5&"-"&$M5,REF!$J$2:$J$61,REF!F$2:F$61) -> COURTYARD HOMES | H5: =P5 -> 42 | J5: 45658 | K5: 46022 | L5: 100 | M5: 22 | N5: AComm\AComm LTC\MD\AMV\IL AMV\CH | O5: 43 | P5: 42 | U5: =W5&X5&Y5 -> 10061Medicare Advantage | V5: 100-61 Skilled Nursing Facility | W5: =VALUE(LEFT(V5,3)) -> 100 | X5: =VALUE(MID(V5,5,2)) -> 61 | Y5: Medicare Advantage | Z5: 5 | AA5: =COUNTIFS($W$73:$W$136,W5,$X$73:$X$136,X5,$Y$73:$Y$136,Y5) -> 0 | AB5: =AA5-Z5 -> -5
A6: =J6 -> 45658 | B6: =K6 -> 45716 | C6: =_xlfn.XLOOKUP($L6&"-"&$M6,REF!$J$2:$J$61,REF!B$2:B$61) -> PRIVATE PAY | D6: =_xlfn.XLOOKUP($L6&"-"&$M6,REF!$J$2:$J$61,REF!C$2:C$61) -> PPM IL | E6: =_xlfn.XLOOKUP($L6&"-"&$M6,REF!$J$2:$J$61,REF!D$2:D$61) -> ASBURY METHODIST VILLAGE | F6: =_xlfn.XLOOKUP($L6&"-"&$M6,REF!$J$2:$J$61,REF!E$2:E$61) -> AMV INDEPENDENT LIVING | G6: =_xlfn.XLOOKUP($L6&"-"&$M6,REF!$J$2:$J$61,REF!F$2:F$61) -> TROTT APARTMENTS | H6: =P6 -> 61 | J6: 45658 | K6: 45716 | L6: 100 | M6: 31 | N6: AComm\AComm LTC\MD\AMV\IL AMV\Trott Apt | O6: 109 | P6: 61 | U6: =W6&X6&Y6 -> 10061Medicaid | V6: 100-61 Skilled Nursing Facility | W6: =VALUE(LEFT(V6,3)) -> 100 | X6: =VALUE(MID(V6,5,2)) -> 61 | Y6: Medicaid | Z6: 5 | AA6: =COUNTIFS($W$73:$W$136,W6,$X$73:$X$136,X6,$Y$73:$Y$136,Y6) -> 1 | AB6: =AA6-Z6 -> -4
A7: =J7 -> 45717 | B7: =K7 -> 45777 | C7: =_xlfn.XLOOKUP($L7&"-"&$M7,REF!$J$2:$J$61,REF!B$2:B$61) -> PRIVATE PAY | D7: =_xlfn.XLOOKUP($L7&"-"&$M7,REF!$J$2:$J$61,REF!C$2:C$61) -> PPM IL | E7: =_xlfn.XLOOKUP($L7&"-"&$M7,REF!$J$2:$J$61,REF!D$2:D$61) -> ASBURY METHODIST VILLAGE | F7: =_xlfn.XLOOKUP($L7&"-"&$M7,REF!$J$2:$J$61,REF!E$2:E$61) -> AMV INDEPENDENT LIVING | G7: =_xlfn.XLOOKUP($L7&"-"&$M7,REF!$J$2:$J$61,REF!F$2:F$61) -> TROTT APARTMENTS | H7: =P7 -> 62 | J7: 45717 | K7: 45777 | L7: 100 | M7: 31 | N7: AComm\AComm LTC\MD\AMV\IL AMV\Trott Apt | O7: 109 | P7: 62 | U7: =W7&X7&Y7 -> 10061Insurance | V7: 100-61 Skilled Nursing Facility | W7: =VALUE(LEFT(V7,3)) -> 100 | X7: =VALUE(MID(V7,5,2)) -> 61 | Y7: Insurance | Z7: 5 | AA7: =COUNTIFS($W$73:$W$136,W7,$X$73:$X$136,X7,$Y$73:$Y$136,Y7) -> 0 | AB7: =AA7-Z7 -> -5
A8: =J8 -> 45778 | B8: =K8 -> 45838 | C8: =_xlfn.XLOOKUP($L8&"-"&$M8,REF!$J$2:$J$61,REF!B$2:B$61) -> PRIVATE PAY | D8: =_xlfn.XLOOKUP($L8&"-"&$M8,REF!$J$2:$J$61,REF!C$2:C$61) -> PPM IL | E8: =_xlfn.XLOOKUP($L8&"-"&$M8,REF!$J$2:$J$61,REF!D$2:D$61) -> ASBURY METHODIST VILLAGE | F8: =_xlfn.XLOOKUP($L8&"-"&$M8,REF!$J$2:$J$61,REF!E$2:E$61) -> AMV INDEPENDENT LIVING | G8: =_xlfn.XLOOKUP($L8&"-"&$M8,REF!$J$2:$J$61,REF!F$2:F$61) -> TROTT APARTMENTS | H8: =P8 -> 63 | J8: 45778 | K8: 45838 | L8: 100 | M8: 31 | N8: AComm\AComm LTC\MD\AMV\IL AMV\Trott Apt | O8: 109 | P8: 63 | U8: =W8&X8&Y8 -> 10061Private Pay | V8: 100-61 Skilled Nursing Facility | W8: =VALUE(LEFT(V8,3)) -> 100 | X8: =VALUE(MID(V8,5,2)) -> 61 | Y8: Private Pay | Z8: 5 | AA8: =COUNTIFS($W$73:$W$136,W8,$X$73:$X$136,X8,$Y$73:$Y$136,Y8) -> 1 | AB8: =AA8-Z8 -> -4
A9: =J9 -> 45839 | B9: =K9 -> 45900 | C9: =_xlfn.XLOOKUP($L9&"-"&$M9,REF!$J$2:$J$61,REF!B$2:B$61) -> PRIVATE PAY | D9: =_xlfn.XLOOKUP($L9&"-"&$M9,REF!$J$2:$J$61,REF!C$2:C$61) -> PPM IL | E9: =_xlfn.XLOOKUP($L9&"-"&$M9,REF!$J$2:$J$61,REF!D$2:D$61) -> ASBURY METHODIST VILLAGE | F9: =_xlfn.XLOOKUP($L9&"-"&$M9,REF!$J$2:$J$61,REF!E$2:E$61) -> AMV INDEPENDENT LIVING | G9: =_xlfn.XLOOKUP($L9&"-"&$M9,REF!$J$2:$J$61,REF!F$2:F$61) -> TROTT APARTMENTS | H9: =P9 -> 65 | J9: 45839 | K9: 45900 | L9: 100 | M9: 31 | N9: AComm\AComm LTC\MD\AMV\IL AMV\Trott Apt | O9: 109 | P9: 65 | U9: =W9&X9&Y9 -> 10061Hospice | V9: 100-61 Skilled Nursing Facility | W9: =VALUE(LEFT(V9,3)) -> 100 | X9: =VALUE(MID(V9,5,2)) -> 61 | Y9: Hospice | Z9: 5 | AA9: =COUNTIFS($W$73:$W$136,W9,$X$73:$X$136,X9,$Y$73:$Y$136,Y9) -> 1 | AB9: =AA9-Z9 -> -4
A10: =J10 -> 45901 | B10: =K10 -> 45961 | C10: =_xlfn.XLOOKUP($L10&"-"&$M10,REF!$J$2:$J$61,REF!B$2:B$61) -> PRIVATE PAY | D10: =_xlfn.XLOOKUP($L10&"-"&$M10,REF!$J$2:$J$61,REF!C$2:C$61) -> PPM IL | E10: =_xlfn.XLOOKUP($L10&"-"&$M10,REF!$J$2:$J$61,REF!D$2:D$61) -> ASBURY METHODIST VILLAGE | F10: =_xlfn.XLOOKUP($L10&"-"&$M10,REF!$J$2:$J$61,REF!E$2:E$61) -> AMV INDEPENDENT LIVING | G10: =_xlfn.XLOOKUP($L10&"-"&$M10,REF!$J$2:$J$61,REF!F$2:F$61) -> TROTT APARTMENTS | H10: =P10 -> 66 | J10: 45901 | K10: 45961 | L10: 100 | M10: 31 | N10: AComm\AComm LTC\MD\AMV\IL AMV\Trott Apt | O10: 109 | P10: 66 | U10: =W10&X10&Y10 -> 10062Medicare A | V10: 100-62 Skilled Nursing - TCU | W10: =VALUE(LEFT(V10,3)) -> 100 | X10: =VALUE(MID(V10,5,2)) -> 62 | Y10: Medicare A | Z10: 5 | AA10: =COUNTIFS($W$73:$W$136,W10,$X$73:$X$136,X10,$Y$73:$Y$136,Y10) -> 1 | AB10: =AA10-Z10 -> -4
A11: =J11 -> 45962 | B11: =K11 -> 46022 | C11: =_xlfn.XLOOKUP($L11&"-"&$M11,REF!$J$2:$J$61,REF!B$2:B$61) -> PRIVATE PAY | D11: =_xlfn.XLOOKUP($L11&"-"&$M11,REF!$J$2:$J$61,REF!C$2:C$61) -> PPM IL | E11: =_xlfn.XLOOKUP($L11&"-"&$M11,REF!$J$2:$J$61,REF!D$2:D$61) -> ASBURY METHODIST VILLAGE | F11: =_xlfn.XLOOKUP($L11&"-"&$M11,REF!$J$2:$J$61,REF!E$2:E$61) -> AMV INDEPENDENT LIVING | G11: =_xlfn.XLOOKUP($L11&"-"&$M11,REF!$J$2:$J$61,REF!F$2:F$61) -> TROTT APARTMENTS | H11: =P11 -> 67 | J11: 45962 | K11: 46022 | L11: 100 | M11: 31 | N11: AComm\AComm LTC\MD\AMV\IL AMV\Trott Apt | O11: 109 | P11: 67 | U11: =W11&X11&Y11 -> 10062Medicare Advantage | V11: 100-62 Skilled Nursing - TCU | W11: =VALUE(LEFT(V11,3)) -> 100 | X11: =VALUE(MID(V11,5,2)) -> 62 | Y11: Medicare Advantage | Z11: 5 | AA11: =COUNTIFS($W$73:$W$136,W11,$X$73:$X$136,X11,$Y$73:$Y$136,Y11) -> 1 | AB11: =AA11-Z11 -> -4
A12: =J12 -> 45658 | B12: =K12 -> 45688 | C12: =_xlfn.XLOOKUP($L12&"-"&$M12,REF!$J$2:$J$61,REF!B$2:B$61) -> PRIVATE PAY | D12: =_xlfn.XLOOKUP($L12&"-"&$M12,REF!$J$2:$J$61,REF!C$2:C$61) -> PPM IL | E12: =_xlfn.XLOOKUP($L12&"-"&$M12,REF!$J$2:$J$61,REF!D$2:D$61) -> ASBURY METHODIST VILLAGE | F12: =_xlfn.XLOOKUP($L12&"-"&$M12,REF!$J$2:$J$61,REF!E$2:E$61) -> AMV INDEPENDENT LIVING | G12: =_xlfn.XLOOKUP($L12&"-"&$M12,REF!$J$2:$J$61,REF!F$2:F$61) -> DIAMOND APARTMENTS | H12: =P12 -> 159 | J12: 45658 | K12: 45688 | L12: 100 | M12: 32 | N12: AComm\AComm LTC\MD\AMV\IL AMV\DM Apt | O12: 184 | P12: 159 | U12: =W12&X12&Y12 -> 20061Medicare A | V12: 200-61 Skilled Nursing Facility | W12: =VALUE(LEFT(V12,3)) -> 200 | X12: =VALUE(MID(V12,5,2)) -> 61 | Y12: Medicare A | Z12: 1 | AA12: =COUNTIFS($W$73:$W$136,W12,$X$73:$X$136,X12,$Y$73:$Y$136,Y12) -> 1 | AB12: =AA12-Z12 -> 0
A13: =J13 -> 45689 | B13: =K13 -> 45716 | C13: =_xlfn.XLOOKUP($L13&"-"&$M13,REF!$J$2:$J$61,REF!B$2:B$61) -> PRIVATE PAY | D13: =_xlfn.XLOOKUP($L13&"-"&$M13,REF!$J$2:$J$61,REF!C$2:C$61) -> PPM IL | E13: =_xlfn.XLOOKUP($L13&"-"&$M13,REF!$J$2:$J$61,REF!D$2:D$61) -> ASBURY METHODIST VILLAGE | F13: =_xlfn.XLOOKUP($L13&"-"&$M13,REF!$J$2:$J$61,REF!E$2:E$61) -> AMV INDEPENDENT LIVING | G13: =_xlfn.XLOOKUP($L13&"-"&$M13,REF!$J$2:$J$61,REF!F$2:F$61) -> DIAMOND APARTMENTS | H13: =P13 -> 160 | J13: 45689 | K13: 45716 | L13: 100 | M13: 32 | N13: AComm\AComm LTC\MD\AMV\IL AMV\DM Apt | O13: 184 | P13: 160 | U13: =W13&X13&Y13 -> 20061Medicaid | V13: 200-61 Skilled Nursing Facility | W13: =VALUE(LEFT(V13,3)) -> 200 | X13: =VALUE(MID(V13,5,2)) -> 61 | Y13: Medicaid | Z13: 1 | AA13: =COUNTIFS($W$73:$W$136,W13,$X$73:$X$136,X13,$Y$73:$Y$136,Y13) -> 1 | AB13: =AA13-Z13 -> 0
A14: =J14 -> 45717 | B14: =K14 -> 45747 | C14: =_xlfn.XLOOKUP($L14&"-"&$M14,REF!$J$2:$J$61,REF!B$2:B$61) -> PRIVATE PAY | D14: =_xlfn.XLOOKUP($L14&"-"&$M14,REF!$J$2:$J$61,REF!C$2:C$61) -> PPM IL | E14: =_xlfn.XLOOKUP($L14&"-"&$M14,REF!$J$2:$J$61,REF!D$2:D$61) -> ASBURY METHODIST VILLAGE | F14: =_xlfn.XLOOKUP($L14&"-"&$M14,REF!$J$2:$J$61,REF!E$2:E$61) -> AMV INDEPENDENT LIVING | G14: =_xlfn.XLOOKUP($L14&"-"&$M14,REF!$J$2:$J$61,REF!F$2:F$61) -> DIAMOND APARTMENTS | H14: =P14 -> 161 | J14: 45717 | K14: 45747 | L14: 100 | M14: 32 | N14: AComm\AComm LTC\MD\AMV\IL AMV\DM Apt | O14: 184 | P14: 161 | U14: =W14&X14&Y14 -> 20061Private Pay | V14: 200-61 Skilled Nursing Facility | W14: =VALUE(LEFT(V14,3)) -> 200 | X14: =VALUE(MID(V14,5,2)) -> 61 | Y14: Private Pay | Z14: 1 | AA14: =COUNTIFS($W$73:$W$136,W14,$X$73:$X$136,X14,$Y$73:$Y$136,Y14) -> 1 | AB14: =AA14-Z14 -> 0
A15: =J15 -> 45748 | B15: =K15 -> 45777 | C15: =_xlfn.XLOOKUP($L15&"-"&$M15,REF!$J$2:$J$61,REF!B$2:B$61) -> PRIVATE PAY | D15: =_xlfn.XLOOKUP($L15&"-"&$M15,REF!$J$2:$J$61,REF!C$2:C$61) -> PPM IL | E15: =_xlfn.XLOOKUP($L15&"-"&$M15,REF!$J$2:$J$61,REF!D$2:D$61) -> ASBURY METHODIST VILLAGE | F15: =_xlfn.XLOOKUP($L15&"-"&$M15,REF!$J$2:$J$61,REF!E$2:E$61) -> AMV INDEPENDENT LIVING | G15: =_xlfn.XLOOKUP($L15&"-"&$M15,REF!$J$2:$J$61,REF!F$2:F$61) -> DIAMOND APARTMENTS | H15: =P15 -> 162 | J15: 45748 | K15: 45777 | L15: 100 | M15: 32 | N15: AComm\AComm LTC\MD\AMV\IL AMV\DM Apt | O15: 184 | P15: 162 | U15: =W15&X15&Y15 -> 32461Medicare A | V15: 324-61 Skilled Nursing Facility | W15: =VALUE(LEFT(V15,3)) -> 324 | X15: =VALUE(MID(V15,5,2)) -> 61 | Y15: Medicare A | Z15: 2 | AA15: =COUNTIFS($W$73:$W$136,W15,$X$73:$X$136,X15,$Y$73:$Y$136,Y15) -> 1 | AB15: =AA15-Z15 -> -1
... A31: =J31 -> 45658 | B31: =K31 -> 45716 | C31: =_xlfn.XLOOKUP($L31&"-"&$M31,REF!$J$2:$J$61,REF!B$2:B$61) -> PRIVATE PAY | D31: =_xlfn.XLOOKUP($L31&"-"&$M31,REF!$J$2:$J$61,REF!C$2:C$61) -> PPM IL | E31: =_xlfn.XLOOKUP($L31&"-"&$M31,REF!$J$2:$J$61,REF!D$2:D$61) -> ASBURY METHODIST VILLAGE | F31: =_xlfn.XLOOKUP($L31&"-"&$M31,REF!$J$2:$J$61,REF!E$2:E$61) -> AMV INDEPENDENT LIVING | G31: =_xlfn.XLOOKUP($L31&"-"&$M31,REF!$J$2:$J$61,REF!F$2:F$61) -> MUND APARTMENTS | H31: =P31 -> 80 | J31: 45658 | K31: 45716 | L31: 100 | M31: 36 | N31: AComm\AComm LTC\MD\AMV\IL AMV\Mund Apt | O31: 126 | P31: 80 | U31: =W31&X31&Y31 -> 84061Private Pay | V31: 840-61 Skilled Nursing Facility | W31: =VALUE(LEFT(V31,3)) -> 840 | X31: =VALUE(MID(V31,5,2)) -> 61 | Y31: Private Pay | Z31: 1 | AA31: =COUNTIFS($W$73:$W$136,W31,$X$73:$X$136,X31,$Y$73:$Y$136,Y31) -> 1 | AB31: =AA31-Z31 -> 0
A32: =J32 -> 45717 | B32: =K32 -> 45777 | C32: =_xlfn.XLOOKUP($L32&"-"&$M32,REF!$J$2:$J$61,REF!B$2:B$61) -> PRIVATE PAY | D32: =_xlfn.XLOOKUP($L32&"-"&$M32,REF!$J$2:$J$61,REF!C$2:C$61) -> PPM IL | E32: =_xlfn.XLOOKUP($L32&"-"&$M32,REF!$J$2:$J$61,REF!D$2:D$61) -> ASBURY METHODIST VILLAGE | F32: =_xlfn.XLOOKUP($L32&"-"&$M32,REF!$J$2:$J$61,REF!E$2:E$61) -> AMV INDEPENDENT LIVING | G32: =_xlfn.XLOOKUP($L32&"-"&$M32,REF!$J$2:$J$61,REF!F$2:F$61) -> MUND APARTMENTS | H32: =P32 -> 81 | J32: 45717 | K32: 45777 | L32: 100 | M32: 36 | N32: AComm\AComm LTC\MD\AMV\IL AMV\Mund Apt | O32: 126 | P32: 81
A33: =J33 -> 45778 | B33: =K33 -> 45838 | C33: =_xlfn.XLOOKUP($L33&"-"&$M33,REF!$J$2:$J$61,REF!B$2:B$61) -> PRIVATE PAY | D33: =_xlfn.XLOOKUP($L33&"-"&$M33,REF!$J$2:$J$61,REF!C$2:C$61) -> PPM IL | E33: =_xlfn.XLOOKUP($L33&"-"&$M33,REF!$J$2:$J$61,REF!D$2:D$61) -> ASBURY METHODIST VILLAGE | F33: =_xlfn.XLOOKUP($L33&"-"&$M33,REF!$J$2:$J$61,REF!E$2:E$61) -> AMV INDEPENDENT LIVING | G33: =_xlfn.XLOOKUP($L33&"-"&$M33,REF!$J$2:$J$61,REF!F$2:F$61) -> MUND APARTMENTS | H33: =P33 -> 82 | J33: 45778 | K33: 45838 | L33: 100 | M33: 36 | N33: AComm\AComm LTC\MD\AMV\IL AMV\Mund Apt | O33: 126 | P33: 82
A34: =J34 -> 45839 | B34: =K34 -> 45900 | C34: =_xlfn.XLOOKUP($L34&"-"&$M34,REF!$J$2:$J$61,REF!B$2:B$61) -> PRIVATE PAY | D34: =_xlfn.XLOOKUP($L34&"-"&$M34,REF!$J$2:$J$61,REF!C$2:C$61) -> PPM IL | E34: =_xlfn.XLOOKUP($L34&"-"&$M34,REF!$J$2:$J$61,REF!D$2:D$61) -> ASBURY METHODIST VILLAGE | F34: =_xlfn.XLOOKUP($L34&"-"&$M34,REF!$J$2:$J$61,REF!E$2:E$61) -> AMV INDEPENDENT LIVING | G34: =_xlfn.XLOOKUP($L34&"-"&$M34,REF!$J$2:$J$61,REF!F$2:F$61) -> MUND APARTMENTS | H34: =P34 -> 83 | J34: 45839 | K34: 45900 | L34: 100 | M34: 36 | N34: AComm\AComm LTC\MD\AMV\IL AMV\Mund Apt | O34: 126 | P34: 83
A35: =J35 -> 45901 | B35: =K35 -> 45961 | C35: =_xlfn.XLOOKUP($L35&"-"&$M35,REF!$J$2:$J$61,REF!B$2:B$61) -> PRIVATE PAY | D35: =_xlfn.XLOOKUP($L35&"-"&$M35,REF!$J$2:$J$61,REF!C$2:C$61) -> PPM IL | E35: =_xlfn.XLOOKUP($L35&"-"&$M35,REF!$J$2:$J$61,REF!D$2:D$61) -> ASBURY METHODIST VILLAGE | F35: =_xlfn.XLOOKUP($L35&"-"&$M35,REF!$J$2:$J$61,REF!E$2:E$61) -> AMV INDEPENDENT LIVING | G35: =_xlfn.XLOOKUP($L35&"-"&$M35,REF!$J$2:$J$61,REF!F$2:F$61) -> MUND APARTMENTS | H35: =P35 -> 84 | J35: 45901 | K35: 45961 | L35: 100 | M35: 36 | N35: AComm\AComm LTC\MD\AMV\IL AMV\Mund Apt | O35: 126 | P35: 84
A36: =J36 -> 45962 | B36: =K36 -> 46022 | C36: =_xlfn.XLOOKUP($L36&"-"&$M36,REF!$J$2:$J$61,REF!B$2:B$61) -> PRIVATE PAY | D36: =_xlfn.XLOOKUP($L36&"-"&$M36,REF!$J$2:$J$61,REF!C$2:C$61) -> PPM IL | E36: =_xlfn.XLOOKUP($L36&"-"&$M36,REF!$J$2:$J$61,REF!D$2:D$61) -> ASBURY METHODIST VILLAGE | F36: =_xlfn.XLOOKUP($L36&"-"&$M36,REF!$J$2:$J$61,REF!E$2:E$61) -> AMV INDEPENDENT LIVING | G36: =_xlfn.XLOOKUP($L36&"-"&$M36,REF!$J$2:$J$61,REF!F$2:F$61) -> MUND APARTMENTS | H36: =P36 -> 85 | J36: 45962 | K36: 46022 | L36: 100 | M36: 36 | N36: AComm\AComm LTC\MD\AMV\IL AMV\Mund Apt | O36: 126 | P36: 85
A37: =J37 -> 45658 | B37: =K37 -> 46022 | C37: =_xlfn.XLOOKUP($L37&"-"&$M37,REF!$J$2:$J$61,REF!B$2:B$61) -> PRIVATE PAY | D37: =_xlfn.XLOOKUP($L37&"-"&$M37,REF!$J$2:$J$61,REF!C$2:C$61) -> PPM AL | E37: =_xlfn.XLOOKUP($L37&"-"&$M37,REF!$J$2:$J$61,REF!D$2:D$61) -> ASBURY METHODIST VILLAGE | F37: =_xlfn.XLOOKUP($L37&"-"&$M37,REF!$J$2:$J$61,REF!E$2:E$61) -> AMV ASSISTED LIVING | G37: =_xlfn.XLOOKUP($L37&"-"&$M37,REF!$J$2:$J$61,REF!F$2:F$61) -> KINDLEY | H37: =P37 -> 124 | J37: 45658 | K37: 46022 | L37: 100 | M37: 51 | N37: AComm\AComm LTC\MD\AMV\AL AMV\Kindley | O37: 133 | P37: 124
A38: =J38 -> 45658 | B38: =K38 -> 46022 | C38: =_xlfn.XLOOKUP($L38&"-"&$M38,REF!$J$2:$J$61,REF!B$2:B$61) -> Hospice | D38: =_xlfn.XLOOKUP($L38&"-"&$M38,REF!$J$2:$J$61,REF!C$2:C$61) -> Hospice - Private Pay | E38: =_xlfn.XLOOKUP($L38&"-"&$M38,REF!$J$2:$J$61,REF!D$2:D$61) -> ASBURY METHODIST VILLAGE | F38: =_xlfn.XLOOKUP($L38&"-"&$M38,REF!$J$2:$J$61,REF!E$2:E$61) -> SKILLED NURSING | G38: =_xlfn.XLOOKUP($L38&"-"&$M38,REF!$J$2:$J$61,REF!F$2:F$61) -> AMV - WILSON HEALTH CARE CENTER | H38: =P38 -> 133 | J38: 45658 | K38: 46022 | L38: 100 | M38: 61 | N38: AComm\AComm LTC\MD\AMV\SNF AMV | O38: 139 | P38: 133
A39: =J39 -> 45658 | B39: =K39 -> 46022 | C39: =_xlfn.XLOOKUP($L39&"-"&$M39,REF!$J$2:$J$61,REF!B$2:B$61) -> Medicare Advantage | D39: =_xlfn.XLOOKUP($L39&"-"&$M39,REF!$J$2:$J$61,REF!C$2:C$61) -> Med Adv HMO A | E39: =_xlfn.XLOOKUP($L39&"-"&$M39,REF!$J$2:$J$61,REF!D$2:D$61) -> ASBURY METHODIST VILLAGE | F39: =_xlfn.XLOOKUP($L39&"-"&$M39,REF!$J$2:$J$61,REF!E$2:E$61) -> SKILLED NURSING - Household | G39: =_xlfn.XLOOKUP($L39&"-"&$M39,REF!$J$2:$J$61,REF!F$2:F$61) -> AMV - WILSON HEALTH CARE CENTER | H39: =P39 -> 45 | J39: 45658 | K39: 46022 | L39: 100 | M39: 62 | N39: AComm\AComm LTC\MD\AMV\SNF AMV H | O39: 46 | P39: 45
A40: =J40 -> 45658 | B40: =K40 -> 46022 | C40: =_xlfn.XLOOKUP($L40&"-"&$M40,REF!$J$2:$J$61,REF!B$2:B$61) -> PRIVATE PAY | D40: =_xlfn.XLOOKUP($L40&"-"&$M40,REF!$J$2:$J$61,REF!C$2:C$61) -> PPM IL | E40: =_xlfn.XLOOKUP($L40&"-"&$M40,REF!$J$2:$J$61,REF!D$2:D$61) -> ASBURY SOLOMONS | F40: =_xlfn.XLOOKUP($L40&"-"&$M40,REF!$J$2:$J$61,REF!E$2:E$61) -> AS INDEPENDENT LIVING | G40: =_xlfn.XLOOKUP($L40&"-"&$M40,REF!$J$2:$J$61,REF!F$2:F$61) -> IL COTTAGES | H40: =P40 -> 71 | J40: 45658 | K40: 46022 | L40: 200 | M40: 21 | N40: AComm\AComm LTC\MD\AS\IL AS\IL Cottages | O40: 72 | P40: 71
A41: =J41 -> 45658 | B41: =K41 -> 46022 | C41: =_xlfn.XLOOKUP($L41&"-"&$M41,REF!$J$2:$J$61,REF!B$2:B$61) -> PRIVATE PAY | D41: =_xlfn.XLOOKUP($L41&"-"&$M41,REF!$J$2:$J$61,REF!C$2:C$61) -> PPM IL | E41: =_xlfn.XLOOKUP($L41&"-"&$M41,REF!$J$2:$J$61,REF!D$2:D$61) -> ASBURY SOLOMONS | F41: =_xlfn.XLOOKUP($L41&"-"&$M41,REF!$J$2:$J$61,REF!E$2:E$61) -> AS INDEPENDENT LIVING | G41: =_xlfn.XLOOKUP($L41&"-"&$M41,REF!$J$2:$J$61,REF!F$2:F$61) -> IL NORTH APARTMENTS | H41: =P41 -> 134 | J41: 45658 | K41: 46022 | L41: 200 | M41: 31 | N41: AComm\AComm LTC\MD\AS\IL AS\IL North Apt | O41: 142 | P41: 134
A42: =J42 -> 45658 | B42: =K42 -> 46022 | C42: =_xlfn.XLOOKUP($L42&"-"&$M42,REF!$J$2:$J$61,REF!B$2:B$61) -> PRIVATE PAY | D42: =_xlfn.XLOOKUP($L42&"-"&$M42,REF!$J$2:$J$61,REF!C$2:C$61) -> PPM IL | E42: =_xlfn.XLOOKUP($L42&"-"&$M42,REF!$J$2:$J$61,REF!D$2:D$61) -> ASBURY SOLOMONS | F42: =_xlfn.XLOOKUP($L42&"-"&$M42,REF!$J$2:$J$61,REF!E$2:E$61) -> AS INDEPENDENT LIVING | G42: =_xlfn.XLOOKUP($L42&"-"&$M42,REF!$J$2:$J$61,REF!F$2:F$61) -> IL SOUTH APARTMENTS | H42: =P42 -> 83 | J42: 45658 | K42: 46022 | L42: 200 | M42: 32 | N42: AComm\AComm LTC\MD\AS\IL AS\IL South Apt | O42: 86 | P42: 83
A43: =J43 -> 45658 | B43: =K43 -> 46022 | C43: =_xlfn.XLOOKUP($L43&"-"&$M43,REF!$J$2:$J$61,REF!B$2:B$61) -> PRIVATE PAY | D43: =_xlfn.XLOOKUP($L43&"-"&$M43,REF!$J$2:$J$61,REF!C$2:C$61) -> PPM AL | E43: =_xlfn.XLOOKUP($L43&"-"&$M43,REF!$J$2:$J$61,REF!D$2:D$61) -> ASBURY SOLOMONS | F43: =_xlfn.XLOOKUP($L43&"-"&$M43,REF!$J$2:$J$61,REF!E$2:E$61) -> AS ASSISTED LIVING | G43: =_xlfn.XLOOKUP($L43&"-"&$M43,REF!$J$2:$J$61,REF!F$2:F$61) -> ASSISTED LIVING | H43: =P43 -> 23.5 | J43: 45658 | K43: 46022 | L43: 200 | M43: 51 | N43: AComm\AComm LTC\MD\AS\AL AS\AL | O43: 24 | P43: 23.5
... A65: =J65 -> 45658 | B65: =K65 -> 46022 | C65: =_xlfn.XLOOKUP($L65&"-"&$M65,REF!$J$2:$J$61,REF!B$2:B$61) -> MANAGED CARE | D65: =_xlfn.XLOOKUP($L65&"-"&$M65,REF!$J$2:$J$61,REF!C$2:C$61) -> MGCARE LEVEL OF CARE | E65: =_xlfn.XLOOKUP($L65&"-"&$M65,REF!$J$2:$J$61,REF!D$2:D$61) -> Normandie Ridge | F65: =_xlfn.XLOOKUP($L65&"-"&$M65,REF!$J$2:$J$61,REF!E$2:E$61) -> SKILLED NURSING | G65: =_xlfn.XLOOKUP($L65&"-"&$M65,REF!$J$2:$J$61,REF!F$2:F$61) -> NORMANDIE RIDGE SNF | H65: =P65 -> 61 | J65: 45658 | K65: 46022 | L65: 840 | M65: 61 | N65: Skilled Nursing Facility | O65: 64 | P65: 61
A66: =J66 -> 45658 | B66: =K66 -> 46022 | C66: =_xlfn.XLOOKUP($L66&"-"&$M66,REF!$J$2:$J$61,REF!B$2:B$61) -> PRIVATE PAY | D66: =_xlfn.XLOOKUP($L66&"-"&$M66,REF!$J$2:$J$61,REF!C$2:C$61) -> PPM AL | E66: =_xlfn.XLOOKUP($L66&"-"&$M66,REF!$J$2:$J$61,REF!D$2:D$61) -> Normandie Ridge | F66: =_xlfn.XLOOKUP($L66&"-"&$M66,REF!$J$2:$J$61,REF!E$2:E$61) -> NORMANDIE RIDGE AL | G66: =_xlfn.XLOOKUP($L66&"-"&$M66,REF!$J$2:$J$61,REF!F$2:F$61) -> NR PC | H66: =P66+P67 -> 24 | J66: 45658 | K66: 46022 | L66: 840 | M66: 51 | N66: AComm\AComm LTC\PA\NR\AL NR\NR PC | O66: 9 | P66: 8.5 | Q66: combine 51 and 52
A67: =J68 -> 45658 | B67: =K68 -> 46022 | C67: PRIVATE PAY | D67: PPM IL | E67: Grace Park | F67: GP Independent Living | G67: GP Cottages | H67: =P68 -> 12 | J67: 45658 | K67: 46022 | L67: 840 | M67: 52 | N67: Assisted Living (Memory Care) | O67: 16 | P67: 15.5 | Q67: combine 51 and 52
A68: =J69 -> 45658 | B68: =K69 -> 46022 | C68: PRIVATE PAY | D68: PPM AL | E68: Grace Park | F68: GP Assisted Living | G68: GP PC | H68: =P69+P70 -> 77 | J68: 45658 | K68: 46022 | L68: 350 | M68: 21 | N68: AComm\AComm LTC\PA\GP\IL GP\GP Cottage Units | O68: 13 | P68: 12
A69: =J71 -> 45658 | B69: =K71 -> 45688 | C69: =$C$68 -> PRIVATE PAY | D69: =$D$68 -> PPM AL | E69: Ivy Gables | F69: IG Assisted Living | G69: IG PC | H69: =P71+$P$75 -> 42 | J69: 45658 | K69: 46022 | L69: 350 | M69: 51 | N69: AComm\AComm LTC\PA\GP\AL GP\GP PC | O69: 70 | P69: 66 | Q69: combine 51 and 52
A70: =J72 -> 45689 | B70: =K72 -> 45716 | C70: =$C$68 -> PRIVATE PAY | D70: =$D$68 -> PPM AL | E70: Ivy Gables | F70: IG Assisted Living | G70: IG PC | H70: =P72+$P$75 -> 43 | J70: 45658 | K70: 46022 | L70: 350 | M70: 52 | N70: AComm\AComm LTC\PA\GP\AL GP\GP PC | O70: 12 | P70: 11 | Q70: combine 51 and 52
A71: =J73 -> 45717 | B71: =K73 -> 45747 | C71: =$C$68 -> PRIVATE PAY | D71: =$D$68 -> PPM AL | E71: Ivy Gables | F71: IG Assisted Living | G71: IG PC | H71: =P73+$P$75 -> 44 | J71: 45658 | K71: 45688 | L71: 360 | M71: 51 | N71: AComm\AComm LTC\DE\IG\AL IG\IG AL | O71: 43 | P71: 34 | Q71: combine 51 and 52
A72: =J74 -> 45748 | B72: =K74 -> 46022 | C72: =$C$68 -> PRIVATE PAY | D72: =$D$68 -> PPM AL | E72: Ivy Gables | F72: IG Assisted Living | G72: IG PC | H72: =P74+$P$75 -> 45 | J72: 45689 | K72: 45716 | L72: 360 | M72: 51 | N72: AComm\AComm LTC\DE\IG\AL IG\IG AL | O72: 43 | P72: 35 | Q72: combine 51 and 52
A73: {=INDEX('OC-SNF PMix Anc Days'!$DA$6:$EV$41,_xlfn.XMATCH($U73,'OC-SNF PMix Anc Days'!$CT$6:$CT$41),_xlfn.XMATCH(A$3&$S73,'OC-SNF PMix Anc Days'!$DA$3:$EV$3))} -> 45658 | B73: {=INDEX('OC-SNF PMix Anc Days'!$DA$6:$EV$41,_xlfn.XMATCH($U73,'OC-SNF PMix Anc Days'!$CT$6:$CT$41),_xlfn.XMATCH(B$3&$S73,'OC-SNF PMix Anc Days'!$DA$3:$EV$3))} -> 46022 | C73: {=INDEX('OC-SNF PMix Anc Days'!$DA$6:$EV$41,_xlfn.XMATCH($U73,'OC-SNF PMix Anc Days'!$CT$6:$CT$41),_xlfn.XMATCH(C$3&$S73,'OC-SNF PMix Anc Days'!$DA$3:$EV$3))} -> MEDICAREA/MC HMO | D73: {=INDEX('OC-SNF PMix Anc Days'!$DA$6:$EV$41,_xlfn.XMATCH($U73,'OC-SNF PMix Anc Days'!$CT$6:$CT$41),_xlfn.XMATCH(D$3&$S73,'OC-SNF PMix Anc Days'!$DA$3:$EV$3))} -> MEDICARE A HIGHMARK | E73: {=INDEX('OC-SNF PMix Anc Days'!$DA$6:$EV$41,_xlfn.XMATCH($U73,'OC-SNF PMix Anc Days'!$CT$6:$CT$41),_xlfn.XMATCH(E$3&$S73,'OC-SNF PMix Anc Days'!$DA$3:$EV$3))} -> ASBURY METHODIST VILLAGE | F73: {=INDEX('OC-SNF PMix Anc Days'!$DA$6:$EV$41,_xlfn.XMATCH($U73,'OC-SNF PMix Anc Days'!$CT$6:$CT$41),_xlfn.XMATCH(F$3&$S73,'OC-SNF PMix Anc Days'!$DA$3:$EV$3))} -> SKILLED NURSING | G73: {=INDEX('OC-SNF PMix Anc Days'!$DA$6:$EV$41,_xlfn.XMATCH($U73,'OC-SNF PMix Anc Days'!$CT$6:$CT$41),_xlfn.XMATCH(G$3&$S73,'OC-SNF PMix Anc Days'!$DA$3:$EV$3))} -> AMV - WILSON HEALTH CARE CENTER | H73: {=INDEX('OC-SNF PMix Anc Days'!$DA$6:$EV$41,_xlfn.XMATCH($U73,'OC-SNF PMix Anc Days'!$CT$6:$CT$41),_xlfn.XMATCH(H$3&$S73,'OC-SNF PMix Anc Days'!$DA$3:$EV$3))} -> 1.995 | J73: 45717 | K73: 45747 | L73: 360 | M73: 51 | N73: AComm\AComm LTC\DE\IG\AL IG\IG AL | O73: 43 | P73: 36 | Q73: combine 51 and 52 | S73: =COUNTIFS($W$73:W73,W73,$X$73:X73,X73,$Y$73:Y73,Y73) -> 1 | U73: =W73&X73&Y73 -> 10061Medicare A | W73: 100 | X73: 61 | Y73: Medicare A | AA73: 1
A74: {=INDEX('OC-SNF PMix Anc Days'!$DA$6:$EV$41,_xlfn.XMATCH($U74,'OC-SNF PMix Anc Days'!$CT$6:$CT$41),_xlfn.XMATCH(A$3&$S74,'OC-SNF PMix Anc Days'!$DA$3:$EV$3))} -> 45658 | B74: {=INDEX('OC-SNF PMix Anc Days'!$DA$6:$EV$41,_xlfn.XMATCH($U74,'OC-SNF PMix Anc Days'!$CT$6:$CT$41),_xlfn.XMATCH(B$3&$S74,'OC-SNF PMix Anc Days'!$DA$3:$EV$3))} -> 46022 | C74: {=INDEX('OC-SNF PMix Anc Days'!$DA$6:$EV$41,_xlfn.XMATCH($U74,'OC-SNF PMix Anc Days'!$CT$6:$CT$41),_xlfn.XMATCH(C$3&$S74,'OC-SNF PMix Anc Days'!$DA$3:$EV$3))} -> MEDICAID | D74: {=INDEX('OC-SNF PMix Anc Days'!$DA$6:$EV$41,_xlfn.XMATCH($U74,'OC-SNF PMix Anc Days'!$CT$6:$CT$41),_xlfn.XMATCH(D$3&$S74,'OC-SNF PMix Anc Days'!$DA$3:$EV$3))} -> MARYLAND MEDICAID | E74: {=INDEX('OC-SNF PMix Anc Days'!$DA$6:$EV$41,_xlfn.XMATCH($U74,'OC-SNF PMix Anc Days'!$CT$6:$CT$41),_xlfn.XMATCH(E$3&$S74,'OC-SNF PMix Anc Days'!$DA$3:$EV$3))} -> ASBURY METHODIST VILLAGE | F74: {=INDEX('OC-SNF PMix Anc Days'!$DA$6:$EV$41,_xlfn.XMATCH($U74,'OC-SNF PMix Anc Days'!$CT$6:$CT$41),_xlfn.XMATCH(F$3&$S74,'OC-SNF PMix Anc Days'!$DA$3:$EV$3))} -> SKILLED NURSING | G74: {=INDEX('OC-SNF PMix Anc Days'!$DA$6:$EV$41,_xlfn.XMATCH($U74,'OC-SNF PMix Anc Days'!$CT$6:$CT$41),_xlfn.XMATCH(G$3&$S74,'OC-SNF PMix Anc Days'!$DA$3:$EV$3))} -> AMV - WILSON HEALTH CARE CENTER | H74: {=INDEX('OC-SNF PMix Anc Days'!$DA$6:$EV$41,_xlfn.XMATCH($U74,'OC-SNF PMix Anc Days'!$CT$6:$CT$41),_xlfn.XMATCH(H$3&$S74,'OC-SNF PMix Anc Days'!$DA$3:$EV$3))} -> 85.0003 | J74: 45748 | K74: 46022 | L74: 360 | M74: 51 | N74: AComm\AComm LTC\DE\IG\AL IG\IG AL | O74: 43 | P74: 37 | S74: =COUNTIFS($W$73:W74,W74,$X$73:X74,X74,$Y$73:Y74,Y74) -> 1 | U74: =W74&X74&Y74 -> 10061Medicaid | W74: 100 | X74: 61 | Y74: Medicaid | AA74: 1
A75: {=INDEX('OC-SNF PMix Anc Days'!$DA$6:$EV$41,_xlfn.XMATCH($U75,'OC-SNF PMix Anc Days'!$CT$6:$CT$41),_xlfn.XMATCH(A$3&$S75,'OC-SNF PMix Anc Days'!$DA$3:$EV$3))} -> 45658 | B75: {=INDEX('OC-SNF PMix Anc Days'!$DA$6:$EV$41,_xlfn.XMATCH($U75,'OC-SNF PMix Anc Days'!$CT$6:$CT$41),_xlfn.XMATCH(B$3&$S75,'OC-SNF PMix Anc Days'!$DA$3:$EV$3))} -> 46022 | C75: {=INDEX('OC-SNF PMix Anc Days'!$DA$6:$EV$41,_xlfn.XMATCH($U75,'OC-SNF PMix Anc Days'!$CT$6:$CT$41),_xlfn.XMATCH(C$3&$S75,'OC-SNF PMix Anc Days'!$DA$3:$EV$3))} -> PRIVATE PAY | D75: {=INDEX('OC-SNF PMix Anc Days'!$DA$6:$EV$41,_xlfn.XMATCH($U75,'OC-SNF PMix Anc Days'!$CT$6:$CT$41),_xlfn.XMATCH(D$3&$S75,'OC-SNF PMix Anc Days'!$DA$3:$EV$3))} -> PRIVATE PAY | E75: {=INDEX('OC-SNF PMix Anc Days'!$DA$6:$EV$41,_xlfn.XMATCH($U75,'OC-SNF PMix Anc Days'!$CT$6:$CT$41),_xlfn.XMATCH(E$3&$S75,'OC-SNF PMix Anc Days'!$DA$3:$EV$3))} -> ASBURY METHODIST VILLAGE | F75: {=INDEX('OC-SNF PMix Anc Days'!$DA$6:$EV$41,_xlfn.XMATCH($U75,'OC-SNF PMix Anc Days'!$CT$6:$CT$41),_xlfn.XMATCH(F$3&$S75,'OC-SNF PMix Anc Days'!$DA$3:$EV$3))} -> SKILLED NURSING | G75: {=INDEX('OC-SNF PMix Anc Days'!$DA$6:$EV$41,_xlfn.XMATCH($U75,'OC-SNF PMix Anc Days'!$CT$6:$CT$41),_xlfn.XMATCH(G$3&$S75,'OC-SNF PMix Anc Days'!$DA$3:$EV$3))} -> AMV - WILSON HEALTH CARE CENTER | H75: {=INDEX('OC-SNF PMix Anc Days'!$DA$6:$EV$41,_xlfn.XMATCH($U75,'OC-SNF PMix Anc Days'!$CT$6:$CT$41),_xlfn.XMATCH(H$3&$S75,'OC-SNF PMix Anc Days'!$DA$3:$EV$3))} -> 42.9989 | J75: 45658 | K75: 46022 | L75: 360 | M75: 52 | N75: AComm\AComm LTC\DE\IG\AL IG\IG AL | O75: 9 | P75: 8 | S75: =COUNTIFS($W$73:W75,W75,$X$73:X75,X75,$Y$73:Y75,Y75) -> 1 | U75: =W75&X75&Y75 -> 10061Private Pay | W75: 100 | X75: 61 | Y75: Private Pay | AA75: 1
A76: {=INDEX('OC-SNF PMix Anc Days'!$DA$6:$EV$41,_xlfn.XMATCH($U76,'OC-SNF PMix Anc Days'!$CT$6:$CT$41),_xlfn.XMATCH(A$3&$S76,'OC-SNF PMix Anc Days'!$DA$3:$EV$3))} -> 45658 | B76: {=INDEX('OC-SNF PMix Anc Days'!$DA$6:$EV$41,_xlfn.XMATCH($U76,'OC-SNF PMix Anc Days'!$CT$6:$CT$41),_xlfn.XMATCH(B$3&$S76,'OC-SNF PMix Anc Days'!$DA$3:$EV$3))} -> 46022 | C76: {=INDEX('OC-SNF PMix Anc Days'!$DA$6:$EV$41,_xlfn.XMATCH($U76,'OC-SNF PMix Anc Days'!$CT$6:$CT$41),_xlfn.XMATCH(C$3&$S76,'OC-SNF PMix Anc Days'!$DA$3:$EV$3))} -> Hospice | D76: {=INDEX('OC-SNF PMix Anc Days'!$DA$6:$EV$41,_xlfn.XMATCH($U76,'OC-SNF PMix Anc Days'!$CT$6:$CT$41),_xlfn.XMATCH(D$3&$S76,'OC-SNF PMix Anc Days'!$DA$3:$EV$3))} -> Hospice - Private Pay | E76: {=INDEX('OC-SNF PMix Anc Days'!$DA$6:$EV$41,_xlfn.XMATCH($U76,'OC-SNF PMix Anc Days'!$CT$6:$CT$41),_xlfn.XMATCH(E$3&$S76,'OC-SNF PMix Anc Days'!$DA$3:$EV$3))} -> ASBURY METHODIST VILLAGE | F76: {=INDEX('OC-SNF PMix Anc Days'!$DA$6:$EV$41,_xlfn.XMATCH($U76,'OC-SNF PMix Anc Days'!$CT$6:$CT$41),_xlfn.XMATCH(F$3&$S76,'OC-SNF PMix Anc Days'!$DA$3:$EV$3))} -> SKILLED NURSING | G76: {=INDEX('OC-SNF PMix Anc Days'!$DA$6:$EV$41,_xlfn.XMATCH($U76,'OC-SNF PMix Anc Days'!$CT$6:$CT$41),_xlfn.XMATCH(G$3&$S76,'OC-SNF PMix Anc Days'!$DA$3:$EV$3))} -> AMV - WILSON HEALTH CARE CENTER | H76: {=INDEX('OC-SNF PMix Anc Days'!$DA$6:$EV$41,_xlfn.XMATCH($U76,'OC-SNF PMix Anc Days'!$CT$6:$CT$41),_xlfn.XMATCH(H$3&$S76,'OC-SNF PMix Anc Days'!$DA$3:$EV$3))} -> 3.0058 | S76: =COUNTIFS($W$73:W76,W76,$X$73:X76,X76,$Y$73:Y76,Y76) -> 1 | U76: =W76&X76&Y76 -> 10061Hospice | W76: 100 | X76: 61 | Y76: Hospice | AA76: 1
...

Sheet OC-SNF PMix Anc Days
A1: Days in Month | D1: =_xlfn.XLOOKUP(D5,'OC-Days'!$G:$G,'OC-Days'!$B:$B) -> 31 | E1: =_xlfn.XLOOKUP(E5,'OC-Days'!$G:$G,'OC-Days'!$B:$B) -> 28 | F1: =_xlfn.XLOOKUP(F5,'OC-Days'!$G:$G,'OC-Days'!$B:$B) -> 31 | G1: =_xlfn.XLOOKUP(G5,'OC-Days'!$G:$G,'OC-Days'!$B:$B) -> 30 | H1: =_xlfn.XLOOKUP(H5,'OC-Days'!$G:$G,'OC-Days'!$B:$B) -> 31 | I1: =_xlfn.XLOOKUP(I5,'OC-Days'!$G:$G,'OC-Days'!$B:$B) -> 30 | J1: =_xlfn.XLOOKUP(J5,'OC-Days'!$G:$G,'OC-Days'!$B:$B) -> 31 | K1: =_xlfn.XLOOKUP(K5,'OC-Days'!$G:$G,'OC-Days'!$B:$B) -> 31 | ... O1: =_xlfn.XLOOKUP(O5,'OC-Days'!$G:$G,'OC-Days'!$B:$B) -> 31 | AF1: Processing | AI1: Processing | AL1: Processing | AO1: Processing | AS1: Processing | AV1: Processing | AY1: Processing | BB1: Processing | BF1: Processing | BI1: Processing | BL1: Processing | BO1: Processing | BS1: Processing | BV1: Processing | BY1: Processing | CB1: Processing | CF1: Processing | CI1: Processing | CL1: Processing | CO1: Processing | CS1: Processing | CX1: Processing | DA1: Processing | DI1: Processing | DQ1: Processing | DY1: Processing | EG1: Processing | EO1: Processing
AF2: f(x) | AG2: f(x) | AH2: f(x) | AI2: f(x) | AJ2: f(x) | AK2: f(x) | AL2: f(x) | AM2: f(x) | AN2: f(x) | AO2: f(x) | AP2: f(x) | AQ2: f(x) | AS2: f(x) | AT2: f(x) | AU2: f(x) | AV2: f(x) | AW2: f(x) | AX2: f(x) | AY2: f(x) | AZ2: f(x) | BA2: f(x) | BB2: f(x) | BC2: f(x) | BD2: f(x) | BF2: f(x) | BG2: f(x) | BH2: f(x) | BI2: f(x) | BJ2: f(x) | BK2: f(x) | BL2: f(x) | BM2: f(x) | BN2: f(x) | BO2: f(x) | BP2: f(x) | BQ2: f(x) | BS2: f(x) | BT2: f(x) | BU2: f(x) | BV2: f(x) | BW2: f(x) | BX2: f(x) | BY2: f(x) | BZ2: f(x) | CA2: f(x) | CB2: f(x) | CC2: f(x) | CD2: f(x) | CF2: f(x) | CG2: f(x) | CH2: f(x) | CI2: f(x) | CJ2: f(x) | CK2: f(x) | CL2: f(x) | CM2: f(x) | CN2: f(x) | CO2: f(x) | CP2: f(x) | CQ2: f(x) | CS2: f(x) | CT2: f(x) | CU2: f(x) | CV2: f(x) | CX2: f(x) | CY2: f(x) | DA2: f(x) | DB2: f(x) | DC2: f(x) | DD2: f(x) | DE2: f(x) | DF2: f(x) | DG2: f(x) | DH2: f(x) | DI2: f(x) | DJ2: f(x) | DK2: f(x) | DL2: f(x) | DM2: f(x) | DN2: f(x) | DO2: f(x) | DP2: f(x) | DQ2: f(x) | DR2: f(x) | DS2: f(x) | DT2: f(x) | DU2: f(x) | DV2: f(x) | DW2: f(x) | DX2: f(x) | DY2: f(x) | DZ2: f(x) | EA2: f(x) | EB2: f(x) | EC2: f(x) | ED2: f(x) | EE2: f(x) | EF2: f(x) | EG2: f(x) | EH2: f(x) | EI2: f(x) | EJ2: f(x) | EK2: f(x) | EL2: f(x) | EM2: f(x) | EN2: f(x) | EO2: f(x) | EP2: f(x) | EQ2: f(x) | ER2: f(x) | ES2: f(x) | ET2: f(x) | EU2: f(x) | EV2: f(x)
DA3: =DA4&DA5 -> StartDate1 | DB3: =DB4&DB5 -> EndDate1 | DC3: =DC4&DC5 -> PayerName1 | DD3: =DD4&DD5 -> PlanName1 | DE3: =DE4&DE5 -> CampusName1 | DF3: =DF4&DF5 -> LevelOfCareName1 | DG3: =DG4&DG5 -> BuildingName1 | DH3: =DH4&DH5 -> BudgetPlanDays1 | ... EV3: =EV4&EV5 -> BudgetPlanDays6
D4: Budget 2025 | E4: Budget 2025 | F4: Budget 2025 | G4: Budget 2025 | H4: Budget 2025 | I4: Budget 2025 | J4: Budget 2025 | K4: Budget 2025 | L4: Budget 2025 | M4: Budget 2025 | N4: Budget 2025 | O4: Budget 2025 | Q4: Check SNF Facilities - SNF Ancillary Days (SNF Pmix Cube) vs Resident Days (Occ FC Cube) | AF4: Census | AG4: Census | AH4: Census | AI4: Census | AJ4: Census | AK4: Census | AL4: Census | AM4: Census | AN4: Census | AO4: Census | AP4: Census | AQ4: Census | AS4: Census -Start Date | AT4: Census -Start Date | AU4: Census -Start Date | AV4: Census -Start Date | AW4: Census -Start Date | AX4: Census -Start Date | AY4: Census -Start Date | AZ4: Census -Start Date | BA4: Census -Start Date | BB4: Census -Start Date | BC4: Census -Start Date | BD4: Census -Start Date | BF4: Census - End Date | BG4: Census - End Date | BH4: Census - End Date | BI4: Census - End Date | BJ4: Census - End Date | BK4: Census - End Date | BL4: Census - End Date | BM4: Census - End Date | BN4: Census - End Date | BO4: Census - End Date | BP4: Census - End Date | BQ4: Census - End Date | BS4: Start REF | BT4: Start REF | BU4: Start REF | BV4: Start REF | BW4: Start REF | BX4: Start REF | BY4: Start REF | BZ4: Start REF | CA4: Start REF | CB4: Start REF | CC4: Start REF | CD4: Start REF | CF4: End REF | CG4: End REF | CH4: End REF | CI4: End REF | CJ4: End REF | CK4: End REF | CL4: End REF | CM4: End REF | CN4: End REF | CO4: End REF | CP4: End REF | CQ4: End REF | CX4: Start Date Row Counts | CY4: End Date Row Counts | DA4: StartDate | DB4: EndDate | DC4: PayerName | DD4: PlanName | DE4: CampusName | DF4: LevelOfCareName | DG4: BuildingName | DH4: BudgetPlanDays | DI4: StartDate | DJ4: EndDate | DK4: PayerName | DL4: PlanName | DM4: CampusName | DN4: LevelOfCareName | DO4: BuildingName | DP4: BudgetPlanDays | DQ4: StartDate | DR4: EndDate | DS4: PayerName | DT4: PlanName | DU4: CampusName | DV4: LevelOfCareName | DW4: BuildingName | DX4: BudgetPlanDays | DY4: StartDate | DZ4: EndDate | EA4: PayerName | EB4: PlanName | EC4: CampusName | ED4: LevelOfCareName | EE4: BuildingName | EF4: BudgetPlanDays | EG4: StartDate | EH4: EndDate | EI4: PayerName | EJ4: PlanName | EK4: CampusName | EL4: LevelOfCareName | EM4: BuildingName | EN4: BudgetPlanDays | EO4: StartDate | EP4: EndDate | EQ4: PayerName | ER4: PlanName | ES4: CampusName | ET4: LevelOfCareName | EU4: BuildingName | EV4: BudgetPlanDays
D5: Jan-2025 | E5: Feb-2025 | F5: Mar-2025 | G5: Apr-2025 | H5: May-2025 | I5: Jun-2025 | J5: Jul-2025 | K5: Aug-2025 | L5: Sep-2025 | M5: Oct-2025 | N5: Nov-2025 | O5: Dec-2025 | S5: =D5 -> Jan-2025 | T5: =E5 -> Feb-2025 | U5: =F5 -> Mar-2025 | V5: =G5 -> Apr-2025 | W5: =H5 -> May-2025 | X5: =I5 -> Jun-2025 | Y5: =J5 -> Jul-2025 | Z5: =K5 -> Aug-2025 | ... AD5: =O5 -> Dec-2025 | AF5: =D5 -> Jan-2025 | AG5: =E5 -> Feb-2025 | AH5: =F5 -> Mar-2025 | AI5: =G5 -> Apr-2025 | AJ5: =H5 -> May-2025 | AK5: =I5 -> Jun-2025 | AL5: =J5 -> Jul-2025 | AM5: =K5 -> Aug-2025 | ... AQ5: =O5 -> Dec-2025 | AS5: =AF5 -> Jan-2025 | AT5: =AG5 -> Feb-2025 | AU5: =AH5 -> Mar-2025 | AV5: =AI5 -> Apr-2025 | AW5: =AJ5 -> May-2025 | AX5: =AK5 -> Jun-2025 | AY5: =AL5 -> Jul-2025 | AZ5: =AM5 -> Aug-2025 | ... BD5: =AQ5 -> Dec-2025 | BF5: =AS5 -> Jan-2025 | BG5: =AT5 -> Feb-2025 | BH5: =AU5 -> Mar-2025 | BI5: =AV5 -> Apr-2025 | BJ5: =AW5 -> May-2025 | BK5: =AX5 -> Jun-2025 | BL5: =AY5 -> Jul-2025 | BM5: =AZ5 -> Aug-2025 | ... BQ5: =BD5 -> Dec-2025 | BS5: =BF5 -> Jan-2025 | BT5: =BG5 -> Feb-2025 | BU5: =BH5 -> Mar-2025 | BV5: =BI5 -> Apr-2025 | BW5: =BJ5 -> May-2025 | BX5: =BK5 -> Jun-2025 | BY5: =BL5 -> Jul-2025 | BZ5: =BM5 -> Aug-2025 | ... CD5: =BQ5 -> Dec-2025 | CF5: =BS5 -> Jan-2025 | CG5: =BT5 -> Feb-2025 | CH5: =BU5 -> Mar-2025 | CI5: =BV5 -> Apr-2025 | CJ5: =BW5 -> May-2025 | CK5: =BX5 -> Jun-2025 | CL5: =BY5 -> Jul-2025 | CM5: =BZ5 -> Aug-2025 | ... CQ5: =CD5 -> Dec-2025 | CS5: Include? | CT5: Ent-Fac-PMix | CU5: Ent | CV5: Fac | DA5: 1 | DB5: 1 | DC5: 1 | DD5: 1 | DE5: 1 | DF5: 1 | DG5: 1 | DH5: 1 | DI5: =DA5+1 -> 2 | DJ5: =DB5+1 -> 2 | DK5: =DC5+1 -> 2 | DL5: =DD5+1 -> 2 | DM5: =DE5+1 -> 2 | DN5: =DF5+1 -> 2 | DO5: =DG5+1 -> 2 | DP5: =DH5+1 -> 2 | ... EV5: =EN5+1 -> 6
A6: 100-61 Skilled Nursing Facility | B6: Rev_Asm_SNF_Payer_Mix.SNF_Ancillary_Medicare_A | C6: Medicare A | D6: 61.845 | E6: 55.86 | F6: 61.845 | G6: 59.85 | H6: 61.845 | I6: 59.85 | J6: 61.845 | K6: 61.845 | L6: 59.85 | M6: 61.845 | N6: 59.85 | O6: 61.845 | Q6: 100-61 Skilled Nursing Facility | R6: SNF Anc Days | S6: =SUMIFS(D$6:D$41,$A$6:$A$41,$Q6) -> 4123 | T6: =SUMIFS(E$6:E$41,$A$6:$A$41,$Q6) -> 3724 | U6: =SUMIFS(F$6:F$41,$A$6:$A$41,$Q6) -> 4123 | V6: =SUMIFS(G$6:G$41,$A$6:$A$41,$Q6) -> 3990 | W6: =SUMIFS(H$6:H$41,$A$6:$A$41,$Q6) -> 4123 | X6: =SUMIFS(I$6:I$41,$A$6:$A$41,$Q6) -> 3990 | Y6: =SUMIFS(J$6:J$41,$A$6:$A$41,$Q6) -> 4123 | Z6: =SUMIFS(K$6:K$41,$A$6:$A$41,$Q6) -> 4123 | ... AD6: =SUMIFS(O$6:O$41,$A$6:$A$41,$Q6) -> 4123 | AF6: =D6/D$1 -> 1.995 | AG6: =E6/E$1 -> 1.995 | AH6: =F6/F$1 -> 1.995 | AI6: =G6/G$1 -> 1.995 | AJ6: =H6/H$1 -> 1.995 | AK6: =I6/I$1 -> 1.995 | AL6: =J6/J$1 -> 1.995 | AM6: =K6/K$1 -> 1.995 | ... AQ6: =O6/O$1 -> 1.995 | AS6: =_xlfn.XLOOKUP(AS$5,'OC-Days'!$G:$G,'OC-Days'!$F:$F) -> 45658 | AT6: =IF(AG6=AF6,"na",_xlfn.XLOOKUP(AT$5,'OC-Days'!$G:$G,'OC-Days'!$F:$F)) -> na | AU6: =IF(AH6=AG6,"na",_xlfn.XLOOKUP(AU$5,'OC-Days'!$G:$G,'OC-Days'!$F:$F)) -> na | AV6: =IF(AI6=AH6,"na",_xlfn.XLOOKUP(AV$5,'OC-Days'!$G:$G,'OC-Days'!$F:$F)) -> na | AW6: =IF(AJ6=AI6,"na",_xlfn.XLOOKUP(AW$5,'OC-Days'!$G:$G,'OC-Days'!$F:$F)) -> na | AX6: =IF(AK6=AJ6,"na",_xlfn.XLOOKUP(AX$5,'OC-Days'!$G:$G,'OC-Days'!$F:$F)) -> na | AY6: =IF(AL6=AK6,"na",_xlfn.XLOOKUP(AY$5,'OC-Days'!$G:$G,'OC-Days'!$F:$F)) -> na | AZ6: =IF(AM6=AL6,"na",_xlfn.XLOOKUP(AZ$5,'OC-Days'!$G:$G,'OC-Days'!$F:$F)) -> na | BA6: =IF(AN6=AM6,"na",_xlfn.XLOOKUP(BA$5,'OC-Days'!$G:$G,'OC-Days'!$F:$F)) -> na | ... BD6: =IF(AQ6=AP6,"na",_xlfn.XLOOKUP(BD$5,'OC-Days'!$G:$G,'OC-Days'!$F:$F)) -> na | BF6: =IF(AT6="na",AT6,AT6-1) -> na | BG6: =IF(AU6="na",AU6,AU6-1) -> na | BH6: =IF(AV6="na",AV6,AV6-1) -> na | BI6: =IF(AW6="na",AW6,AW6-1) -> na | BJ6: =IF(AX6="na",AX6,AX6-1) -> na | BK6: =IF(AY6="na",AY6,AY6-1) -> na | BL6: =IF(AZ6="na",AZ6,AZ6-1) -> na | BM6: =IF(BA6="na",BA6,BA6-1) -> na | ... BP6: =IF(BD6="na",BD6,BD6-1) -> na | BQ6: =DATE(VALUE(RIGHT($BQ$5,4)),12,31) -> 46022 | BS6: =COUNT($AS6:AS6) -> 1 | BT6: =COUNT($AS6:AT6) -> 1 | BU6: =COUNT($AS6:AU6) -> 1 | BV6: =COUNT($AS6:AV6) -> 1 | BW6: =COUNT($AS6:AW6) -> 1 | BX6: =COUNT($AS6:AX6) -> 1 | BY6: =COUNT($AS6:AY6) -> 1 | BZ6: =COUNT($AS6:AZ6) -> 1 | ... CD6: =COUNT($AS6:BD6) -> 1 | CF6: =COUNT($BF6:BF6) -> 0 | CG6: =COUNT($BF6:BG6) -> 0 | CH6: =COUNT($BF6:BH6) -> 0 | CI6: =COUNT($BF6:BI6) -> 0 | CJ6: =COUNT($BF6:BJ6) -> 0 | CK6: =COUNT($BF6:BK6) -> 0 | CL6: =COUNT($BF6:BL6) -> 0 | CM6: =COUNT($BF6:BM6) -> 0 | ... CQ6: =COUNT($BF6:BQ6) -> 1 | CS6: =IF(SUM(D6:O6)=0,0,1) -> 1 | CT6: =CU6&CV6&C6 -> 10061Medicare A | CU6: =VALUE(LEFT(A6,3)) -> 100 | CV6: =VALUE(MID(A6,5,2)) -> 61 | CX6: =COUNT(AS6:BD6) -> 1 | CY6: =COUNT(BF6:BQ6) -> 1 | DA6: {=IF(DA$5<=$CX6,INDEX($AS6:$BD6,1,_xlfn.XMATCH(DA$5,$BS6:$CD6)),"na")} -> 45658 | DB6: {=IF(DB$5<=$CY6,INDEX($BF6:$BQ6,1,_xlfn.XMATCH(DB$5,$CF6:$CQ6)),"na")} -> 46022 | DC6: =_xlfn.XLOOKUP($CU6&"-"&$CV6&$C6,REF!$K$2:$K$90,REF!B$2:B$90) -> MEDICAREA/MC HMO | DD6: =_xlfn.XLOOKUP($CU6&"-"&$CV6&$C6,REF!$K$2:$K$90,REF!C$2:C$90) -> MEDICARE A HIGHMARK | DE6: =_xlfn.XLOOKUP($CU6&"-"&$CV6&$C6,REF!$K$2:$K$90,REF!D$2:D$90) -> ASBURY METHODIST VILLAGE | DF6: =_xlfn.XLOOKUP($CU6&"-"&$CV6&$C6,REF!$K$2:$K$90,REF!E$2:E$90) -> SKILLED NURSING | DG6: =_xlfn.XLOOKUP($CU6&"-"&$CV6&$C6,REF!$K$2:$K$90,REF!F$2:F$90) -> AMV - WILSON HEALTH CARE CENTER | DH6: {=IF(DH$5<=$CX6,INDEX($AF6:$AQ6,1,_xlfn.XMATCH(DH$5,$BS6:$CD6)),"na")} -> 1.995 | DI6: {=IF(DI$5<=$CX6,INDEX($AS6:$BD6,1,_xlfn.XMATCH(DI$5,$BS6:$CD6)),"na")} -> na | DJ6: {=IF(DJ$5<=$CY6,INDEX($BF6:$BQ6,1,_xlfn.XMATCH(DJ$5,$CF6:$CQ6)),"na")} -> na | DK6: =DC6 -> MEDICAREA/MC HMO | DL6: =DD6 -> MEDICARE A HIGHMARK | DM6: =DE6 -> ASBURY METHODIST VILLAGE | DN6: =DF6 -> SKILLED NURSING | DO6: =DG6 -> AMV - WILSON HEALTH CARE CENTER | DP6: {=IF(DP$5<=$CX6,INDEX($AF6:$AQ6,1,_xlfn.XMATCH(DP$5,$BS6:$CD6)),"na")} -> na | DQ6: {=IF(DQ$5<=$CX6,INDEX($AS6:$BD6,1,_xlfn.XMATCH(DQ$5,$BS6:$CD6)),"na")} -> na | DR6: {=IF(DR$5<=$CY6,INDEX($BF6:$BQ6,1,_xlfn.XMATCH(DR$5,$CF6:$CQ6)),"na")} -> na | DS6: =DK6 -> MEDICAREA/MC HMO | DT6: =DL6 -> MEDICARE A HIGHMARK | DU6: =DM6 -> ASBURY METHODIST VILLAGE | DV6: =DN6 -> SKILLED NURSING | DW6: =DO6 -> AMV - WILSON HEALTH CARE CENTER | DX6: {=IF(DX$5<=$CX6,INDEX($AF6:$AQ6,1,_xlfn.XMATCH(DX$5,$BS6:$CD6)),"na")} -> na | DY6: {=IF(DY$5<=$CX6,INDEX($AS6:$BD6,1,_xlfn.XMATCH(DY$5,$BS6:$CD6)),"na")} -> na | DZ6: {=IF(DZ$5<=$CY6,INDEX($BF6:$BQ6,1,_xlfn.XMATCH(DZ$5,$CF6:$CQ6)),"na")} -> na | EA6: =DS6 -> MEDICAREA/MC HMO | EB6: =DT6 -> MEDICARE A HIGHMARK | EC6: =DU6 -> ASBURY METHODIST VILLAGE | ED6: =DV6 -> SKILLED NURSING | EE6: =DW6 -> AMV - WILSON HEALTH CARE CENTER | EF6: {=IF(EF$5<=$CX6,INDEX($AF6:$AQ6,1,_xlfn.XMATCH(EF$5,$BS6:$CD6)),"na")} -> na | EG6: {=IF(EG$5<=$CX6,INDEX($AS6:$BD6,1,_xlfn.XMATCH(EG$5,$BS6:$CD6)),"na")} -> na | EH6: {=IF(EH$5<=$CY6,INDEX($BF6:$BQ6,1,_xlfn.XMATCH(EH$5,$CF6:$CQ6)),"na")} -> na | EI6: =EA6 -> MEDICAREA/MC HMO | EJ6: =EB6 -> MEDICARE A HIGHMARK | EK6: =EC6 -> ASBURY METHODIST VILLAGE | EL6: =ED6 -> SKILLED NURSING | EM6: =EE6 -> AMV - WILSON HEALTH CARE CENTER | EN6: {=IF(EN$5<=$CX6,INDEX($AF6:$AQ6,1,_xlfn.XMATCH(EN$5,$BS6:$CD6)),"na")} -> na | EO6: {=IF(EO$5<=$CX6,INDEX($AS6:$BD6,1,_xlfn.XMATCH(EO$5,$BS6:$CD6)),"na")} -> na | EP6: {=IF(EP$5<=$CY6,INDEX($BF6:$BQ6,1,_xlfn.XMATCH(EP$5,$CF6:$CQ6)),"na")} -> na | EQ6: =EI6 -> MEDICAREA/MC HMO | ER6: =EJ6 -> MEDICARE A HIGHMARK | ES6: =EK6 -> ASBURY METHODIST VILLAGE | ET6: =EL6 -> SKILLED NURSING | EU6: =EM6 -> AMV - WILSON HEALTH CARE CENTER | EV6: {=IF(EV$5<=$CX6,INDEX($AF6:$AQ6,1,_xlfn.XMATCH(EV$5,$BS6:$CD6)),"na")} -> na
