Workbook
Name _P: #REF!
Name basic: #REF!
Name Company: #REF!
Name CurrYr: [1]HQ!$B$19
Name CurrYrFCVersion: [1]HQ!$B$20
Name dental: #REF!
Name dentcode: #REF!
Name Depart: #REF!
Name Facility: #REF!
Name FillColMatch: '[1]OC-Fill'!$B$1:$NB$1
Name FillDataArray: INDIRECT(RIGHT('[1]OC-Fill'!$NI$6,LEN('[1]OC-Fill'!$NI$6)-1))
Name FillRowMatch: INDIRECT(RIGHT('[1]OC-Fill'!$NI$7,LEN('[1]OC-Fill'!$NI$7)-1))
Name FillSNFColMatch: '[1]OC-SNF Fill'!$B$1:$ET$1
Name FillSNFDataArray: '[1]OC-SNF Fill'!$B$9:$ET$30
Name FillSNFRowMatch: '[1]OC-SNF Fill'!$EV$9:$EV$30
Name health: #REF!
Name jobcode: #REF!
Name MainColMatch: '[1]OC-Main'!$B$1:$LS$1
Name MainDataArray: '[1]OC-Main'!$B$9:$LS$74
Name MainRowMatch: '[1]OC-Main'!$LT$9:$LT$74
Name medcode: #REF!
Name NextYr: [1]HQ!$B$21
Name parttm: #REF!
Name pension: #REF!
Name RaiseColMatch: '[1]OC-Raise'!$B$1:$D$1
Name RaiseDataArray: INDIRECT(RIGHT('[1]OC-Raise'!$I$2,LEN('[1]OC-Raise'!$I$2)-1))
Name RaiseRowMatch: INDIRECT(RIGHT('[1]OC-Raise'!$I$3,LEN('[1]OC-Raise'!$I$3)-1))
Name vachrs: #REF!
Name WASbasic: #REF!
Name WASmeddent: #REF!
Name workcomp: #REF!
Name workcompclass: #REF!

Sheet CrossfireHiddenWorksheet
A3: ff655d58-dd74-44a4-af34-c65de7737e90
A4: 13
M5: ='OC-Pull'!$6:$6 -> 0 | N5: 5 | O5: ='OC-Pull'!$B:$B -> Maximum Resident Days | P5: 1 | Q5: ='OC-Pull'!$B$3 -> FY2025 | R5: 67
M6: ='OC-Pull'!$7:$7 -> 0 | N6: 6 | O6: ='OC-Pull'!$C:$C -> 25732.5 | P6: 2 | Q6: ='OC-Pull'!$C$3 -> FY2025 | R6: 68
M7: ='OC-Pull'!$8:$8 -> 0 | N7: 7 | O7: ='OC-Pull'!$D:$D -> 0.97674419 | P7: 3 | Q7: ='OC-Pull'!$D$3 -> FY2025 | R7: 69
M8: ='OC-Pull'!$9:$9 -> 0 | N8: 8 | O8: ='OC-Pull'!$E:$E -> 0.58733191 | P8: 4 | Q8: ='OC-Pull'!$E$3 -> FY2025 | R8: 70
M9: ='OC-Pull'!$10:$10 -> 0 | N9: 9 | Q9: ='OC-Pull'!$B$4 -> Budget 2025 | R9: 71
M10: ='OC-Pull'!$11:$11 -> 0 | N10: 10 | Q10: ='OC-Pull'!$C$4 -> Budget 2025 | R10: 72
M11: ='OC-Pull'!$12:$12 -> 0 | N11: 11 | Q11: ='OC-Pull'!$D$4 -> Budget 2025 | R11: 73
M12: ='OC-Pull'!$13:$13 -> 0 | N12: 12 | Q12: ='OC-Pull'!$E$4 -> Budget 2025 | R12: 74
M13: ='OC-Pull'!$14:$14 -> 0 | N13: 13 | Q13: ='OC-Pull'!$B$5 -> Maximum Resident Days | R13: 75
M14: ='OC-Pull'!$15:$15 -> 0 | N14: 14 | Q14: ='OC-Pull'!$C$5 -> Forecasted Resident Days | R14: 76
M15: ='OC-Pull'!$16:$16 -> 0 | N15: 15 | Q15: ='OC-Pull'!$D$5 -> Forecasted Occ. % - Actual Available Units | R15: 77
M16: ='OC-Pull'!$17:$17 -> 0 | N16: 16 | Q16: ='OC-Pull'!$E$5 -> Forecasted Occ. % - Budget Available Units | R16: 78
M17: ='OC-Pull'!$18:$18 -> 0 | N17: 17 | Q17: ='OC-Pull'!$A$6 -> 100-21 Villas/Cottages | R17: 79
M18: ='OC-Pull'!$19:$19 -> 0 | N18: 18 | Q18: ='OC-Pull'!$A$7 -> 100-22 Villas/Cottages B (AMV=Courtyard Homes, BV=BV West, APKS=Patio Homes) | R18: 80
M19: ='OC-Pull'!$20:$20 -> 0 | N19: 19 | Q19: ='OC-Pull'!$A$8 -> 100-31 Apartment A (AMV=Trott, BV=Center, All others) | R19: 81
M20: ='OC-Pull'!$21:$21 -> 0 | N20: 20 | Q20: ='OC-Pull'!$A$9 -> 100-32 Apartment B (AMV=Diamond, BV=Court) | R20: 82
M21: ='OC-Pull'!$22:$22 -> 0 | N21: 21 | Q21: ='OC-Pull'!$A$10 -> 100-33 Apartment C (AMV=419 Wallace, BV=BVWest) | R21: 83
M22: ='OC-Pull'!$23:$23 -> 0 | N22: 22 | Q22: ='OC-Pull'!$A$11 -> 100-34 Apartment D (AMV=ParkView) | R22: 84
M23: ='OC-Pull'!$24:$24 -> 0 | N23: 23 | Q23: ='OC-Pull'!$A$12 -> 100-35 Apartment E (AMV=Edwards Fisher) | R23: 85
M24: ='OC-Pull'!$25:$25 -> 0 | N24: 24 | Q24: ='OC-Pull'!$A$13 -> 100-36 Apartment F (AMV=Mund) | R24: 86
M25: ='OC-Pull'!$26:$26 -> 0 | N25: 25 | Q25: ='OC-Pull'!$A$14 -> 100-51 AL/PC A | R25: 87
M26: ='OC-Pull'!$27:$27 -> 0 | N26: 26 | Q26: ='OC-Pull'!$A$15 -> 100-61 Skilled Nursing Facility | R26: 88
M27: ='OC-Pull'!$28:$28 -> 0 | N27: 27 | Q27: ='OC-Pull'!$A$16 -> 100-62 Skilled Nursing - TCU | R27: 89
M28: ='OC-Pull'!$36:$36 -> 0 | N28: 30 | Q28: ='OC-Pull'!$A$17 -> 100 Asbury Methodist Village | R28: 90
M29: ='OC-Pull'!$37:$37 -> 0 | N29: 31 | Q29: ='OC-Pull'!$A$18 -> 200-21 Villas/Cottages | R29: 91
M30: ='OC-Pull'!$38:$38 -> 0 | N30: 32 | Q30: ='OC-Pull'!$A$19 -> 200-31 Apartment A (AMV=Trott, BV=Center, AS=North Apts.) | R30: 92
M31: ='OC-Pull'!$39:$39 -> 0 | N31: 33 | Q31: ='OC-Pull'!$A$20 -> 200-32 Apartment B (AS=South Apts.) | R31: 93
M32: ='OC-Pull'!$40:$40 -> 0 | N32: 34 | Q32: ='OC-Pull'!$A$21 -> 200-51 AL/PC A | R32: 94
M33: ='OC-Pull'!$41:$41 -> 0 | N33: 35 | Q33: ='OC-Pull'!$A$22 -> 200-61 Skilled Nursing Facility | R33: 95
M34: ='OC-Pull'!$42:$42 -> 0 | N34: 36 | Q34: ='OC-Pull'!$A$23 -> 200 Asbury Solomons | R34: 96
M35: ='OC-Pull'!$43:$43 -> 0 | N35: 37 | Q35: ='OC-Pull'!$A$24 -> 324-21 Villas/Cottages | R35: 97
M36: ='OC-Pull'!$44:$44 -> 0 | N36: 38 | Q36: ='OC-Pull'!$A$25 -> 324-31 Apartment A (AMV=Trott, BV=Center, All others) | R36: 98
M37: ='OC-Pull'!$45:$45 -> 0 | N37: 39 | Q37: ='OC-Pull'!$A$26 -> 324-51 AL/PC A | R37: 99
M38: ='OC-Pull'!$46:$46 -> 0 | N38: 40 | Q38: ='OC-Pull'!$A$27 -> 324-61 Skilled Nursing Facility | R38: 100
M39: ='OC-Pull'!$47:$47 -> 0 | N39: 41 | Q39: ='OC-Pull'!$A$28 -> 324 Springhill | R39: 101
M40: ='OC-Pull'!$48:$48 -> 0 | N40: 44 | Q40: ='OC-Pull'!$A$36 -> 810-21 Villas/Cottages | R40: 104
M41: ='OC-Pull'!$49:$49 -> 0 | N41: 45 | Q41: ='OC-Pull'!$A$37 -> 810-22 Villas/Cottages B (AMV=Courtyard Homes, BV=BV West, APKS=Patio Homes) | R41: 105
M42: ='OC-Pull'!$50:$50 -> 0 | N42: 46 | Q42: ='OC-Pull'!$A$38 -> 810-31 Apartment A (AMV=Trott, BV=Center, All others) | R42: 106
...

Sheet OfficeConnectCellHighlights

Sheet Load 2025
A1: Qlik Load
A2: text | B2: text | C2: text | D2: f(x) | E2: f(x) | F2: text | G2: text
A3: Year | B3: Entity | C3: Facility | D3: Budget In Service (Days) | E3: Budget In Use (Days) | F3: Item Type | G3: Path
A4: 2025 | B4: 100 Asbury Methodist Village | C4: 21 Villas/Cottages | D4: =_xlfn.XLOOKUP(LEFT($B4,3)&"-"&LEFT($C4,2),Prep!$I$6:$I$67,Prep!B$6:B$67) -> 26645 | E4: =_xlfn.XLOOKUP(LEFT($B4,3)&"-"&LEFT($C4,2),Prep!$I$6:$I$67,Prep!C$6:C$67) -> 25732.5 | F4: Item | G4: ReportingandData/Dashboards/Lists/Budget Occupancy
A5: 2025 | B5: 100 Asbury Methodist Village | C5: 22 Villas/Cottages B | D5: =_xlfn.XLOOKUP(LEFT($B5,3)&"-"&LEFT($C5,2),Prep!$I$6:$I$67,Prep!B$6:B$67) -> 15695 | E5: =_xlfn.XLOOKUP(LEFT($B5,3)&"-"&LEFT($C5,2),Prep!$I$6:$I$67,Prep!C$6:C$67) -> 15330 | F5: Item | G5: ReportingandData/Dashboards/Lists/Budget Occupancy
A6: 2025 | B6: 100 Asbury Methodist Village | C6: 31 Apartment A | D6: =_xlfn.XLOOKUP(LEFT($B6,3)&"-"&LEFT($C6,2),Prep!$I$6:$I$67,Prep!B$6:B$67) -> 39785 | E6: =_xlfn.XLOOKUP(LEFT($B6,3)&"-"&LEFT($C6,2),Prep!$I$6:$I$67,Prep!C$6:C$67) -> 23367 | F6: Item | G6: ReportingandData/Dashboards/Lists/Budget Occupancy
A7: 2025 | B7: 100 Asbury Methodist Village | C7: 32 Apartment B | D7: =_xlfn.XLOOKUP(LEFT($B7,3)&"-"&LEFT($C7,2),Prep!$I$6:$I$67,Prep!B$6:B$67) -> 67160 | E7: =_xlfn.XLOOKUP(LEFT($B7,3)&"-"&LEFT($C7,2),Prep!$I$6:$I$67,Prep!C$6:C$67) -> 60052 | F7: Item | G7: ReportingandData/Dashboards/Lists/Budget Occupancy
A8: 2025 | B8: 100 Asbury Methodist Village | C8: 33 Apartment C | D8: =_xlfn.XLOOKUP(LEFT($B8,3)&"-"&LEFT($C8,2),Prep!$I$6:$I$67,Prep!B$6:B$67) -> 36135 | E8: =_xlfn.XLOOKUP(LEFT($B8,3)&"-"&LEFT($C8,2),Prep!$I$6:$I$67,Prep!C$6:C$67) -> 32850 | F8: Item | G8: ReportingandData/Dashboards/Lists/Budget Occupancy
A9: 2025 | B9: 100 Asbury Methodist Village | C9: 34 Apartment D | D9: =_xlfn.XLOOKUP(LEFT($B9,3)&"-"&LEFT($C9,2),Prep!$I$6:$I$67,Prep!B$6:B$67) -> 23725 | E9: =_xlfn.XLOOKUP(LEFT($B9,3)&"-"&LEFT($C9,2),Prep!$I$6:$I$67,Prep!C$6:C$67) -> 20989 | F9: Item | G9: ReportingandData/Dashboards/Lists/Budget Occupancy
A10: 2025 | B10: 100 Asbury Methodist Village | C10: 35 Apartment E | D10: =_xlfn.XLOOKUP(LEFT($B10,3)&"-"&LEFT($C10,2),Prep!$I$6:$I$67,Prep!B$6:B$67) -> 45990 | E10: =_xlfn.XLOOKUP(LEFT($B10,3)&"-"&LEFT($C10,2),Prep!$I$6:$I$67,Prep!C$6:C$67) -> 35956 | F10: Item | G10: ReportingandData/Dashboards/Lists/Budget Occupancy
A11: 2025 | B11: 100 Asbury Methodist Village | C11: 36 Apartment F | D11: =_xlfn.XLOOKUP(LEFT($B11,3)&"-"&LEFT($C11,2),Prep!$I$6:$I$67,Prep!B$6:B$67) -> 45990 | E11: =_xlfn.XLOOKUP(LEFT($B11,3)&"-"&LEFT($C11,2),Prep!$I$6:$I$67,Prep!C$6:C$67) -> 30118 | F11: Item | G11: ReportingandData/Dashboards/Lists/Budget Occupancy
A12: 2025 | B12: 100 Asbury Methodist Village | C12: 51 Assisted Living A | D12: =_xlfn.XLOOKUP(LEFT($B12,3)&"-"&LEFT($C12,2),Prep!$I$6:$I$67,Prep!B$6:B$67) -> 48545 | E12: =_xlfn.XLOOKUP(LEFT($B12,3)&"-"&LEFT($C12,2),Prep!$I$6:$I$67,Prep!C$6:C$67) -> 45260 | F12: Item | G12: ReportingandData/Dashboards/Lists/Budget Occupancy
A13: 2025 | B13: 100 Asbury Methodist Village | C13: 61 Skilled Nursing Facility | D13: =_xlfn.XLOOKUP(LEFT($B13,3)&"-"&LEFT($C13,2),Prep!$I$6:$I$67,Prep!B$6:B$67) -> 50735 | E13: =_xlfn.XLOOKUP(LEFT($B13,3)&"-"&LEFT($C13,2),Prep!$I$6:$I$67,Prep!C$6:C$67) -> 48545 | F13: Item | G13: ReportingandData/Dashboards/Lists/Budget Occupancy
A14: 2025 | B14: 100 Asbury Methodist Village | C14: 62 Skilled Nursing - Household | D14: =_xlfn.XLOOKUP(LEFT($B14,3)&"-"&LEFT($C14,2),Prep!$I$6:$I$67,Prep!B$6:B$67) -> 16790 | E14: =_xlfn.XLOOKUP(LEFT($B14,3)&"-"&LEFT($C14,2),Prep!$I$6:$I$67,Prep!C$6:C$67) -> 16425 | F14: Item | G14: ReportingandData/Dashboards/Lists/Budget Occupancy
A15: 2025 | B15: 200 Asbury Solomons | C15: 21 Villas/Cottages | D15: =_xlfn.XLOOKUP(LEFT($B15,3)&"-"&LEFT($C15,2),Prep!$I$6:$I$67,Prep!B$6:B$67) -> 26280 | E15: =_xlfn.XLOOKUP(LEFT($B15,3)&"-"&LEFT($C15,2),Prep!$I$6:$I$67,Prep!C$6:C$67) -> 25915 | F15: Item | G15: ReportingandData/Dashboards/Lists/Budget Occupancy
... A23: 2025 | B23: 324 Springhill | C23: 61 Skilled Nursing Facility | D23: =_xlfn.XLOOKUP(LEFT($B23,3)&"-"&LEFT($C23,2),Prep!$I$6:$I$67,Prep!B$6:B$67) -> 27740 | E23: =_xlfn.XLOOKUP(LEFT($B23,3)&"-"&LEFT($C23,2),Prep!$I$6:$I$67,Prep!C$6:C$67) -> 26645 | F23: Item | G23: ReportingandData/Dashboards/Lists/Budget Occupancy
A24: 2025 | B24: 350 Grace Park | C24: =C29 -> 21 Villas/Cottages | D24: =_xlfn.XLOOKUP(LEFT($B24,3)&"-"&LEFT($C24,2),Prep!$I$6:$I$67,Prep!B$6:B$67) -> 4745 | E24: =_xlfn.XLOOKUP(LEFT($B24,3)&"-"&LEFT($C24,2),Prep!$I$6:$I$67,Prep!C$6:C$67) -> 4380 | F24: Item | G24: ReportingandData/Dashboards/Lists/Budget Occupancy
A25: 2025 | B25: 350 Grace Park | C25: =C42 -> 51 Assisted Living A | D25: =_xlfn.XLOOKUP(LEFT($B25,3)&"-"&LEFT($C25,2),Prep!$I$6:$I$67,Prep!B$6:B$67) -> 25550 | E25: =_xlfn.XLOOKUP(LEFT($B25,3)&"-"&LEFT($C25,2),Prep!$I$6:$I$67,Prep!C$6:C$67) -> 24090 | F25: Item | G25: ReportingandData/Dashboards/Lists/Budget Occupancy
A26: 2025 | B26: 350 Grace Park | C26: =C43 -> 52 Assisted Living B | D26: =_xlfn.XLOOKUP(LEFT($B26,3)&"-"&LEFT($C26,2),Prep!$I$6:$I$67,Prep!B$6:B$67) -> 4380 | E26: =_xlfn.XLOOKUP(LEFT($B26,3)&"-"&LEFT($C26,2),Prep!$I$6:$I$67,Prep!C$6:C$67) -> 4015 | F26: Item | G26: ReportingandData/Dashboards/Lists/Budget Occupancy
A27: 2025 | B27: 360 Ivy Gables | C27: =C25 -> 51 Assisted Living A | D27: =_xlfn.XLOOKUP(LEFT($B27,3)&"-"&LEFT($C27,2),Prep!$I$6:$I$67,Prep!B$6:B$67) -> 15695 | E27: =_xlfn.XLOOKUP(LEFT($B27,3)&"-"&LEFT($C27,2),Prep!$I$6:$I$67,Prep!C$6:C$67) -> 13325 | F27: Item | G27: ReportingandData/Dashboards/Lists/Budget Occupancy
A28: 2025 | B28: 360 Ivy Gables | C28: =C26 -> 52 Assisted Living B | D28: =_xlfn.XLOOKUP(LEFT($B28,3)&"-"&LEFT($C28,2),Prep!$I$6:$I$67,Prep!B$6:B$67) -> 3285 | E28: =_xlfn.XLOOKUP(LEFT($B28,3)&"-"&LEFT($C28,2),Prep!$I$6:$I$67,Prep!C$6:C$67) -> 2920 | F28: Item | G28: ReportingandData/Dashboards/Lists/Budget Occupancy
A29: 2025 | B29: 810 Bethany Village | C29: 21 Villas/Cottages | D29: =_xlfn.XLOOKUP(LEFT($B29,3)&"-"&LEFT($C29,2),Prep!$I$6:$I$67,Prep!B$6:B$67) -> 34675 | E29: =_xlfn.XLOOKUP(LEFT($B29,3)&"-"&LEFT($C29,2),Prep!$I$6:$I$67,Prep!C$6:C$67) -> 33945 | F29: Item | G29: ReportingandData/Dashboards/Lists/Budget Occupancy
A30: 2025 | B30: 810 Bethany Village | C30: 22 Villas/Cottages B | D30: =_xlfn.XLOOKUP(LEFT($B30,3)&"-"&LEFT($C30,2),Prep!$I$6:$I$67,Prep!B$6:B$67) -> 17155 | E30: =_xlfn.XLOOKUP(LEFT($B30,3)&"-"&LEFT($C30,2),Prep!$I$6:$I$67,Prep!C$6:C$67) -> 16790 | F30: Item | G30: ReportingandData/Dashboards/Lists/Budget Occupancy
A31: 2025 | B31: 810 Bethany Village | C31: 31 Apartment A | D31: =_xlfn.XLOOKUP(LEFT($B31,3)&"-"&LEFT($C31,2),Prep!$I$6:$I$67,Prep!B$6:B$67) -> 6205 | E31: =_xlfn.XLOOKUP(LEFT($B31,3)&"-"&LEFT($C31,2),Prep!$I$6:$I$67,Prep!C$6:C$67) -> 5840 | F31: Item | G31: ReportingandData/Dashboards/Lists/Budget Occupancy
A32: 2025 | B32: 810 Bethany Village | C32: 32 Apartment B | D32: =_xlfn.XLOOKUP(LEFT($B32,3)&"-"&LEFT($C32,2),Prep!$I$6:$I$67,Prep!B$6:B$67) -> 34310 | E32: =_xlfn.XLOOKUP(LEFT($B32,3)&"-"&LEFT($C32,2),Prep!$I$6:$I$67,Prep!C$6:C$67) -> 31207.5 | F32: Item | G32: ReportingandData/Dashboards/Lists/Budget Occupancy
A33: 2025 | B33: 810 Bethany Village | C33: 33 Apartment C | D33: =_xlfn.XLOOKUP(LEFT($B33,3)&"-"&LEFT($C33,2),Prep!$I$6:$I$67,Prep!B$6:B$67) -> 50370 | E33: =_xlfn.XLOOKUP(LEFT($B33,3)&"-"&LEFT($C33,2),Prep!$I$6:$I$67,Prep!C$6:C$67) -> 48180 | F33: Item | G33: ReportingandData/Dashboards/Lists/Budget Occupancy
A34: 2025 | B34: 810 Bethany Village | C34: 51 Assisted Living A | D34: =_xlfn.XLOOKUP(LEFT($B34,3)&"-"&LEFT($C34,2),Prep!$I$6:$I$67,Prep!B$6:B$67) -> 36500 | E34: =_xlfn.XLOOKUP(LEFT($B34,3)&"-"&LEFT($C34,2),Prep!$I$6:$I$67,Prep!C$6:C$67) -> 35222.5 | F34: Item | G34: ReportingandData/Dashboards/Lists/Budget Occupancy
A35: 2025 | B35: 810 Bethany Village | C35: 61 Skilled Nursing Facility | D35: =_xlfn.XLOOKUP(LEFT($B35,3)&"-"&LEFT($C35,2),Prep!$I$6:$I$67,Prep!B$6:B$67) -> 25185 | E35: =_xlfn.XLOOKUP(LEFT($B35,3)&"-"&LEFT($C35,2),Prep!$I$6:$I$67,Prep!C$6:C$67) -> 24090 | F35: Item | G35: ReportingandData/Dashboards/Lists/Budget Occupancy
A36: 2025 | B36: 835 Riverwoods | C36: 21 Villas/Cottages | D36: =_xlfn.XLOOKUP(LEFT($B36,3)&"-"&LEFT($C36,2),Prep!$I$6:$I$67,Prep!B$6:B$67) -> 18615 | E36: =_xlfn.XLOOKUP(LEFT($B36,3)&"-"&LEFT($C36,2),Prep!$I$6:$I$67,Prep!C$6:C$67) -> 17520 | F36: Item | G36: ReportingandData/Dashboards/Lists/Budget Occupancy
A37: 2025 | B37: 835 Riverwoods | C37: 31 Apartment A | D37: =_xlfn.XLOOKUP(LEFT($B37,3)&"-"&LEFT($C37,2),Prep!$I$6:$I$67,Prep!B$6:B$67) -> 28470 | E37: =_xlfn.XLOOKUP(LEFT($B37,3)&"-"&LEFT($C37,2),Prep!$I$6:$I$67,Prep!C$6:C$67) -> 26280 | F37: Item | G37: ReportingandData/Dashboards/Lists/Budget Occupancy
A38: 2025 | B38: 835 Riverwoods | C38: 51 Assisted Living A | D38: =_xlfn.XLOOKUP(LEFT($B38,3)&"-"&LEFT($C38,2),Prep!$I$6:$I$67,Prep!B$6:B$67) -> 13870 | E38: =_xlfn.XLOOKUP(LEFT($B38,3)&"-"&LEFT($C38,2),Prep!$I$6:$I$67,Prep!C$6:C$67) -> 12899.1 | F38: Item | G38: ReportingandData/Dashboards/Lists/Budget Occupancy
A39: 2025 | B39: 835 Riverwoods | C39: 61 Skilled Nursing Facility | D39: =_xlfn.XLOOKUP(LEFT($B39,3)&"-"&LEFT($C39,2),Prep!$I$6:$I$67,Prep!B$6:B$67) -> 0 | E39: =_xlfn.XLOOKUP(LEFT($B39,3)&"-"&LEFT($C39,2),Prep!$I$6:$I$67,Prep!C$6:C$67) -> 0 | F39: Item | G39: ReportingandData/Dashboards/Lists/Budget Occupancy
A40: 2025 | B40: 840 Normandie Ridge | C40: 21 Villas/Cottages | D40: =_xlfn.XLOOKUP(LEFT($B40,3)&"-"&LEFT($C40,2),Prep!$I$6:$I$67,Prep!B$6:B$67) -> 24090 | E40: =_xlfn.XLOOKUP(LEFT($B40,3)&"-"&LEFT($C40,2),Prep!$I$6:$I$67,Prep!C$6:C$67) -> 22630 | F40: Item | G40: ReportingandData/Dashboards/Lists/Budget Occupancy
... A47: 2025 | B47: 925 Chandler Estate | C47: 51 Assisted Living A | D47: =_xlfn.XLOOKUP(LEFT($B47,3)&"-"&LEFT($C47,2),Prep!$I$6:$I$67,Prep!B$6:B$67) -> 14235 | E47: =_xlfn.XLOOKUP(LEFT($B47,3)&"-"&LEFT($C47,2),Prep!$I$6:$I$67,Prep!C$6:C$67) -> 13505 | F47: Item | G47: ReportingandData/Dashboards/Lists/Budget Occupancy

Sheet Prep
A1: Office Connect Data - Copy and Pasted from OC-Pull tab | C1: Office Connect Data - Copy and Pasted from OC-Pull tab | G1: f(x) | H1: f(x) | I1: f(x)
B3: ='OC-Pull'!B3 -> FY2025 | C3: ='OC-Pull'!C3 -> FY2025 | D3: ='OC-Pull'!D3 -> FY2025 | E3: ='OC-Pull'!E3 -> FY2025
B4: ='OC-Pull'!B4 -> Budget 2025 | C4: ='OC-Pull'!C4 -> Budget 2025 | D4: ='OC-Pull'!D4 -> Budget 2025 | E4: ='OC-Pull'!E4 -> Budget 2025
B5: ='OC-Pull'!B5 -> Maximum Resident Days | C5: ='OC-Pull'!C5 -> Forecasted Resident Days | D5: ='OC-Pull'!D5 -> Forecasted Occ. % - Actual Available Units | E5: ='OC-Pull'!E5 -> Forecasted Occ. % - Budget Available Units | G5: Ent | H5: Fac | I5: Ent-Fac | J5: Match
A6: 100-21 Villas/Cottages | B6: 26645 | C6: 25732.5 | D6: 0.96575342 | E6: 0.96575342 | G6: =IFERROR(VALUE(LEFT(A6,3)),"Rollup") -> 100 | H6: =IFERROR(VALUE(MID(A6,5,2)),IF(ISNUMBER(G6),"Entity",G6)) -> 21 | I6: =G6&"-"&H6 -> 100-21 | J6: =_xlfn.XMATCH(I6,#REF!) -> #REF!
A7: 100-22 Villas/Cottages B (AMV=Courtyard Homes, BV=BV West, APKS=Patio Homes) | B7: 15695 | C7: 15330 | D7: 0.97674419 | E7: 0.97674419 | G7: =IFERROR(VALUE(LEFT(A7,3)),"Rollup") -> 100 | H7: =IFERROR(VALUE(MID(A7,5,2)),IF(ISNUMBER(G7),"Entity",G7)) -> 22 | I7: =G7&"-"&H7 -> 100-22 | J7: =_xlfn.XMATCH(I7,#REF!) -> #REF!
A8: 100-31 Apartment A (AMV=Trott, BV=Center, All others) | B8: 39785 | C8: 23367 | D8: 0.58733191 | E8: 0.58733191 | G8: =IFERROR(VALUE(LEFT(A8,3)),"Rollup") -> 100 | H8: =IFERROR(VALUE(MID(A8,5,2)),IF(ISNUMBER(G8),"Entity",G8)) -> 31 | I8: =G8&"-"&H8 -> 100-31 | J8: =_xlfn.XMATCH(I8,#REF!) -> #REF!
A9: 100-32 Apartment B (AMV=Diamond, BV=Court) | B9: 67160 | C9: 60052 | D9: 0.89416319 | E9: 0.89416319 | G9: =IFERROR(VALUE(LEFT(A9,3)),"Rollup") -> 100 | H9: =IFERROR(VALUE(MID(A9,5,2)),IF(ISNUMBER(G9),"Entity",G9)) -> 32 | I9: =G9&"-"&H9 -> 100-32 | J9: =_xlfn.XMATCH(I9,#REF!) -> #REF!
A10: 100-33 Apartment C (AMV=419 Wallace, BV=BVWest) | B10: 36135 | C10: 32850 | D10: 0.90909091 | E10: 0.90909091 | G10: =IFERROR(VALUE(LEFT(A10,3)),"Rollup") -> 100 | H10: =IFERROR(VALUE(MID(A10,5,2)),IF(ISNUMBER(G10),"Entity",G10)) -> 33 | I10: =G10&"-"&H10 -> 100-33 | J10: =_xlfn.XMATCH(I10,#REF!) -> #REF!
A11: 100-34 Apartment D (AMV=ParkView) | B11: 23725 | C11: 20989 | D11: 0.88467861 | E11: 0.88467861 | G11: =IFERROR(VALUE(LEFT(A11,3)),"Rollup") -> 100 | H11: =IFERROR(VALUE(MID(A11,5,2)),IF(ISNUMBER(G11),"Entity",G11)) -> 34 | I11: =G11&"-"&H11 -> 100-34 | J11: =_xlfn.XMATCH(I11,#REF!) -> #REF!
A12: 100-35 Apartment E (AMV=Edwards Fisher) | B12: 45990 | C12: 35956 | D12: 0.78182214 | E12: 0.78182214 | G12: =IFERROR(VALUE(LEFT(A12,3)),"Rollup") -> 100 | H12: =IFERROR(VALUE(MID(A12,5,2)),IF(ISNUMBER(G12),"Entity",G12)) -> 35 | I12: =G12&"-"&H12 -> 100-35 | J12: =_xlfn.XMATCH(I12,#REF!) -> #REF!
A13: 100-36 Apartment F (AMV=Mund) | B13: 45990 | C13: 30118 | D13: 0.6548815 | E13: 0.6548815 | G13: =IFERROR(VALUE(LEFT(A13,3)),"Rollup") -> 100 | H13: =IFERROR(VALUE(MID(A13,5,2)),IF(ISNUMBER(G13),"Entity",G13)) -> 36 | I13: =G13&"-"&H13 -> 100-36 | J13: =_xlfn.XMATCH(I13,#REF!) -> #REF!
A14: 100-51 AL/PC A | B14: 48545 | C14: 45260 | D14: 0.93233083 | E14: 0.93233083 | G14: =IFERROR(VALUE(LEFT(A14,3)),"Rollup") -> 100 | H14: =IFERROR(VALUE(MID(A14,5,2)),IF(ISNUMBER(G14),"Entity",G14)) -> 51 | I14: =G14&"-"&H14 -> 100-51 | J14: =_xlfn.XMATCH(I14,#REF!) -> #REF!
A15: 100-61 Skilled Nursing Facility | B15: 50735 | C15: 48545 | D15: 0.95683453 | E15: 0.95683453 | G15: =IFERROR(VALUE(LEFT(A15,3)),"Rollup") -> 100 | H15: =IFERROR(VALUE(MID(A15,5,2)),IF(ISNUMBER(G15),"Entity",G15)) -> 61 | I15: =G15&"-"&H15 -> 100-61 | J15: =_xlfn.XMATCH(I15,#REF!) -> #REF!
A16: 100-62 Skilled Nursing - TCU | B16: 16790 | C16: 16425 | D16: 0.97826087 | E16: 0.97826087 | G16: =IFERROR(VALUE(LEFT(A16,3)),"Rollup") -> 100 | H16: =IFERROR(VALUE(MID(A16,5,2)),IF(ISNUMBER(G16),"Entity",G16)) -> 62 | I16: =G16&"-"&H16 -> 100-62 | J16: =_xlfn.XMATCH(I16,#REF!) -> #REF!
A17: 100 Asbury Methodist Village | B17: 417195 | C17: 354624.5 | D17: 0.85002097 | E17: 0.85002097 | G17: =IFERROR(VALUE(LEFT(A17,3)),"Rollup") -> 100 | H17: =IFERROR(VALUE(MID(A17,5,2)),IF(ISNUMBER(G17),"Entity",G17)) -> Entity | I17: =G17&"-"&H17 -> 100-Entity | J17: =_xlfn.XMATCH(I17,#REF!) -> #REF!
... A59: Asbury Communities (Consolidated) | B59: 1097920 | C59: 996968.6 | D59: 0.90805213 | E59: 0.90805213 | G59: =IFERROR(VALUE(LEFT(A59,3)),"Rollup") -> Rollup | H59: =IFERROR(VALUE(MID(A59,5,2)),IF(ISNUMBER(G59),"Entity",G59)) -> Rollup | I59: =G59&"-"&H59 -> Rollup-Rollup | J59: =_xlfn.XMATCH(I59,#REF!) -> #REF!
A61: Check | B61: =B59-SUMIFS(B$6:B$58,$H$6:$H$58,"<>Entity") -> 0 | C61: =C59-SUMIFS(C$6:C$58,$H$6:$H$58,"<>Entity") -> 0

Sheet OC-Pull
B3: FY2025 | C3: FY2025 | D3: FY2025 | E3: FY2025
B4: Budget 2025 | C4: Budget 2025 | D4: Budget 2025 | E4: Budget 2025
B5: Maximum Resident Days | C5: Forecasted Resident Days | D5: Forecasted Occ. % - Actual Available Units | E5: Forecasted Occ. % - Budget Available Units
A6: 100-21 Villas/Cottages | B6: 26645 | C6: 25732.5 | D6: 0.96575342 | E6: 0.96575342
A7: 100-22 Villas/Cottages B (AMV=Courtyard Homes, BV=BV West, APKS=Patio Homes) | B7: 15695 | C7: 15330 | D7: 0.97674419 | E7: 0.97674419
A8: 100-31 Apartment A (AMV=Trott, BV=Center, All others) | B8: 39785 | C8: 23367 | D8: 0.58733191 | E8: 0.58733191
A9: 100-32 Apartment B (AMV=Diamond, BV=Court) | B9: 67160 | C9: 60052 | D9: 0.89416319 | E9: 0.89416319
A10: 100-33 Apartment C (AMV=419 Wallace, BV=BVWest) | B10: 36135 | C10: 32850 | D10: 0.90909091 | E10: 0.90909091
A11: 100-34 Apartment D (AMV=ParkView) | B11: 23725 | C11: 20989 | D11: 0.88467861 | E11: 0.88467861
A12: 100-35 Apartment E (AMV=Edwards Fisher) | B12: 45990 | C12: 35956 | D12: 0.78182214 | E12: 0.78182214
A13: 100-36 Apartment F (AMV=Mund) | B13: 45990 | C13: 30118 | D13: 0.6548815 | E13: 0.6548815
A14: 100-51 AL/PC A | B14: 48545 | C14: 45260 | D14: 0.93233083 | E14: 0.93233083
A15: 100-61 Skilled Nursing Facility | B15: 50735 | C15: 48545 | D15: 0.95683453 | E15: 0.95683453
A16: 100-62 Skilled Nursing - TCU | B16: 16790 | C16: 16425 | D16: 0.97826087 | E16: 0.97826087
A17: 100 Asbury Methodist Village | B17: 417195 | C17: 354624.5 | D17: 0.85002097 | E17: 0.85002097
... A59: Asbury Communities (Consolidated) | B59: 1097920 | C59: 996968.6 | D59: 0.90805213 | E59: 0.90805213
