Workbook
Name _P: #REF!
Name basic: #REF!
Name Company: #REF!
Name CurrYr: [1]HQ!$B$19
Name CurrYr: [2]HQ!$B$19
Name CurrYrFCVersion: [1]HQ!$B$20
Name CurrYrFCVersion: [2]HQ!$B$20
Name dental: #REF!
Name dentcode: #REF!
Name Depart: #REF!
Name Facility: #REF!
Name FillColMatch: '[1]OC-Fill'!$B$1:$NB$1
Name FillColMatch: '[2]OC-Fill'!$B$1:$NB$1
Name FillDataArray: INDIRECT(RIGHT('[1]OC-Fill'!$NI$6,LEN('[1]OC-Fill'!$NI$6)-1))
Name FillDataArray: INDIRECT(RIGHT('[2]OC-Fill'!$NI$6,LEN('[2]OC-Fill'!$NI$6)-1))
Name FillRowMatch: INDIRECT(RIGHT('[1]OC-Fill'!$NI$7,LEN('[1]OC-Fill'!$NI$7)-1))
Name FillRowMatch: INDIRECT(RIGHT('[2]OC-Fill'!$NI$7,LEN('[2]OC-Fill'!$NI$7)-1))
Name FillSNFColMatch: '[1]OC-SNF Fill'!$B$1:$CX$1
Name FillSNFColMatch: '[2]OC-SNF Fill'!$B$1:$ET$1
Name FillSNFDataArray: '[1]OC-SNF Fill'!$B$9:$CX$15
Name FillSNFDataArray: '[2]OC-SNF Fill'!$B$9:$ET$30
Name FillSNFRowMatch: '[1]OC-SNF Fill'!$CZ$9:$CZ$15
Name FillSNFRowMatch: '[2]OC-SNF Fill'!$EV$9:$EV$30
Name health: #REF!
Name jobcode: #REF!
Name MainColMatch: '[1]OC-Main'!$B$1:$LD$1
Name MainColMatch: '[2]OC-Main'!$B$1:$LS$1
Name MainDataArray: '[1]OC-Main'!$B$9:$LD$74
Name MainDataArray: '[2]OC-Main'!$B$9:$LS$74
Name MainRowMatch: '[1]OC-Main'!$LE$9:$LE$74
Name MainRowMatch: '[2]OC-Main'!$LT$9:$LT$74
Name medcode: #REF!
Name NextYr: [1]HQ!$B$21
Name NextYr: [2]HQ!$B$21
Name parttm: #REF!
Name pension: #REF!
Name RaiseColMatch: '[1]OC-Raise'!$B$1:$D$1
Name RaiseColMatch: '[2]OC-Raise'!$B$1:$D$1
Name RaiseDataArray: INDIRECT(RIGHT('[1]OC-Raise'!$I$2,LEN('[1]OC-Raise'!$I$2)-1))
Name RaiseDataArray: INDIRECT(RIGHT('[2]OC-Raise'!$I$2,LEN('[2]OC-Raise'!$I$2)-1))
Name RaiseRowMatch: INDIRECT(RIGHT('[1]OC-Raise'!$I$3,LEN('[1]OC-Raise'!$I$3)-1))
Name RaiseRowMatch: INDIRECT(RIGHT('[2]OC-Raise'!$I$3,LEN('[2]OC-Raise'!$I$3)-1))
Name vachrs: #REF!
Name WASbasic: #REF!
Name WASmeddent: #REF!
Name workcomp: #REF!
Name workcompclass: #REF!

Sheet CrossfireHiddenWorksheet
A3: c6d463ac-99dd-4e17-9213-ada598534116 | B3: 34864750-36d0-48eb-b30f-296de4ba20f4
A4: 7 | B4: 13
G5: =OC!$6:$6 -> 2263 | H5: 1 | I5: =OC!$C:$C -> Jan-2025 | J5: 67 | K5: =OC!$C$3 -> Budget 2025 | L5: 91 | M5: ='OC-Days'!$14:$14 -> 0 | N5: 1 | O5: ='OC-Days'!$B:$B -> 31 | P5: 37
G6: =OC!$7:$7 -> 1333 | H6: 2 | I6: =OC!$D:$D -> 2044 | J6: 68 | K6: =OC!$D$3 -> Budget 2025 | L6: 92 | M6: ='OC-Days'!$13:$13 -> 0 | N6: 2
G7: =OC!$8:$8 -> 3379 | H7: 3 | I7: =OC!$E:$E -> 1333 | J7: 69 | K7: =OC!$E$3 -> Budget 2025 | L7: 93 | M7: ='OC-Days'!$12:$12 -> 0 | N7: 3
G8: =OC!$9:$9 -> 5704 | H8: 4 | I8: =OC!$F:$F -> 3270 | J8: 70 | K8: =OC!$F$3 -> Budget 2025 | L8: 94 | M8: ='OC-Days'!$11:$11 -> 0 | N8: 4
G9: =OC!$10:$10 -> 3069 | H9: 5 | I9: =OC!$G:$G -> 5704 | J9: 71 | K9: =OC!$G$3 -> Budget 2025 | L9: 95 | M9: ='OC-Days'!$10:$10 -> 0 | N9: 5
G10: =OC!$11:$11 -> 2015 | H10: 6 | I10: =OC!$H:$H -> 2970 | J10: 72 | K10: =OC!$H$3 -> Budget 2025 | L10: 96 | M10: ='OC-Days'!$9:$9 -> 0 | N10: 6
G11: =OC!$12:$12 -> 3906 | H11: 7 | I11: =OC!$I:$I -> 2015 | J11: 73 | K11: =OC!$I$3 -> Budget 2025 | L11: 97 | M11: ='OC-Days'!$8:$8 -> 0 | N11: 7
G12: =OC!$13:$13 -> 3906 | H12: 8 | I12: =OC!$J:$J -> 3906 | J12: 74 | K12: =OC!$J$3 -> Budget 2025 | L12: 98 | M12: ='OC-Days'!$7:$7 -> 0 | N12: 8
G13: =OC!$14:$14 -> 4123 | H13: 9 | I13: =OC!$K:$K -> 3780 | J13: 75 | K13: =OC!$K$3 -> Budget 2025 | L13: 99 | M13: ='OC-Days'!$6:$6 -> 0 | N13: 9
G14: =OC!$15:$15 -> 4309 | H14: 10 | I14: =OC!$L:$L -> 4123 | J14: 76 | K14: =OC!$L$3 -> Budget 2025 | L14: 100 | M14: ='OC-Days'!$5:$5 -> 0 | N14: 10
G15: =OC!$16:$16 -> 1426 | H15: 11 | I15: =OC!$M:$M -> 4170 | J15: 77 | K15: =OC!$M$3 -> Budget 2025 | L15: 101 | M15: ='OC-Days'!$4:$4 -> 0 | N15: 11
G16: =OC!$17:$17 -> 35433 | H16: 12 | I16: =OC!$N:$N -> 1426 | J16: 78 | K16: =OC!$N$3 -> Budget 2025 | L16: 102 | M16: ='OC-Days'!$3:$3 -> 0 | N16: 12
G17: =OC!$18:$18 -> 2232 | H17: 13 | I17: =OC!$P:$P -> 29713.5 | J17: 79 | K17: =OC!$P$3 -> Budget 2025 | L17: 104 | M17: ='OC-Days'!$26:$26 -> 0 | N17: 13
G18: =OC!$19:$19 -> 4402 | H18: 14 | I18: =OC!$Q:$Q -> 1988 | J18: 80 | K18: =OC!$Q$3 -> Budget 2025 | L18: 105 | M18: ='OC-Days'!$25:$25 -> 0 | N18: 14
G19: =OC!$20:$20 -> 2666 | H19: 15 | I19: =OC!$R:$R -> 4154 | J19: 81 | K19: =OC!$R$3 -> Budget 2025 | L19: 106 | M19: ='OC-Days'!$24:$24 -> 0 | N19: 15
G20: =OC!$21:$21 -> 744 | H20: 16 | I20: =OC!$S:$S -> 2490 | J20: 82 | K20: =OC!$S$3 -> Budget 2025 | L20: 107 | M20: ='OC-Days'!$23:$23 -> 0 | N20: 16
G21: =OC!$22:$22 -> 1488 | H21: 17 | I21: =OC!$T:$T -> 728.5 | J21: 83 | K21: =OC!$T$3 -> Budget 2025 | L21: 108 | M21: ='OC-Days'!$22:$22 -> 0 | N21: 17
G22: =OC!$23:$23 -> 11532 | H22: 18 | I22: =OC!$U:$U -> 1125 | J22: 84 | K22: =OC!$U$3 -> Budget 2025 | L22: 109 | M22: ='OC-Days'!$21:$21 -> 0 | N22: 18
G23: =OC!$24:$24 -> 1116 | H23: 19 | I23: =OC!$V:$V -> 10819 | J23: 85 | K23: =OC!$V$3 -> Budget 2025 | L23: 110 | M23: ='OC-Days'!$20:$20 -> 0 | N23: 19
G24: =OC!$25:$25 -> 3813 | H24: 20 | I24: =OC!$W:$W -> 1085 | J24: 86 | K24: =OC!$W$3 -> Budget 2025 | L24: 111 | M24: ='OC-Days'!$19:$19 -> 0 | N24: 20
G25: =OC!$26:$26 -> 1085 | H25: 21 | I25: =OC!$X:$X -> 3390 | J25: 87 | K25: =OC!$X$3 -> Budget 2025 | L25: 112 | M25: ='OC-Days'!$18:$18 -> 0 | N25: 21
G26: =OC!$27:$27 -> 2356 | H26: 22 | I26: =OC!$Y:$Y -> 1023 | J26: 88 | K26: =OC!$Y$3 -> Budget 2025 | L26: 113 | M26: ='OC-Days'!$17:$17 -> 0 | N26: 22
G27: =OC!$28:$28 -> 8370 | H27: 23 | I27: =OC!$Z:$Z -> 2190 | J27: 89 | K27: =OC!$Z$3 -> Budget 2025 | L27: 114 | M27: ='OC-Days'!$16:$16 -> 0 | N27: 23
G28: =OC!$32:$32 -> 2945 | H28: 24 | I28: =OC!$AA:$AA -> 7874 | J28: 90 | K28: =OC!$AA$3 -> Budget 2025 | L28: 115 | M28: ='OC-Days'!$15:$15 -> 0 | N28: 24
G29: =OC!$35:$35 -> 1612 | H29: 25 | K29: =OC!$C$4 -> Maximum Resident Days | L29: 116 | M29: ='OC-Days'!$30:$30 -> 0 | N29: 25
G30: =OC!$36:$36 -> 2945 | H30: 28 | K30: =OC!$D$4 -> Maximum Resident Days | L30: 117 | M30: ='OC-Days'!$27:$27 -> 0 | N30: 26
G31: =OC!$37:$37 -> 1457 | H31: 29 | K31: =OC!$E$4 -> Maximum Resident Days | L31: 118 | M31: ='OC-Days'!$28:$28 -> 0 | N31: 27
G32: =OC!$38:$38 -> 527 | H32: 30 | K32: =OC!$F$4 -> Maximum Resident Days | L32: 119 | M32: ='OC-Days'!$29:$29 -> 0 | N32: 28
G33: =OC!$39:$39 -> 2914 | H33: 31 | K33: =OC!$G$4 -> Maximum Resident Days | L33: 120 | M33: ='OC-Days'!$31:$31 -> 0 | N33: 29
G34: =OC!$40:$40 -> 4278 | H34: 32 | K34: =OC!$H$4 -> Maximum Resident Days | L34: 121 | M34: ='OC-Days'!$32:$32 -> 0 | N34: 30
G35: =OC!$41:$41 -> 3100 | H35: 33 | K35: =OC!$I$4 -> Maximum Resident Days | L35: 122 | M35: ='OC-Days'!$33:$33 -> 0 | N35: 31
G36: =OC!$42:$42 -> 2139 | H36: 34 | K36: =OC!$J$4 -> Maximum Resident Days | L36: 123 | M36: ='OC-Days'!$34:$34 -> 0 | N36: 32
G37: =OC!$43:$43 -> 17360 | H37: 35 | K37: =OC!$K$4 -> Maximum Resident Days | L37: 124 | M37: ='OC-Days'!$35:$35 -> 0 | N37: 33
G38: =OC!$44:$44 -> 961 | H38: 36 | K38: =OC!$L$4 -> Maximum Resident Days | L38: 125 | M38: ='OC-Days'!$36:$36 -> 0 | N38: 34
G39: =OC!$45:$45 -> 1116 | H39: 37 | K39: =OC!$M$4 -> Maximum Resident Days | L39: 126 | M39: ='OC-Days'!$37:$37 -> 0 | N39: 35
G40: =OC!$46:$46 -> 1209 | H40: 38 | K40: =OC!$N$4 -> Maximum Resident Days | L40: 127 | M40: ='OC-Days'!$38:$38 -> 0 | N40: 36
G41: =OC!$47:$47 -> 3286 | H41: 39 | K41: =OC!$P$4 -> Forecasted Resident Days | L41: 129 | M41: ='OC-Days'!$39:$39 -> 0 | N41: 38
G42: =OC!$48:$48 -> 80538 | H42: 40 | K42: =OC!$Q$4 -> Forecasted Resident Days | L42: 130 | M42: ='OC-Days'!$40:$40 -> 0 | N42: 39
...

Sheet OfficeConnectCellHighlights

Sheet Nuance
A4: Note, data for GP/IG facilities 51 and 52 go into the same FullOrgDesc for each (this how it is currently structured in Qlik I think).
B5: Ent | C5: Fac
B6: 350 | C6: 51 | D6: AComm\AComm LTC\PA\GP\AL GP\GP PC
B7: 350 | C7: 52 | D7: AComm\AComm LTC\PA\GP\AL GP\GP PC
B9: 360 | C9: 51 | D9: AComm\AComm LTC\DE\IG\AL IG\IG AL
B10: 360 | C10: 52 | D10: AComm\AComm LTC\DE\IG\AL IG\IG AL

Sheet 2025 Load
A1: Qlik Load | D1: Qlik Load | F1: Qlik Load | I1: Processing | L1: Processing | O1: Check
A2: f(x) | B2: f(x) | C2: text | D2: text | E2: f(x) | F2: f(x) | G2: f(x) | I2: f(x) | N2: Row Counts
A3: StartDate | B3: EndDate | C3: EntityCode | D3: FacilityCode | E3: FullOrgDesc | F3: BudgetAvailablePerDay | G3: BudgetResidentDaysPerDay | I3: # Ent-Fac | L3: Ent | M3: Fac | N3: Should be | O3: Is | P3: Delta
A4: {=INDEX(OC!$DJ$6:$FE$62,_xlfn.XMATCH($C4&"-"&$D4,OC!$DE$6:$DE$62),_xlfn.XMATCH(A$3&$I4,OC!$DJ$3:$FE$3))} -> 45658 | B4: {=INDEX(OC!$DJ$6:$FE$62,_xlfn.XMATCH($C4&"-"&$D4,OC!$DE$6:$DE$62),_xlfn.XMATCH(B$3&$I4,OC!$DJ$3:$FE$3))} -> 46022 | C4: 100 | D4: 21 | E4: =_xlfn.XLOOKUP(C4&"-"&D4,REF!$A$3:$A$47,REF!$D$3:$D$47) -> AComm\AComm LTC\MD\AMV\IL AMV\Villas | F4: {=INDEX(OC!$DJ$6:$FE$62,_xlfn.XMATCH($C4&"-"&$D4,OC!$DE$6:$DE$62),_xlfn.XMATCH(F$3&$I4,OC!$DJ$3:$FE$3))} -> 73 | G4: {=INDEX(OC!$DJ$6:$FE$62,_xlfn.XMATCH($C4&"-"&$D4,OC!$DE$6:$DE$62),_xlfn.XMATCH(G$3&$I4,OC!$DJ$3:$FE$3))} -> 70.5 | I4: =COUNTIFS($C$4:C4,C4,$D$4:D4,D4) -> 1 | L4: 100 | M4: 21 | N4: 1 | O4: =COUNTIFS($C$4:$C$75,L4,$D$4:$D$75,M4) -> 1 | P4: =N4-O4 -> 0
A5: {=INDEX(OC!$DJ$6:$FE$62,_xlfn.XMATCH($C5&"-"&$D5,OC!$DE$6:$DE$62),_xlfn.XMATCH(A$3&$I5,OC!$DJ$3:$FE$3))} -> 45658 | B5: {=INDEX(OC!$DJ$6:$FE$62,_xlfn.XMATCH($C5&"-"&$D5,OC!$DE$6:$DE$62),_xlfn.XMATCH(B$3&$I5,OC!$DJ$3:$FE$3))} -> 46022 | C5: 100 | D5: 22 | E5: =_xlfn.XLOOKUP(C5&"-"&D5,REF!$A$3:$A$47,REF!$D$3:$D$47) -> AComm\AComm LTC\MD\AMV\IL AMV\CH | F5: {=INDEX(OC!$DJ$6:$FE$62,_xlfn.XMATCH($C5&"-"&$D5,OC!$DE$6:$DE$62),_xlfn.XMATCH(F$3&$I5,OC!$DJ$3:$FE$3))} -> 43 | G5: {=INDEX(OC!$DJ$6:$FE$62,_xlfn.XMATCH($C5&"-"&$D5,OC!$DE$6:$DE$62),_xlfn.XMATCH(G$3&$I5,OC!$DJ$3:$FE$3))} -> 42 | I5: =COUNTIFS($C$4:C5,C5,$D$4:D5,D5) -> 1 | L5: 100 | M5: 22 | N5: 1 | O5: =COUNTIFS($C$4:$C$75,L5,$D$4:$D$75,M5) -> 1 | P5: =N5-O5 -> 0
A6: {=INDEX(OC!$DJ$6:$FE$62,_xlfn.XMATCH($C6&"-"&$D6,OC!$DE$6:$DE$62),_xlfn.XMATCH(A$3&$I6,OC!$DJ$3:$FE$3))} -> 45658 | B6: {=INDEX(OC!$DJ$6:$FE$62,_xlfn.XMATCH($C6&"-"&$D6,OC!$DE$6:$DE$62),_xlfn.XMATCH(B$3&$I6,OC!$DJ$3:$FE$3))} -> 45716 | C6: 100 | D6: 31 | E6: =_xlfn.XLOOKUP(C6&"-"&D6,REF!$A$3:$A$47,REF!$D$3:$D$47) -> AComm\AComm LTC\MD\AMV\IL AMV\Trott Apt | F6: {=INDEX(OC!$DJ$6:$FE$62,_xlfn.XMATCH($C6&"-"&$D6,OC!$DE$6:$DE$62),_xlfn.XMATCH(F$3&$I6,OC!$DJ$3:$FE$3))} -> 109 | G6: {=INDEX(OC!$DJ$6:$FE$62,_xlfn.XMATCH($C6&"-"&$D6,OC!$DE$6:$DE$62),_xlfn.XMATCH(G$3&$I6,OC!$DJ$3:$FE$3))} -> 61 | I6: =COUNTIFS($C$4:C6,C6,$D$4:D6,D6) -> 1 | L6: 100 | M6: 31 | N6: 6 | O6: =COUNTIFS($C$4:$C$75,L6,$D$4:$D$75,M6) -> 6 | P6: =N6-O6 -> 0
A7: {=INDEX(OC!$DJ$6:$FE$62,_xlfn.XMATCH($C7&"-"&$D7,OC!$DE$6:$DE$62),_xlfn.XMATCH(A$3&$I7,OC!$DJ$3:$FE$3))} -> 45717 | B7: {=INDEX(OC!$DJ$6:$FE$62,_xlfn.XMATCH($C7&"-"&$D7,OC!$DE$6:$DE$62),_xlfn.XMATCH(B$3&$I7,OC!$DJ$3:$FE$3))} -> 45777 | C7: 100 | D7: 31 | E7: =_xlfn.XLOOKUP(C7&"-"&D7,REF!$A$3:$A$47,REF!$D$3:$D$47) -> AComm\AComm LTC\MD\AMV\IL AMV\Trott Apt | F7: {=INDEX(OC!$DJ$6:$FE$62,_xlfn.XMATCH($C7&"-"&$D7,OC!$DE$6:$DE$62),_xlfn.XMATCH(F$3&$I7,OC!$DJ$3:$FE$3))} -> 109 | G7: {=INDEX(OC!$DJ$6:$FE$62,_xlfn.XMATCH($C7&"-"&$D7,OC!$DE$6:$DE$62),_xlfn.XMATCH(G$3&$I7,OC!$DJ$3:$FE$3))} -> 62 | I7: =COUNTIFS($C$4:C7,C7,$D$4:D7,D7) -> 2 | L7: 100 | M7: 32 | N7: 12 | O7: =COUNTIFS($C$4:$C$75,L7,$D$4:$D$75,M7) -> 12 | P7: =N7-O7 -> 0
A8: {=INDEX(OC!$DJ$6:$FE$62,_xlfn.XMATCH($C8&"-"&$D8,OC!$DE$6:$DE$62),_xlfn.XMATCH(A$3&$I8,OC!$DJ$3:$FE$3))} -> 45778 | B8: {=INDEX(OC!$DJ$6:$FE$62,_xlfn.XMATCH($C8&"-"&$D8,OC!$DE$6:$DE$62),_xlfn.XMATCH(B$3&$I8,OC!$DJ$3:$FE$3))} -> 45838 | C8: 100 | D8: 31 | E8: =_xlfn.XLOOKUP(C8&"-"&D8,REF!$A$3:$A$47,REF!$D$3:$D$47) -> AComm\AComm LTC\MD\AMV\IL AMV\Trott Apt | F8: {=INDEX(OC!$DJ$6:$FE$62,_xlfn.XMATCH($C8&"-"&$D8,OC!$DE$6:$DE$62),_xlfn.XMATCH(F$3&$I8,OC!$DJ$3:$FE$3))} -> 109 | G8: {=INDEX(OC!$DJ$6:$FE$62,_xlfn.XMATCH($C8&"-"&$D8,OC!$DE$6:$DE$62),_xlfn.XMATCH(G$3&$I8,OC!$DJ$3:$FE$3))} -> 63 | I8: =COUNTIFS($C$4:C8,C8,$D$4:D8,D8) -> 3 | L8: 100 | M8: 33 | N8: 1 | O8: =COUNTIFS($C$4:$C$75,L8,$D$4:$D$75,M8) -> 1 | P8: =N8-O8 -> 0
A9: {=INDEX(OC!$DJ$6:$FE$62,_xlfn.XMATCH($C9&"-"&$D9,OC!$DE$6:$DE$62),_xlfn.XMATCH(A$3&$I9,OC!$DJ$3:$FE$3))} -> 45839 | B9: {=INDEX(OC!$DJ$6:$FE$62,_xlfn.XMATCH($C9&"-"&$D9,OC!$DE$6:$DE$62),_xlfn.XMATCH(B$3&$I9,OC!$DJ$3:$FE$3))} -> 45900 | C9: 100 | D9: 31 | E9: =_xlfn.XLOOKUP(C9&"-"&D9,REF!$A$3:$A$47,REF!$D$3:$D$47) -> AComm\AComm LTC\MD\AMV\IL AMV\Trott Apt | F9: {=INDEX(OC!$DJ$6:$FE$62,_xlfn.XMATCH($C9&"-"&$D9,OC!$DE$6:$DE$62),_xlfn.XMATCH(F$3&$I9,OC!$DJ$3:$FE$3))} -> 109 | G9: {=INDEX(OC!$DJ$6:$FE$62,_xlfn.XMATCH($C9&"-"&$D9,OC!$DE$6:$DE$62),_xlfn.XMATCH(G$3&$I9,OC!$DJ$3:$FE$3))} -> 65 | I9: =COUNTIFS($C$4:C9,C9,$D$4:D9,D9) -> 4 | L9: 100 | M9: 34 | N9: 2 | O9: =COUNTIFS($C$4:$C$75,L9,$D$4:$D$75,M9) -> 2 | P9: =N9-O9 -> 0
A10: {=INDEX(OC!$DJ$6:$FE$62,_xlfn.XMATCH($C10&"-"&$D10,OC!$DE$6:$DE$62),_xlfn.XMATCH(A$3&$I10,OC!$DJ$3:$FE$3))} -> 45901 | B10: {=INDEX(OC!$DJ$6:$FE$62,_xlfn.XMATCH($C10&"-"&$D10,OC!$DE$6:$DE$62),_xlfn.XMATCH(B$3&$I10,OC!$DJ$3:$FE$3))} -> 45961 | C10: 100 | D10: 31 | E10: =_xlfn.XLOOKUP(C10&"-"&D10,REF!$A$3:$A$47,REF!$D$3:$D$47) -> AComm\AComm LTC\MD\AMV\IL AMV\Trott Apt | F10: {=INDEX(OC!$DJ$6:$FE$62,_xlfn.XMATCH($C10&"-"&$D10,OC!$DE$6:$DE$62),_xlfn.XMATCH(F$3&$I10,OC!$DJ$3:$FE$3))} -> 109 | G10: {=INDEX(OC!$DJ$6:$FE$62,_xlfn.XMATCH($C10&"-"&$D10,OC!$DE$6:$DE$62),_xlfn.XMATCH(G$3&$I10,OC!$DJ$3:$FE$3))} -> 66 | I10: =COUNTIFS($C$4:C10,C10,$D$4:D10,D10) -> 5 | L10: 100 | M10: 35 | N10: 4 | O10: =COUNTIFS($C$4:$C$75,L10,$D$4:$D$75,M10) -> 4 | P10: =N10-O10 -> 0
A11: {=INDEX(OC!$DJ$6:$FE$62,_xlfn.XMATCH($C11&"-"&$D11,OC!$DE$6:$DE$62),_xlfn.XMATCH(A$3&$I11,OC!$DJ$3:$FE$3))} -> 45962 | B11: {=INDEX(OC!$DJ$6:$FE$62,_xlfn.XMATCH($C11&"-"&$D11,OC!$DE$6:$DE$62),_xlfn.XMATCH(B$3&$I11,OC!$DJ$3:$FE$3))} -> 46022 | C11: 100 | D11: 31 | E11: =_xlfn.XLOOKUP(C11&"-"&D11,REF!$A$3:$A$47,REF!$D$3:$D$47) -> AComm\AComm LTC\MD\AMV\IL AMV\Trott Apt | F11: {=INDEX(OC!$DJ$6:$FE$62,_xlfn.XMATCH($C11&"-"&$D11,OC!$DE$6:$DE$62),_xlfn.XMATCH(F$3&$I11,OC!$DJ$3:$FE$3))} -> 109 | G11: {=INDEX(OC!$DJ$6:$FE$62,_xlfn.XMATCH($C11&"-"&$D11,OC!$DE$6:$DE$62),_xlfn.XMATCH(G$3&$I11,OC!$DJ$3:$FE$3))} -> 67 | I11: =COUNTIFS($C$4:C11,C11,$D$4:D11,D11) -> 6 | L11: 100 | M11: 36 | N11: 6 | O11: =COUNTIFS($C$4:$C$75,L11,$D$4:$D$75,M11) -> 6 | P11: =N11-O11 -> 0
A12: {=INDEX(OC!$DJ$6:$FE$62,_xlfn.XMATCH($C12&"-"&$D12,OC!$DE$6:$DE$62),_xlfn.XMATCH(A$3&$I12,OC!$DJ$3:$FE$3))} -> 45658 | B12: {=INDEX(OC!$DJ$6:$FE$62,_xlfn.XMATCH($C12&"-"&$D12,OC!$DE$6:$DE$62),_xlfn.XMATCH(B$3&$I12,OC!$DJ$3:$FE$3))} -> 45688 | C12: 100 | D12: 32 | E12: =_xlfn.XLOOKUP(C12&"-"&D12,REF!$A$3:$A$47,REF!$D$3:$D$47) -> AComm\AComm LTC\MD\AMV\IL AMV\DM Apt | F12: {=INDEX(OC!$DJ$6:$FE$62,_xlfn.XMATCH($C12&"-"&$D12,OC!$DE$6:$DE$62),_xlfn.XMATCH(F$3&$I12,OC!$DJ$3:$FE$3))} -> 184 | G12: {=INDEX(OC!$DJ$6:$FE$62,_xlfn.XMATCH($C12&"-"&$D12,OC!$DE$6:$DE$62),_xlfn.XMATCH(G$3&$I12,OC!$DJ$3:$FE$3))} -> 159 | I12: =COUNTIFS($C$4:C12,C12,$D$4:D12,D12) -> 1 | L12: 100 | M12: 51 | N12: 1 | O12: =COUNTIFS($C$4:$C$75,L12,$D$4:$D$75,M12) -> 1 | P12: =N12-O12 -> 0
A13: {=INDEX(OC!$DJ$6:$FE$62,_xlfn.XMATCH($C13&"-"&$D13,OC!$DE$6:$DE$62),_xlfn.XMATCH(A$3&$I13,OC!$DJ$3:$FE$3))} -> 45689 | B13: {=INDEX(OC!$DJ$6:$FE$62,_xlfn.XMATCH($C13&"-"&$D13,OC!$DE$6:$DE$62),_xlfn.XMATCH(B$3&$I13,OC!$DJ$3:$FE$3))} -> 45716 | C13: 100 | D13: 32 | E13: =_xlfn.XLOOKUP(C13&"-"&D13,REF!$A$3:$A$47,REF!$D$3:$D$47) -> AComm\AComm LTC\MD\AMV\IL AMV\DM Apt | F13: {=INDEX(OC!$DJ$6:$FE$62,_xlfn.XMATCH($C13&"-"&$D13,OC!$DE$6:$DE$62),_xlfn.XMATCH(F$3&$I13,OC!$DJ$3:$FE$3))} -> 184 | G13: {=INDEX(OC!$DJ$6:$FE$62,_xlfn.XMATCH($C13&"-"&$D13,OC!$DE$6:$DE$62),_xlfn.XMATCH(G$3&$I13,OC!$DJ$3:$FE$3))} -> 160 | I13: =COUNTIFS($C$4:C13,C13,$D$4:D13,D13) -> 2 | L13: 100 | M13: 61 | N13: 1 | O13: =COUNTIFS($C$4:$C$75,L13,$D$4:$D$75,M13) -> 1 | P13: =N13-O13 -> 0
A14: {=INDEX(OC!$DJ$6:$FE$62,_xlfn.XMATCH($C14&"-"&$D14,OC!$DE$6:$DE$62),_xlfn.XMATCH(A$3&$I14,OC!$DJ$3:$FE$3))} -> 45717 | B14: {=INDEX(OC!$DJ$6:$FE$62,_xlfn.XMATCH($C14&"-"&$D14,OC!$DE$6:$DE$62),_xlfn.XMATCH(B$3&$I14,OC!$DJ$3:$FE$3))} -> 45747 | C14: 100 | D14: 32 | E14: =_xlfn.XLOOKUP(C14&"-"&D14,REF!$A$3:$A$47,REF!$D$3:$D$47) -> AComm\AComm LTC\MD\AMV\IL AMV\DM Apt | F14: {=INDEX(OC!$DJ$6:$FE$62,_xlfn.XMATCH($C14&"-"&$D14,OC!$DE$6:$DE$62),_xlfn.XMATCH(F$3&$I14,OC!$DJ$3:$FE$3))} -> 184 | G14: {=INDEX(OC!$DJ$6:$FE$62,_xlfn.XMATCH($C14&"-"&$D14,OC!$DE$6:$DE$62),_xlfn.XMATCH(G$3&$I14,OC!$DJ$3:$FE$3))} -> 161 | I14: =COUNTIFS($C$4:C14,C14,$D$4:D14,D14) -> 3 | L14: 100 | M14: 62 | N14: 1 | O14: =COUNTIFS($C$4:$C$75,L14,$D$4:$D$75,M14) -> 1 | P14: =N14-O14 -> 0
A15: {=INDEX(OC!$DJ$6:$FE$62,_xlfn.XMATCH($C15&"-"&$D15,OC!$DE$6:$DE$62),_xlfn.XMATCH(A$3&$I15,OC!$DJ$3:$FE$3))} -> 45748 | B15: {=INDEX(OC!$DJ$6:$FE$62,_xlfn.XMATCH($C15&"-"&$D15,OC!$DE$6:$DE$62),_xlfn.XMATCH(B$3&$I15,OC!$DJ$3:$FE$3))} -> 45777 | C15: 100 | D15: 32 | E15: =_xlfn.XLOOKUP(C15&"-"&D15,REF!$A$3:$A$47,REF!$D$3:$D$47) -> AComm\AComm LTC\MD\AMV\IL AMV\DM Apt | F15: {=INDEX(OC!$DJ$6:$FE$62,_xlfn.XMATCH($C15&"-"&$D15,OC!$DE$6:$DE$62),_xlfn.XMATCH(F$3&$I15,OC!$DJ$3:$FE$3))} -> 184 | G15: {=INDEX(OC!$DJ$6:$FE$62,_xlfn.XMATCH($C15&"-"&$D15,OC!$DE$6:$DE$62),_xlfn.XMATCH(G$3&$I15,OC!$DJ$3:$FE$3))} -> 162 | I15: =COUNTIFS($C$4:C15,C15,$D$4:D15,D15) -> 4 | L15: 200 | M15: 21 | N15: 1 | O15: =COUNTIFS($C$4:$C$75,L15,$D$4:$D$75,M15) -> 1 | P15: =N15-O15 -> 0
... A47: {=INDEX(OC!$DJ$6:$FE$62,_xlfn.XMATCH($C47&"-"&$D47,OC!$DE$6:$DE$62),_xlfn.XMATCH(A$3&$I47,OC!$DJ$3:$FE$3))} -> 45658 | B47: {=INDEX(OC!$DJ$6:$FE$62,_xlfn.XMATCH($C47&"-"&$D47,OC!$DE$6:$DE$62),_xlfn.XMATCH(B$3&$I47,OC!$DJ$3:$FE$3))} -> 46022 | C47: 324 | D47: 51 | E47: =_xlfn.XLOOKUP(C47&"-"&D47,REF!$A$3:$A$47,REF!$D$3:$D$47) -> AComm\AComm LTC\PA\SPH\AL SPH\SPH PC Apts | F47: {=INDEX(OC!$DJ$6:$FE$62,_xlfn.XMATCH($C47&"-"&$D47,OC!$DE$6:$DE$62),_xlfn.XMATCH(F$3&$I47,OC!$DJ$3:$FE$3))} -> 35 | G47: {=INDEX(OC!$DJ$6:$FE$62,_xlfn.XMATCH($C47&"-"&$D47,OC!$DE$6:$DE$62),_xlfn.XMATCH(G$3&$I47,OC!$DJ$3:$FE$3))} -> 33 | I47: =COUNTIFS($C$4:C47,C47,$D$4:D47,D47) -> 1 | L47: 840 | M47: 61 | N47: 1 | O47: =COUNTIFS($C$4:$C$75,L47,$D$4:$D$75,M47) -> 1 | P47: =N47-O47 -> 0
A48: {=INDEX(OC!$DJ$6:$FE$62,_xlfn.XMATCH($C48&"-"&$D48,OC!$DE$6:$DE$62),_xlfn.XMATCH(A$3&$I48,OC!$DJ$3:$FE$3))} -> 45658 | B48: {=INDEX(OC!$DJ$6:$FE$62,_xlfn.XMATCH($C48&"-"&$D48,OC!$DE$6:$DE$62),_xlfn.XMATCH(B$3&$I48,OC!$DJ$3:$FE$3))} -> 46022 | C48: 324 | D48: 61 | E48: =_xlfn.XLOOKUP(C48&"-"&D48,REF!$A$3:$A$47,REF!$D$3:$D$47) -> AComm\AComm LTC\PA\SPH\SNF SPH | F48: {=INDEX(OC!$DJ$6:$FE$62,_xlfn.XMATCH($C48&"-"&$D48,OC!$DE$6:$DE$62),_xlfn.XMATCH(F$3&$I48,OC!$DJ$3:$FE$3))} -> 76 | G48: {=INDEX(OC!$DJ$6:$FE$62,_xlfn.XMATCH($C48&"-"&$D48,OC!$DE$6:$DE$62),_xlfn.XMATCH(G$3&$I48,OC!$DJ$3:$FE$3))} -> 73 | I48: =COUNTIFS($C$4:C48,C48,$D$4:D48,D48) -> 1
A49: {=INDEX(OC!$DJ$6:$FE$62,_xlfn.XMATCH($C49&"-"&$D49,OC!$DE$6:$DE$62),_xlfn.XMATCH(A$3&$I49,OC!$DJ$3:$FE$3))} -> 45658 | B49: {=INDEX(OC!$DJ$6:$FE$62,_xlfn.XMATCH($C49&"-"&$D49,OC!$DE$6:$DE$62),_xlfn.XMATCH(B$3&$I49,OC!$DJ$3:$FE$3))} -> 46022 | C49: 350 | D49: 21 | E49: AComm\AComm LTC\PA\GP\IL GP\GP Cottage Units | F49: {=INDEX(OC!$DJ$6:$FE$62,_xlfn.XMATCH($C49&"-"&$D49,OC!$DE$6:$DE$62),_xlfn.XMATCH(F$3&$I49,OC!$DJ$3:$FE$3))} -> 13 | G49: {=INDEX(OC!$DJ$6:$FE$62,_xlfn.XMATCH($C49&"-"&$D49,OC!$DE$6:$DE$62),_xlfn.XMATCH(G$3&$I49,OC!$DJ$3:$FE$3))} -> 12 | I49: =COUNTIFS($C$4:C49,C49,$D$4:D49,D49) -> 1
A50: {=INDEX(OC!$DJ$6:$FE$62,_xlfn.XMATCH($C50&"-"&$D50,OC!$DE$6:$DE$62),_xlfn.XMATCH(A$3&$I50,OC!$DJ$3:$FE$3))} -> 45658 | B50: {=INDEX(OC!$DJ$6:$FE$62,_xlfn.XMATCH($C50&"-"&$D50,OC!$DE$6:$DE$62),_xlfn.XMATCH(B$3&$I50,OC!$DJ$3:$FE$3))} -> 46022 | C50: 350 | D50: 51 | E50: AComm\AComm LTC\PA\GP\AL GP\GP PC | F50: {=INDEX(OC!$DJ$6:$FE$62,_xlfn.XMATCH($C50&"-"&$D50,OC!$DE$6:$DE$62),_xlfn.XMATCH(F$3&$I50,OC!$DJ$3:$FE$3))} -> 70 | G50: {=INDEX(OC!$DJ$6:$FE$62,_xlfn.XMATCH($C50&"-"&$D50,OC!$DE$6:$DE$62),_xlfn.XMATCH(G$3&$I50,OC!$DJ$3:$FE$3))} -> 66 | I50: =COUNTIFS($C$4:C50,C50,$D$4:D50,D50) -> 1
A51: {=INDEX(OC!$DJ$6:$FE$62,_xlfn.XMATCH($C51&"-"&$D51,OC!$DE$6:$DE$62),_xlfn.XMATCH(A$3&$I51,OC!$DJ$3:$FE$3))} -> 45658 | B51: {=INDEX(OC!$DJ$6:$FE$62,_xlfn.XMATCH($C51&"-"&$D51,OC!$DE$6:$DE$62),_xlfn.XMATCH(B$3&$I51,OC!$DJ$3:$FE$3))} -> 46022 | C51: 350 | D51: 52 | E51: AComm\AComm LTC\PA\GP\AL GP\GP PC | F51: {=INDEX(OC!$DJ$6:$FE$62,_xlfn.XMATCH($C51&"-"&$D51,OC!$DE$6:$DE$62),_xlfn.XMATCH(F$3&$I51,OC!$DJ$3:$FE$3))} -> 12 | G51: {=INDEX(OC!$DJ$6:$FE$62,_xlfn.XMATCH($C51&"-"&$D51,OC!$DE$6:$DE$62),_xlfn.XMATCH(G$3&$I51,OC!$DJ$3:$FE$3))} -> 11 | I51: =COUNTIFS($C$4:C51,C51,$D$4:D51,D51) -> 1
A52: {=INDEX(OC!$DJ$6:$FE$62,_xlfn.XMATCH($C52&"-"&$D52,OC!$DE$6:$DE$62),_xlfn.XMATCH(A$3&$I52,OC!$DJ$3:$FE$3))} -> 45658 | B52: {=INDEX(OC!$DJ$6:$FE$62,_xlfn.XMATCH($C52&"-"&$D52,OC!$DE$6:$DE$62),_xlfn.XMATCH(B$3&$I52,OC!$DJ$3:$FE$3))} -> 45688 | C52: 360 | D52: 51 | E52: AComm\AComm LTC\DE\IG\AL IG\IG AL | F52: {=INDEX(OC!$DJ$6:$FE$62,_xlfn.XMATCH($C52&"-"&$D52,OC!$DE$6:$DE$62),_xlfn.XMATCH(F$3&$I52,OC!$DJ$3:$FE$3))} -> 43 | G52: {=INDEX(OC!$DJ$6:$FE$62,_xlfn.XMATCH($C52&"-"&$D52,OC!$DE$6:$DE$62),_xlfn.XMATCH(G$3&$I52,OC!$DJ$3:$FE$3))} -> 34 | I52: =COUNTIFS($C$4:C52,C52,$D$4:D52,D52) -> 1
A53: {=INDEX(OC!$DJ$6:$FE$62,_xlfn.XMATCH($C53&"-"&$D53,OC!$DE$6:$DE$62),_xlfn.XMATCH(A$3&$I53,OC!$DJ$3:$FE$3))} -> 45689 | B53: {=INDEX(OC!$DJ$6:$FE$62,_xlfn.XMATCH($C53&"-"&$D53,OC!$DE$6:$DE$62),_xlfn.XMATCH(B$3&$I53,OC!$DJ$3:$FE$3))} -> 45716 | C53: 360 | D53: 51 | E53: AComm\AComm LTC\DE\IG\AL IG\IG AL | F53: {=INDEX(OC!$DJ$6:$FE$62,_xlfn.XMATCH($C53&"-"&$D53,OC!$DE$6:$DE$62),_xlfn.XMATCH(F$3&$I53,OC!$DJ$3:$FE$3))} -> 43 | G53: {=INDEX(OC!$DJ$6:$FE$62,_xlfn.XMATCH($C53&"-"&$D53,OC!$DE$6:$DE$62),_xlfn.XMATCH(G$3&$I53,OC!$DJ$3:$FE$3))} -> 35 | I53: =COUNTIFS($C$4:C53,C53,$D$4:D53,D53) -> 2
A54: {=INDEX(OC!$DJ$6:$FE$62,_xlfn.XMATCH($C54&"-"&$D54,OC!$DE$6:$DE$62),_xlfn.XMATCH(A$3&$I54,OC!$DJ$3:$FE$3))} -> 45717 | B54: {=INDEX(OC!$DJ$6:$FE$62,_xlfn.XMATCH($C54&"-"&$D54,OC!$DE$6:$DE$62),_xlfn.XMATCH(B$3&$I54,OC!$DJ$3:$FE$3))} -> 45747 | C54: 360 | D54: 51 | E54: AComm\AComm LTC\DE\IG\AL IG\IG AL | F54: {=INDEX(OC!$DJ$6:$FE$62,_xlfn.XMATCH($C54&"-"&$D54,OC!$DE$6:$DE$62),_xlfn.XMATCH(F$3&$I54,OC!$DJ$3:$FE$3))} -> 43 | G54: {=INDEX(OC!$DJ$6:$FE$62,_xlfn.XMATCH($C54&"-"&$D54,OC!$DE$6:$DE$62),_xlfn.XMATCH(G$3&$I54,OC!$DJ$3:$FE$3))} -> 36 | I54: =COUNTIFS($C$4:C54,C54,$D$4:D54,D54) -> 3
A55: {=INDEX(OC!$DJ$6:$FE$62,_xlfn.XMATCH($C55&"-"&$D55,OC!$DE$6:$DE$62),_xlfn.XMATCH(A$3&$I55,OC!$DJ$3:$FE$3))} -> 45748 | B55: {=INDEX(OC!$DJ$6:$FE$62,_xlfn.XMATCH($C55&"-"&$D55,OC!$DE$6:$DE$62),_xlfn.XMATCH(B$3&$I55,OC!$DJ$3:$FE$3))} -> 46022 | C55: 360 | D55: 51 | E55: AComm\AComm LTC\DE\IG\AL IG\IG AL | F55: {=INDEX(OC!$DJ$6:$FE$62,_xlfn.XMATCH($C55&"-"&$D55,OC!$DE$6:$DE$62),_xlfn.XMATCH(F$3&$I55,OC!$DJ$3:$FE$3))} -> 43 | G55: {=INDEX(OC!$DJ$6:$FE$62,_xlfn.XMATCH($C55&"-"&$D55,OC!$DE$6:$DE$62),_xlfn.XMATCH(G$3&$I55,OC!$DJ$3:$FE$3))} -> 37 | I55: =COUNTIFS($C$4:C55,C55,$D$4:D55,D55) -> 4
A56: {=INDEX(OC!$DJ$6:$FE$62,_xlfn.XMATCH($C56&"-"&$D56,OC!$DE$6:$DE$62),_xlfn.XMATCH(A$3&$I56,OC!$DJ$3:$FE$3))} -> 45658 | B56: {=INDEX(OC!$DJ$6:$FE$62,_xlfn.XMATCH($C56&"-"&$D56,OC!$DE$6:$DE$62),_xlfn.XMATCH(B$3&$I56,OC!$DJ$3:$FE$3))} -> 46022 | C56: 360 | D56: 52 | E56: AComm\AComm LTC\DE\IG\AL IG\IG AL | F56: {=INDEX(OC!$DJ$6:$FE$62,_xlfn.XMATCH($C56&"-"&$D56,OC!$DE$6:$DE$62),_xlfn.XMATCH(F$3&$I56,OC!$DJ$3:$FE$3))} -> 9 | G56: {=INDEX(OC!$DJ$6:$FE$62,_xlfn.XMATCH($C56&"-"&$D56,OC!$DE$6:$DE$62),_xlfn.XMATCH(G$3&$I56,OC!$DJ$3:$FE$3))} -> 8 | I56: =COUNTIFS($C$4:C56,C56,$D$4:D56,D56) -> 1
A57: {=INDEX(OC!$DJ$6:$FE$62,_xlfn.XMATCH($C57&"-"&$D57,OC!$DE$6:$DE$62),_xlfn.XMATCH(A$3&$I57,OC!$DJ$3:$FE$3))} -> 45658 | B57: {=INDEX(OC!$DJ$6:$FE$62,_xlfn.XMATCH($C57&"-"&$D57,OC!$DE$6:$DE$62),_xlfn.XMATCH(B$3&$I57,OC!$DJ$3:$FE$3))} -> 46022 | C57: 810 | D57: 21 | E57: =_xlfn.XLOOKUP(C57&"-"&D57,REF!$A$3:$A$47,REF!$D$3:$D$47) -> AComm\AComm LTC\PA\BV\IL BV\Cottage East | F57: {=INDEX(OC!$DJ$6:$FE$62,_xlfn.XMATCH($C57&"-"&$D57,OC!$DE$6:$DE$62),_xlfn.XMATCH(F$3&$I57,OC!$DJ$3:$FE$3))} -> 95 | G57: {=INDEX(OC!$DJ$6:$FE$62,_xlfn.XMATCH($C57&"-"&$D57,OC!$DE$6:$DE$62),_xlfn.XMATCH(G$3&$I57,OC!$DJ$3:$FE$3))} -> 93 | I57: =COUNTIFS($C$4:C57,C57,$D$4:D57,D57) -> 1
A58: {=INDEX(OC!$DJ$6:$FE$62,_xlfn.XMATCH($C58&"-"&$D58,OC!$DE$6:$DE$62),_xlfn.XMATCH(A$3&$I58,OC!$DJ$3:$FE$3))} -> 45658 | B58: {=INDEX(OC!$DJ$6:$FE$62,_xlfn.XMATCH($C58&"-"&$D58,OC!$DE$6:$DE$62),_xlfn.XMATCH(B$3&$I58,OC!$DJ$3:$FE$3))} -> 46022 | C58: 810 | D58: 22 | E58: =_xlfn.XLOOKUP(C58&"-"&D58,REF!$A$3:$A$47,REF!$D$3:$D$47) -> AComm\AComm LTC\PA\BV\IL BV\Cottage West | F58: {=INDEX(OC!$DJ$6:$FE$62,_xlfn.XMATCH($C58&"-"&$D58,OC!$DE$6:$DE$62),_xlfn.XMATCH(F$3&$I58,OC!$DJ$3:$FE$3))} -> 47 | G58: {=INDEX(OC!$DJ$6:$FE$62,_xlfn.XMATCH($C58&"-"&$D58,OC!$DE$6:$DE$62),_xlfn.XMATCH(G$3&$I58,OC!$DJ$3:$FE$3))} -> 46 | I58: =COUNTIFS($C$4:C58,C58,$D$4:D58,D58) -> 1
A59: {=INDEX(OC!$DJ$6:$FE$62,_xlfn.XMATCH($C59&"-"&$D59,OC!$DE$6:$DE$62),_xlfn.XMATCH(A$3&$I59,OC!$DJ$3:$FE$3))} -> 45658 | B59: {=INDEX(OC!$DJ$6:$FE$62,_xlfn.XMATCH($C59&"-"&$D59,OC!$DE$6:$DE$62),_xlfn.XMATCH(B$3&$I59,OC!$DJ$3:$FE$3))} -> 46022 | C59: 810 | D59: 31 | E59: =_xlfn.XLOOKUP(C59&"-"&D59,REF!$A$3:$A$47,REF!$D$3:$D$47) -> AComm\AComm LTC\PA\BV\IL BV\Center Apartments | F59: {=INDEX(OC!$DJ$6:$FE$62,_xlfn.XMATCH($C59&"-"&$D59,OC!$DE$6:$DE$62),_xlfn.XMATCH(F$3&$I59,OC!$DJ$3:$FE$3))} -> 17 | G59: {=INDEX(OC!$DJ$6:$FE$62,_xlfn.XMATCH($C59&"-"&$D59,OC!$DE$6:$DE$62),_xlfn.XMATCH(G$3&$I59,OC!$DJ$3:$FE$3))} -> 16 | I59: =COUNTIFS($C$4:C59,C59,$D$4:D59,D59) -> 1
A60: {=INDEX(OC!$DJ$6:$FE$62,_xlfn.XMATCH($C60&"-"&$D60,OC!$DE$6:$DE$62),_xlfn.XMATCH(A$3&$I60,OC!$DJ$3:$FE$3))} -> 45658 | B60: {=INDEX(OC!$DJ$6:$FE$62,_xlfn.XMATCH($C60&"-"&$D60,OC!$DE$6:$DE$62),_xlfn.XMATCH(B$3&$I60,OC!$DJ$3:$FE$3))} -> 46022 | C60: 810 | D60: 32 | E60: =_xlfn.XLOOKUP(C60&"-"&D60,REF!$A$3:$A$47,REF!$D$3:$D$47) -> AComm\AComm LTC\PA\BV\IL BV\Court Apartments | F60: {=INDEX(OC!$DJ$6:$FE$62,_xlfn.XMATCH($C60&"-"&$D60,OC!$DE$6:$DE$62),_xlfn.XMATCH(F$3&$I60,OC!$DJ$3:$FE$3))} -> 94 | G60: {=INDEX(OC!$DJ$6:$FE$62,_xlfn.XMATCH($C60&"-"&$D60,OC!$DE$6:$DE$62),_xlfn.XMATCH(G$3&$I60,OC!$DJ$3:$FE$3))} -> 85.5 | I60: =COUNTIFS($C$4:C60,C60,$D$4:D60,D60) -> 1
A61: {=INDEX(OC!$DJ$6:$FE$62,_xlfn.XMATCH($C61&"-"&$D61,OC!$DE$6:$DE$62),_xlfn.XMATCH(A$3&$I61,OC!$DJ$3:$FE$3))} -> 45658 | B61: {=INDEX(OC!$DJ$6:$FE$62,_xlfn.XMATCH($C61&"-"&$D61,OC!$DE$6:$DE$62),_xlfn.XMATCH(B$3&$I61,OC!$DJ$3:$FE$3))} -> 46022 | C61: 810 | D61: 33 | E61: =_xlfn.XLOOKUP(C61&"-"&D61,REF!$A$3:$A$47,REF!$D$3:$D$47) -> AComm\AComm LTC\PA\BV\IL BV\West Apartments | F61: {=INDEX(OC!$DJ$6:$FE$62,_xlfn.XMATCH($C61&"-"&$D61,OC!$DE$6:$DE$62),_xlfn.XMATCH(F$3&$I61,OC!$DJ$3:$FE$3))} -> 138 | G61: {=INDEX(OC!$DJ$6:$FE$62,_xlfn.XMATCH($C61&"-"&$D61,OC!$DE$6:$DE$62),_xlfn.XMATCH(G$3&$I61,OC!$DJ$3:$FE$3))} -> 132 | I61: =COUNTIFS($C$4:C61,C61,$D$4:D61,D61) -> 1
A62: {=INDEX(OC!$DJ$6:$FE$62,_xlfn.XMATCH($C62&"-"&$D62,OC!$DE$6:$DE$62),_xlfn.XMATCH(A$3&$I62,OC!$DJ$3:$FE$3))} -> 45658 | B62: {=INDEX(OC!$DJ$6:$FE$62,_xlfn.XMATCH($C62&"-"&$D62,OC!$DE$6:$DE$62),_xlfn.XMATCH(B$3&$I62,OC!$DJ$3:$FE$3))} -> 46022 | C62: 810 | D62: 51 | E62: =_xlfn.XLOOKUP(C62&"-"&D62,REF!$A$3:$A$47,REF!$D$3:$D$47) -> AComm\AComm LTC\PA\BV\AL BV\Maplewood | F62: {=INDEX(OC!$DJ$6:$FE$62,_xlfn.XMATCH($C62&"-"&$D62,OC!$DE$6:$DE$62),_xlfn.XMATCH(F$3&$I62,OC!$DJ$3:$FE$3))} -> 100 | G62: {=INDEX(OC!$DJ$6:$FE$62,_xlfn.XMATCH($C62&"-"&$D62,OC!$DE$6:$DE$62),_xlfn.XMATCH(G$3&$I62,OC!$DJ$3:$FE$3))} -> 96.5 | I62: =COUNTIFS($C$4:C62,C62,$D$4:D62,D62) -> 1
A63: {=INDEX(OC!$DJ$6:$FE$62,_xlfn.XMATCH($C63&"-"&$D63,OC!$DE$6:$DE$62),_xlfn.XMATCH(A$3&$I63,OC!$DJ$3:$FE$3))} -> 45658 | B63: {=INDEX(OC!$DJ$6:$FE$62,_xlfn.XMATCH($C63&"-"&$D63,OC!$DE$6:$DE$62),_xlfn.XMATCH(B$3&$I63,OC!$DJ$3:$FE$3))} -> 46022 | C63: 810 | D63: 61 | E63: =_xlfn.XLOOKUP(C63&"-"&D63,REF!$A$3:$A$47,REF!$D$3:$D$47) -> AComm\AComm LTC\PA\BV\SNF BV | F63: {=INDEX(OC!$DJ$6:$FE$62,_xlfn.XMATCH($C63&"-"&$D63,OC!$DE$6:$DE$62),_xlfn.XMATCH(F$3&$I63,OC!$DJ$3:$FE$3))} -> 69 | G63: {=INDEX(OC!$DJ$6:$FE$62,_xlfn.XMATCH($C63&"-"&$D63,OC!$DE$6:$DE$62),_xlfn.XMATCH(G$3&$I63,OC!$DJ$3:$FE$3))} -> 66 | I63: =COUNTIFS($C$4:C63,C63,$D$4:D63,D63) -> 1
A64: {=INDEX(OC!$DJ$6:$FE$62,_xlfn.XMATCH($C64&"-"&$D64,OC!$DE$6:$DE$62),_xlfn.XMATCH(A$3&$I64,OC!$DJ$3:$FE$3))} -> 45658 | B64: {=INDEX(OC!$DJ$6:$FE$62,_xlfn.XMATCH($C64&"-"&$D64,OC!$DE$6:$DE$62),_xlfn.XMATCH(B$3&$I64,OC!$DJ$3:$FE$3))} -> 46022 | C64: 925 | D64: 21 | E64: =_xlfn.XLOOKUP(C64&"-"&D64,REF!$A$3:$A$47,REF!$D$3:$D$47) -> AComm\TAG Services\PA\CE\IL CE\Cottage Units | F64: {=INDEX(OC!$DJ$6:$FE$62,_xlfn.XMATCH($C64&"-"&$D64,OC!$DE$6:$DE$62),_xlfn.XMATCH(F$3&$I64,OC!$DJ$3:$FE$3))} -> 31 | G64: {=INDEX(OC!$DJ$6:$FE$62,_xlfn.XMATCH($C64&"-"&$D64,OC!$DE$6:$DE$62),_xlfn.XMATCH(G$3&$I64,OC!$DJ$3:$FE$3))} -> 30 | I64: =COUNTIFS($C$4:C64,C64,$D$4:D64,D64) -> 1
A65: {=INDEX(OC!$DJ$6:$FE$62,_xlfn.XMATCH($C65&"-"&$D65,OC!$DE$6:$DE$62),_xlfn.XMATCH(A$3&$I65,OC!$DJ$3:$FE$3))} -> 45658 | B65: {=INDEX(OC!$DJ$6:$FE$62,_xlfn.XMATCH($C65&"-"&$D65,OC!$DE$6:$DE$62),_xlfn.XMATCH(B$3&$I65,OC!$DJ$3:$FE$3))} -> 46022 | C65: 925 | D65: 31 | E65: =_xlfn.XLOOKUP(C65&"-"&D65,REF!$A$3:$A$47,REF!$D$3:$D$47) -> AComm\TAG Services\PA\CE\IL CE\Garden Units | F65: {=INDEX(OC!$DJ$6:$FE$62,_xlfn.XMATCH($C65&"-"&$D65,OC!$DE$6:$DE$62),_xlfn.XMATCH(F$3&$I65,OC!$DJ$3:$FE$3))} -> 36 | G65: {=INDEX(OC!$DJ$6:$FE$62,_xlfn.XMATCH($C65&"-"&$D65,OC!$DE$6:$DE$62),_xlfn.XMATCH(G$3&$I65,OC!$DJ$3:$FE$3))} -> 35 | I65: =COUNTIFS($C$4:C65,C65,$D$4:D65,D65) -> 1
A66: {=INDEX(OC!$DJ$6:$FE$62,_xlfn.XMATCH($C66&"-"&$D66,OC!$DE$6:$DE$62),_xlfn.XMATCH(A$3&$I66,OC!$DJ$3:$FE$3))} -> 45658 | B66: {=INDEX(OC!$DJ$6:$FE$62,_xlfn.XMATCH($C66&"-"&$D66,OC!$DE$6:$DE$62),_xlfn.XMATCH(B$3&$I66,OC!$DJ$3:$FE$3))} -> 46022 | C66: 925 | D66: 51 | E66: =_xlfn.XLOOKUP(C66&"-"&D66,REF!$A$3:$A$47,REF!$D$3:$D$47) -> AComm\TAG Services\PA\CE\AL CE\CE PC Units | F66: {=INDEX(OC!$DJ$6:$FE$62,_xlfn.XMATCH($C66&"-"&$D66,OC!$DE$6:$DE$62),_xlfn.XMATCH(F$3&$I66,OC!$DJ$3:$FE$3))} -> 39 | G66: {=INDEX(OC!$DJ$6:$FE$62,_xlfn.XMATCH($C66&"-"&$D66,OC!$DE$6:$DE$62),_xlfn.XMATCH(G$3&$I66,OC!$DJ$3:$FE$3))} -> 37 | I66: =COUNTIFS($C$4:C66,C66,$D$4:D66,D66) -> 1
A67: {=INDEX(OC!$DJ$6:$FE$62,_xlfn.XMATCH($C67&"-"&$D67,OC!$DE$6:$DE$62),_xlfn.XMATCH(A$3&$I67,OC!$DJ$3:$FE$3))} -> 45658 | B67: {=INDEX(OC!$DJ$6:$FE$62,_xlfn.XMATCH($C67&"-"&$D67,OC!$DE$6:$DE$62),_xlfn.XMATCH(B$3&$I67,OC!$DJ$3:$FE$3))} -> 46022 | C67: 835 | D67: 21 | E67: =_xlfn.XLOOKUP(C67&"-"&D67,REF!$A$3:$A$47,REF!$D$3:$D$47) -> AComm\AComm LTC\PA\RW\IL RW\GC | F67: {=INDEX(OC!$DJ$6:$FE$62,_xlfn.XMATCH($C67&"-"&$D67,OC!$DE$6:$DE$62),_xlfn.XMATCH(F$3&$I67,OC!$DJ$3:$FE$3))} -> 51 | G67: {=INDEX(OC!$DJ$6:$FE$62,_xlfn.XMATCH($C67&"-"&$D67,OC!$DE$6:$DE$62),_xlfn.XMATCH(G$3&$I67,OC!$DJ$3:$FE$3))} -> 48 | I67: =COUNTIFS($C$4:C67,C67,$D$4:D67,D67) -> 1
A68: {=INDEX(OC!$DJ$6:$FE$62,_xlfn.XMATCH($C68&"-"&$D68,OC!$DE$6:$DE$62),_xlfn.XMATCH(A$3&$I68,OC!$DJ$3:$FE$3))} -> 45658 | B68: {=INDEX(OC!$DJ$6:$FE$62,_xlfn.XMATCH($C68&"-"&$D68,OC!$DE$6:$DE$62),_xlfn.XMATCH(B$3&$I68,OC!$DJ$3:$FE$3))} -> 46022 | C68: 835 | D68: 31 | E68: =_xlfn.XLOOKUP(C68&"-"&D68,REF!$A$3:$A$47,REF!$D$3:$D$47) -> AComm\AComm LTC\PA\RW\IL RW\RC APT | F68: {=INDEX(OC!$DJ$6:$FE$62,_xlfn.XMATCH($C68&"-"&$D68,OC!$DE$6:$DE$62),_xlfn.XMATCH(F$3&$I68,OC!$DJ$3:$FE$3))} -> 78 | G68: {=INDEX(OC!$DJ$6:$FE$62,_xlfn.XMATCH($C68&"-"&$D68,OC!$DE$6:$DE$62),_xlfn.XMATCH(G$3&$I68,OC!$DJ$3:$FE$3))} -> 72 | I68: =COUNTIFS($C$4:C68,C68,$D$4:D68,D68) -> 1
... A75: {=INDEX(OC!$DJ$6:$FE$62,_xlfn.XMATCH($C75&"-"&$D75,OC!$DE$6:$DE$62),_xlfn.XMATCH(A$3&$I75,OC!$DJ$3:$FE$3))} -> 45658 | B75: {=INDEX(OC!$DJ$6:$FE$62,_xlfn.XMATCH($C75&"-"&$D75,OC!$DE$6:$DE$62),_xlfn.XMATCH(B$3&$I75,OC!$DJ$3:$FE$3))} -> 46022 | C75: 840 | D75: 61 | E75: =_xlfn.XLOOKUP(C75&"-"&D75,REF!$A$3:$A$47,REF!$D$3:$D$47) -> Skilled Nursing Facility | F75: {=INDEX(OC!$DJ$6:$FE$62,_xlfn.XMATCH($C75&"-"&$D75,OC!$DE$6:$DE$62),_xlfn.XMATCH(F$3&$I75,OC!$DJ$3:$FE$3))} -> 64 | G75: {=INDEX(OC!$DJ$6:$FE$62,_xlfn.XMATCH($C75&"-"&$D75,OC!$DE$6:$DE$62),_xlfn.XMATCH(G$3&$I75,OC!$DJ$3:$FE$3))} -> 61 | I75: =COUNTIFS($C$4:C75,C75,$D$4:D75,D75) -> 1

Sheet OC
B1: Office Connect Data | C1: Office Connect Data | F1: Office Connect Data | I1: Office Connect Data | L1: Office Connect Data | P1: Office Connect Data | S1: Office Connect Data | V1: Office Connect Data | Y1: Office Connect Data | AC1: Processing | AF1: Processing | AI1: Processing | AL1: Processing | AP1: Processing | AS1: Processing | AV1: Processing | AY1: Processing | BC1: Processing | BF1: Processing | BI1: Processing | BL1: Processing | BP1: Processing | BS1: Processing | BV1: Processing | BY1: Processing | CC1: Processing | CF1: Processing | CI1: Processing | CL1: Processing | CP1: Processing | CS1: Processing | CV1: Processing | CY1: Processing | DC1: Processing | DG1: Processing | DJ1: Processing | DN1: Processing | DR1: Processing | DV1: Processing | DZ1: Processing | ED1: Processing | EH1: Processing | EL1: Processing | EP1: Processing | ET1: Processing | EX1: Processing | FB1: Processing
AC2: f(x) | AD2: f(x) | AE2: f(x) | AF2: f(x) | AG2: f(x) | AH2: f(x) | AI2: f(x) | AJ2: f(x) | AK2: f(x) | AL2: f(x) | AM2: f(x) | AN2: f(x) | AP2: f(x) | AQ2: f(x) | AR2: f(x) | AS2: f(x) | AT2: f(x) | AU2: f(x) | AV2: f(x) | AW2: f(x) | AX2: f(x) | AY2: f(x) | AZ2: f(x) | BA2: f(x) | BC2: f(x) | BD2: f(x) | BE2: f(x) | BF2: f(x) | BG2: f(x) | BH2: f(x) | BI2: f(x) | BJ2: f(x) | BK2: f(x) | BL2: f(x) | BM2: f(x) | BN2: f(x) | BP2: f(x) | BQ2: f(x) | BR2: f(x) | BS2: f(x) | BT2: f(x) | BU2: f(x) | BV2: f(x) | BW2: f(x) | BX2: f(x) | BY2: f(x) | BZ2: f(x) | CA2: f(x) | CC2: f(x) | CD2: f(x) | CE2: f(x) | CF2: f(x) | CG2: f(x) | CH2: f(x) | CI2: f(x) | CJ2: f(x) | CK2: f(x) | CL2: f(x) | CM2: f(x) | CN2: f(x) | CP2: f(x) | CQ2: f(x) | CR2: f(x) | CS2: f(x) | CT2: f(x) | CU2: f(x) | CV2: f(x) | CW2: f(x) | CX2: f(x) | CY2: f(x) | CZ2: f(x) | DA2: f(x) | DC2: f(x) | DD2: f(x) | DG2: f(x) | DH2: f(x) | DJ2: f(x) | DK2: f(x) | DL2: f(x) | DM2: f(x) | DN2: f(x) | DO2: f(x) | DP2: f(x) | DQ2: f(x) | DR2: f(x) | DS2: f(x) | DT2: f(x) | DU2: f(x) | DV2: f(x) | DW2: f(x) | DX2: f(x) | DY2: f(x) | DZ2: f(x) | EA2: f(x) | EB2: f(x) | EC2: f(x) | ED2: f(x) | EE2: f(x) | EF2: f(x) | EG2: f(x) | EH2: f(x) | EI2: f(x) | EJ2: f(x) | EK2: f(x) | EL2: f(x) | EM2: f(x) | EN2: f(x) | EO2: f(x) | EP2: f(x) | EQ2: f(x) | ER2: f(x) | ES2: f(x) | ET2: f(x) | EU2: f(x) | EV2: f(x) | EW2: f(x) | EX2: f(x) | EY2: f(x) | EZ2: f(x) | FA2: f(x) | FB2: f(x) | FC2: f(x) | FD2: f(x) | FE2: f(x)
C3: Budget 2025 | D3: Budget 2025 | E3: Budget 2025 | F3: Budget 2025 | G3: Budget 2025 | H3: Budget 2025 | I3: Budget 2025 | J3: Budget 2025 | K3: Budget 2025 | L3: Budget 2025 | M3: Budget 2025 | N3: Budget 2025 | P3: Budget 2025 | Q3: Budget 2025 | R3: Budget 2025 | S3: Budget 2025 | T3: Budget 2025 | U3: Budget 2025 | V3: Budget 2025 | W3: Budget 2025 | X3: Budget 2025 | Y3: Budget 2025 | Z3: Budget 2025 | AA3: Budget 2025 | BC3: Calcs based on Census, checked no change in monthly units | BP3: Calcs based on Census, checked no change in monthly units | DJ3: =DJ4&DJ5 -> StartDate1 | DK3: =DK4&DK5 -> EndDate1 | DL3: =DL4&DL5 -> BudgetAvailablePerDay1 | DM3: =DM4&DM5 -> BudgetResidentDaysPerDay1 | DN3: =DN4&DN5 -> StartDate2 | DO3: =DO4&DO5 -> EndDate2 | DP3: =DP4&DP5 -> BudgetAvailablePerDay2 | DQ3: =DQ4&DQ5 -> BudgetResidentDaysPerDay2 | ... FE3: =FE4&FE5 -> BudgetResidentDaysPerDay12
C4: Maximum Resident Days | D4: Maximum Resident Days | E4: Maximum Resident Days | F4: Maximum Resident Days | G4: Maximum Resident Days | H4: Maximum Resident Days | I4: Maximum Resident Days | J4: Maximum Resident Days | K4: Maximum Resident Days | L4: Maximum Resident Days | M4: Maximum Resident Days | N4: Maximum Resident Days | P4: Forecasted Resident Days | Q4: Forecasted Resident Days | R4: Forecasted Resident Days | S4: Forecasted Resident Days | T4: Forecasted Resident Days | U4: Forecasted Resident Days | V4: Forecasted Resident Days | W4: Forecasted Resident Days | X4: Forecasted Resident Days | Y4: Forecasted Resident Days | Z4: Forecasted Resident Days | AA4: Forecasted Resident Days | AC4: Units | AD4: Units | AE4: Units | AF4: Units | AG4: Units | AH4: Units | AI4: Units | AJ4: Units | AK4: Units | AL4: Units | AM4: Units | AN4: Units | AP4: Census | AQ4: Census | AR4: Census | AS4: Census | AT4: Census | AU4: Census | AV4: Census | AW4: Census | AX4: Census | AY4: Census | AZ4: Census | BA4: Census | BC4: Census -Start Date | BD4: Census -Start Date | BE4: Census -Start Date | BF4: Census -Start Date | BG4: Census -Start Date | BH4: Census -Start Date | BI4: Census -Start Date | BJ4: Census -Start Date | BK4: Census -Start Date | BL4: Census -Start Date | BM4: Census -Start Date | BN4: Census -Start Date | BP4: Census - End Date | BQ4: Census - End Date | BR4: Census - End Date | BS4: Census - End Date | BT4: Census - End Date | BU4: Census - End Date | BV4: Census - End Date | BW4: Census - End Date | BX4: Census - End Date | BY4: Census - End Date | BZ4: Census - End Date | CA4: Census - End Date | CC4: Start REF | CD4: Start REF | CE4: Start REF | CF4: Start REF | CG4: Start REF | CH4: Start REF | CI4: Start REF | CJ4: Start REF | CK4: Start REF | CL4: Start REF | CM4: Start REF | CN4: Start REF | CP4: End REF | CQ4: End REF | CR4: End REF | CS4: End REF | CT4: End REF | CU4: End REF | CV4: End REF | CW4: End REF | CX4: End REF | CY4: End REF | CZ4: End REF | DA4: End REF | DG4: Start Date Row Counts | DH4: End Date Row Counts | DJ4: StartDate | DK4: EndDate | DL4: BudgetAvailablePerDay | DM4: BudgetResidentDaysPerDay | DN4: StartDate | DO4: EndDate | DP4: BudgetAvailablePerDay | DQ4: BudgetResidentDaysPerDay | DR4: StartDate | DS4: EndDate | DT4: BudgetAvailablePerDay | DU4: BudgetResidentDaysPerDay | DV4: StartDate | DW4: EndDate | DX4: BudgetAvailablePerDay | DY4: BudgetResidentDaysPerDay | DZ4: StartDate | EA4: EndDate | EB4: BudgetAvailablePerDay | EC4: BudgetResidentDaysPerDay | ED4: StartDate | EE4: EndDate | EF4: BudgetAvailablePerDay | EG4: BudgetResidentDaysPerDay | EH4: StartDate | EI4: EndDate | EJ4: BudgetAvailablePerDay | EK4: BudgetResidentDaysPerDay | EL4: StartDate | EM4: EndDate | EN4: BudgetAvailablePerDay | EO4: BudgetResidentDaysPerDay | EP4: StartDate | EQ4: EndDate | ER4: BudgetAvailablePerDay | ES4: BudgetResidentDaysPerDay | ET4: StartDate | EU4: EndDate | EV4: BudgetAvailablePerDay | EW4: BudgetResidentDaysPerDay | EX4: StartDate | EY4: EndDate | EZ4: BudgetAvailablePerDay | FA4: BudgetResidentDaysPerDay | FB4: StartDate | FC4: EndDate | FD4: BudgetAvailablePerDay | FE4: BudgetResidentDaysPerDay
C5: Jan-2025 | D5: Feb-2025 | E5: Mar-2025 | F5: Apr-2025 | G5: May-2025 | H5: Jun-2025 | I5: Jul-2025 | J5: Aug-2025 | K5: Sep-2025 | L5: Oct-2025 | M5: Nov-2025 | N5: Dec-2025 | P5: Jan-2025 | Q5: Feb-2025 | R5: Mar-2025 | S5: Apr-2025 | T5: May-2025 | U5: Jun-2025 | V5: Jul-2025 | W5: Aug-2025 | X5: Sep-2025 | Y5: Oct-2025 | Z5: Nov-2025 | AA5: Dec-2025 | AC5: =C5 -> Jan-2025 | AD5: =D5 -> Feb-2025 | AE5: =E5 -> Mar-2025 | AF5: =F5 -> Apr-2025 | AG5: =G5 -> May-2025 | AH5: =H5 -> Jun-2025 | AI5: =I5 -> Jul-2025 | AJ5: =J5 -> Aug-2025 | ... AN5: =N5 -> Dec-2025 | AP5: =P5 -> Jan-2025 | AQ5: =Q5 -> Feb-2025 | AR5: =R5 -> Mar-2025 | AS5: =S5 -> Apr-2025 | AT5: =T5 -> May-2025 | AU5: =U5 -> Jun-2025 | AV5: =V5 -> Jul-2025 | AW5: =W5 -> Aug-2025 | ... BA5: =AA5 -> Dec-2025 | BC5: =AC5 -> Jan-2025 | BD5: =AD5 -> Feb-2025 | BE5: =AE5 -> Mar-2025 | BF5: =AF5 -> Apr-2025 | BG5: =AG5 -> May-2025 | BH5: =AH5 -> Jun-2025 | BI5: =AI5 -> Jul-2025 | BJ5: =AJ5 -> Aug-2025 | ... BN5: =AN5 -> Dec-2025 | BP5: =AP5 -> Jan-2025 | BQ5: =AQ5 -> Feb-2025 | BR5: =AR5 -> Mar-2025 | BS5: =AS5 -> Apr-2025 | BT5: =AT5 -> May-2025 | BU5: =AU5 -> Jun-2025 | BV5: =AV5 -> Jul-2025 | BW5: =AW5 -> Aug-2025 | ... CA5: =BA5 -> Dec-2025 | CC5: =BC5 -> Jan-2025 | CD5: =BD5 -> Feb-2025 | CE5: =BE5 -> Mar-2025 | CF5: =BF5 -> Apr-2025 | CG5: =BG5 -> May-2025 | CH5: =BH5 -> Jun-2025 | CI5: =BI5 -> Jul-2025 | CJ5: =BJ5 -> Aug-2025 | ... CN5: =BN5 -> Dec-2025 | CP5: =BP5 -> Jan-2025 | CQ5: =BQ5 -> Feb-2025 | CR5: =BR5 -> Mar-2025 | CS5: =BS5 -> Apr-2025 | CT5: =BT5 -> May-2025 | CU5: =BU5 -> Jun-2025 | CV5: =BV5 -> Jul-2025 | CW5: =BW5 -> Aug-2025 | ... DA5: =CA5 -> Dec-2025 | DC5: Ent | DD5: Fac | DE5: Ent-Fac | DJ5: 1 | DK5: 1 | DL5: 1 | DM5: 1 | DN5: =DJ5+1 -> 2 | DO5: =DK5+1 -> 2 | DP5: =DL5+1 -> 2 | DQ5: =DM5+1 -> 2 | DR5: =DN5+1 -> 3 | DS5: =DO5+1 -> 3 | DT5: =DP5+1 -> 3 | DU5: =DQ5+1 -> 3 | ... FE5: =FA5+1 -> 12
B6: 100-21 Villas/Cottages | C6: 2263 | D6: 2044 | E6: 2263 | F6: 2190 | G6: 2263 | H6: 2190 | I6: 2263 | J6: 2263 | K6: 2190 | L6: 2263 | M6: 2190 | N6: 2263 | P6: 2185.5 | Q6: 1974 | R6: 2185.5 | S6: 2115 | T6: 2185.5 | U6: 2115 | V6: 2185.5 | W6: 2185.5 | X6: 2115 | Y6: 2185.5 | Z6: 2115 | AA6: 2185.5 | AC6: =C6/_xlfn.XLOOKUP(AC$5,'OC-Days'!$G:$G,'OC-Days'!$B:$B) -> 73 | AD6: =D6/_xlfn.XLOOKUP(AD$5,'OC-Days'!$G:$G,'OC-Days'!$B:$B) -> 73 | AE6: =E6/_xlfn.XLOOKUP(AE$5,'OC-Days'!$G:$G,'OC-Days'!$B:$B) -> 73 | AF6: =F6/_xlfn.XLOOKUP(AF$5,'OC-Days'!$G:$G,'OC-Days'!$B:$B) -> 73 | AG6: =G6/_xlfn.XLOOKUP(AG$5,'OC-Days'!$G:$G,'OC-Days'!$B:$B) -> 73 | AH6: =H6/_xlfn.XLOOKUP(AH$5,'OC-Days'!$G:$G,'OC-Days'!$B:$B) -> 73 | AI6: =I6/_xlfn.XLOOKUP(AI$5,'OC-Days'!$G:$G,'OC-Days'!$B:$B) -> 73 | AJ6: =J6/_xlfn.XLOOKUP(AJ$5,'OC-Days'!$G:$G,'OC-Days'!$B:$B) -> 73 | ... AN6: =N6/_xlfn.XLOOKUP(AN$5,'OC-Days'!$G:$G,'OC-Days'!$B:$B) -> 73 | AP6: =P6/_xlfn.XLOOKUP(AP$5,'OC-Days'!$G:$G,'OC-Days'!$B:$B) -> 70.5 | AQ6: =Q6/_xlfn.XLOOKUP(AQ$5,'OC-Days'!$G:$G,'OC-Days'!$B:$B) -> 70.5 | AR6: =R6/_xlfn.XLOOKUP(AR$5,'OC-Days'!$G:$G,'OC-Days'!$B:$B) -> 70.5 | AS6: =S6/_xlfn.XLOOKUP(AS$5,'OC-Days'!$G:$G,'OC-Days'!$B:$B) -> 70.5 | AT6: =T6/_xlfn.XLOOKUP(AT$5,'OC-Days'!$G:$G,'OC-Days'!$B:$B) -> 70.5 | AU6: =U6/_xlfn.XLOOKUP(AU$5,'OC-Days'!$G:$G,'OC-Days'!$B:$B) -> 70.5 | AV6: =V6/_xlfn.XLOOKUP(AV$5,'OC-Days'!$G:$G,'OC-Days'!$B:$B) -> 70.5 | AW6: =W6/_xlfn.XLOOKUP(AW$5,'OC-Days'!$G:$G,'OC-Days'!$B:$B) -> 70.5 | ... BA6: =AA6/_xlfn.XLOOKUP(BA$5,'OC-Days'!$G:$G,'OC-Days'!$B:$B) -> 70.5 | BC6: =_xlfn.XLOOKUP(BC$5,'OC-Days'!$G:$G,'OC-Days'!$F:$F) -> 45658 | BD6: =IF(AQ6=AP6,"na",_xlfn.XLOOKUP(BD$5,'OC-Days'!$G:$G,'OC-Days'!$F:$F)) -> na | BE6: =IF(AR6=AQ6,"na",_xlfn.XLOOKUP(BE$5,'OC-Days'!$G:$G,'OC-Days'!$F:$F)) -> na | BF6: =IF(AS6=AR6,"na",_xlfn.XLOOKUP(BF$5,'OC-Days'!$G:$G,'OC-Days'!$F:$F)) -> na | BG6: =IF(AT6=AS6,"na",_xlfn.XLOOKUP(BG$5,'OC-Days'!$G:$G,'OC-Days'!$F:$F)) -> na | BH6: =IF(AU6=AT6,"na",_xlfn.XLOOKUP(BH$5,'OC-Days'!$G:$G,'OC-Days'!$F:$F)) -> na | BI6: =IF(AV6=AU6,"na",_xlfn.XLOOKUP(BI$5,'OC-Days'!$G:$G,'OC-Days'!$F:$F)) -> na | BJ6: =IF(AW6=AV6,"na",_xlfn.XLOOKUP(BJ$5,'OC-Days'!$G:$G,'OC-Days'!$F:$F)) -> na | BK6: =IF(AX6=AW6,"na",_xlfn.XLOOKUP(BK$5,'OC-Days'!$G:$G,'OC-Days'!$F:$F)) -> na | ... BN6: =IF(BA6=AZ6,"na",_xlfn.XLOOKUP(BN$5,'OC-Days'!$G:$G,'OC-Days'!$F:$F)) -> na | BP6: =IF(BD6="na",BD6,BD6-1) -> na | BQ6: =IF(BE6="na",BE6,BE6-1) -> na | BR6: =IF(BF6="na",BF6,BF6-1) -> na | BS6: =IF(BG6="na",BG6,BG6-1) -> na | BT6: =IF(BH6="na",BH6,BH6-1) -> na | BU6: =IF(BI6="na",BI6,BI6-1) -> na | BV6: =IF(BJ6="na",BJ6,BJ6-1) -> na | BW6: =IF(BK6="na",BK6,BK6-1) -> na | ... BZ6: =IF(BN6="na",BN6,BN6-1) -> na | CA6: =DATE(VALUE(RIGHT($CA$5,4)),12,31) -> 46022 | CC6: =COUNT($BC6:BC6) -> 1 | CD6: =COUNT($BC6:BD6) -> 1 | CE6: =COUNT($BC6:BE6) -> 1 | CF6: =COUNT($BC6:BF6) -> 1 | CG6: =COUNT($BC6:BG6) -> 1 | CH6: =COUNT($BC6:BH6) -> 1 | CI6: =COUNT($BC6:BI6) -> 1 | CJ6: =COUNT($BC6:BJ6) -> 1 | ... CN6: =COUNT($BC6:BN6) -> 1 | CP6: =COUNT($BP6:BP6) -> 0 | CQ6: =COUNT($BP6:BQ6) -> 0 | CR6: =COUNT($BP6:BR6) -> 0 | CS6: =COUNT($BP6:BS6) -> 0 | CT6: =COUNT($BP6:BT6) -> 0 | CU6: =COUNT($BP6:BU6) -> 0 | CV6: =COUNT($BP6:BV6) -> 0 | CW6: =COUNT($BP6:BW6) -> 0 | ... DA6: =COUNT($BP6:CA6) -> 1 | DC6: =IF(ISNUMBER(VALUE(LEFT(B6,3))),VALUE(LEFT(B6,3)),"Entity") -> 100 | DD6: =IF(ISNUMBER(VALUE(MID(B6,5,2))),VALUE(MID(B6,5,2)),"Rollup") -> 21 | DE6: =DC6&"-"&DD6 -> 100-21 | DG6: =COUNT(BC6:BN6) -> 1 | DH6: =COUNT(BP6:CA6) -> 1 | DJ6: {=IF(DJ$5<=$DG6,INDEX($BC6:$BN6,1,_xlfn.XMATCH(DJ$5,$CC6:$CN6)),"na")} -> 45658 | DK6: {=IF(DK$5<=$DH6,INDEX($BP6:$CA6,1,_xlfn.XMATCH(DK$5,$CP6:$DA6)),"na")} -> 46022 | DL6: {=IF(DL$5<=$DG6,INDEX($AC6:$AN6,1,_xlfn.XMATCH(DL$5,$CC6:$CN6)),"na")} -> 73 | DM6: {=IF(DM$5<=$DG6,INDEX($AP6:$BA6,1,_xlfn.XMATCH(DM$5,$CC6:$CN6)),"na")} -> 70.5 | DN6: {=IF(DN$5<=$DG6,INDEX($BC6:$BN6,1,_xlfn.XMATCH(DN$5,$CC6:$CN6)),"na")} -> na | DO6: {=IF(DO$5<=$DH6,INDEX($BP6:$CA6,1,_xlfn.XMATCH(DO$5,$CP6:$DA6)),"na")} -> na | DP6: {=IF(DP$5<=$DG6,INDEX($AC6:$AN6,1,_xlfn.XMATCH(DP$5,$CC6:$CN6)),"na")} -> na | DQ6: {=IF(DQ$5<=$DG6,INDEX($AP6:$BA6,1,_xlfn.XMATCH(DQ$5,$CC6:$CN6)),"na")} -> na | DR6: {=IF(DR$5<=$DG6,INDEX($BC6:$BN6,1,_xlfn.XMATCH(DR$5,$CC6:$CN6)),"na")} -> na | DS6: {=IF(DS$5<=$DH6,INDEX($BP6:$CA6,1,_xlfn.XMATCH(DS$5,$CP6:$DA6)),"na")} -> na | DT6: {=IF(DT$5<=$DG6,INDEX($AC6:$AN6,1,_xlfn.XMATCH(DT$5,$CC6:$CN6)),"na")} -> na | DU6: {=IF(DU$5<=$DG6,INDEX($AP6:$BA6,1,_xlfn.XMATCH(DU$5,$CC6:$CN6)),"na")} -> na | DV6: {=IF(DV$5<=$DG6,INDEX($BC6:$BN6,1,_xlfn.XMATCH(DV$5,$CC6:$CN6)),"na")} -> na | DW6: {=IF(DW$5<=$DH6,INDEX($BP6:$CA6,1,_xlfn.XMATCH(DW$5,$CP6:$DA6)),"na")} -> na | DX6: {=IF(DX$5<=$DG6,INDEX($AC6:$AN6,1,_xlfn.XMATCH(DX$5,$CC6:$CN6)),"na")} -> na | DY6: {=IF(DY$5<=$DG6,INDEX($AP6:$BA6,1,_xlfn.XMATCH(DY$5,$CC6:$CN6)),"na")} -> na | DZ6: {=IF(DZ$5<=$DG6,INDEX($BC6:$BN6,1,_xlfn.XMATCH(DZ$5,$CC6:$CN6)),"na")} -> na | EA6: {=IF(EA$5<=$DH6,INDEX($BP6:$CA6,1,_xlfn.XMATCH(EA$5,$CP6:$DA6)),"na")} -> na | EB6: {=IF(EB$5<=$DG6,INDEX($AC6:$AN6,1,_xlfn.XMATCH(EB$5,$CC6:$CN6)),"na")} -> na | EC6: {=IF(EC$5<=$DG6,INDEX($AP6:$BA6,1,_xlfn.XMATCH(EC$5,$CC6:$CN6)),"na")} -> na | ED6: {=IF(ED$5<=$DG6,INDEX($BC6:$BN6,1,_xlfn.XMATCH(ED$5,$CC6:$CN6)),"na")} -> na | EE6: {=IF(EE$5<=$DH6,INDEX($BP6:$CA6,1,_xlfn.XMATCH(EE$5,$CP6:$DA6)),"na")} -> na | EF6: {=IF(EF$5<=$DG6,INDEX($AC6:$AN6,1,_xlfn.XMATCH(EF$5,$CC6:$CN6)),"na")} -> na | EG6: {=IF(EG$5<=$DG6,INDEX($AP6:$BA6,1,_xlfn.XMATCH(EG$5,$CC6:$CN6)),"na")} -> na | EH6: {=IF(EH$5<=$DG6,INDEX($BC6:$BN6,1,_xlfn.XMATCH(EH$5,$CC6:$CN6)),"na")} -> na | EI6: {=IF(EI$5<=$DH6,INDEX($BP6:$CA6,1,_xlfn.XMATCH(EI$5,$CP6:$DA6)),"na")} -> na | EJ6: {=IF(EJ$5<=$DG6,INDEX($AC6:$AN6,1,_xlfn.XMATCH(EJ$5,$CC6:$CN6)),"na")} -> na | EK6: {=IF(EK$5<=$DG6,INDEX($AP6:$BA6,1,_xlfn.XMATCH(EK$5,$CC6:$CN6)),"na")} -> na | EL6: {=IF(EL$5<=$DG6,INDEX($BC6:$BN6,1,_xlfn.XMATCH(EL$5,$CC6:$CN6)),"na")} -> na | EM6: {=IF(EM$5<=$DH6,INDEX($BP6:$CA6,1,_xlfn.XMATCH(EM$5,$CP6:$DA6)),"na")} -> na | EN6: {=IF(EN$5<=$DG6,INDEX($AC6:$AN6,1,_xlfn.XMATCH(EN$5,$CC6:$CN6)),"na")} -> na | EO6: {=IF(EO$5<=$DG6,INDEX($AP6:$BA6,1,_xlfn.XMATCH(EO$5,$CC6:$CN6)),"na")} -> na | EP6: {=IF(EP$5<=$DG6,INDEX($BC6:$BN6,1,_xlfn.XMATCH(EP$5,$CC6:$CN6)),"na")} -> na | EQ6: {=IF(EQ$5<=$DH6,INDEX($BP6:$CA6,1,_xlfn.XMATCH(EQ$5,$CP6:$DA6)),"na")} -> na | ER6: {=IF(ER$5<=$DG6,INDEX($AC6:$AN6,1,_xlfn.XMATCH(ER$5,$CC6:$CN6)),"na")} -> na | ES6: {=IF(ES$5<=$DG6,INDEX($AP6:$BA6,1,_xlfn.XMATCH(ES$5,$CC6:$CN6)),"na")} -> na | ET6: {=IF(ET$5<=$DG6,INDEX($BC6:$BN6,1,_xlfn.XMATCH(ET$5,$CC6:$CN6)),"na")} -> na | EU6: {=IF(EU$5<=$DH6,INDEX($BP6:$CA6,1,_xlfn.XMATCH(EU$5,$CP6:$DA6)),"na")} -> na | EV6: {=IF(EV$5<=$DG6,INDEX($AC6:$AN6,1,_xlfn.XMATCH(EV$5,$CC6:$CN6)),"na")} -> na | EW6: {=IF(EW$5<=$DG6,INDEX($AP6:$BA6,1,_xlfn.XMATCH(EW$5,$CC6:$CN6)),"na")} -> na | EX6: {=IF(EX$5<=$DG6,INDEX($BC6:$BN6,1,_xlfn.XMATCH(EX$5,$CC6:$CN6)),"na")} -> na | EY6: {=IF(EY$5<=$DH6,INDEX($BP6:$CA6,1,_xlfn.XMATCH(EY$5,$CP6:$DA6)),"na")} -> na | EZ6: {=IF(EZ$5<=$DG6,INDEX($AC6:$AN6,1,_xlfn.XMATCH(EZ$5,$CC6:$CN6)),"na")} -> na | FA6: {=IF(FA$5<=$DG6,INDEX($AP6:$BA6,1,_xlfn.XMATCH(FA$5,$CC6:$CN6)),"na")} -> na | FB6: {=IF(FB$5<=$DG6,INDEX($BC6:$BN6,1,_xlfn.XMATCH(FB$5,$CC6:$CN6)),"na")} -> na | FC6: {=IF(FC$5<=$DH6,INDEX($BP6:$CA6,1,_xlfn.XMATCH(FC$5,$CP6:$DA6)),"na")} -> na | FD6: {=IF(FD$5<=$DG6,INDEX($AC6:$AN6,1,_xlfn.XMATCH(FD$5,$CC6:$CN6)),"na")} -> na | FE6: {=IF(FE$5<=$DG6,INDEX($AP6:$BA6,1,_xlfn.XMATCH(FE$5,$CC6:$CN6)),"na")} -> na
B7: 100-22 Villas/Cottages B (AMV=Courtyard Homes, BV=BV West, APKS=Patio Homes) | C7: 1333 | D7: 1204 | E7: 1333 | F7: 1290 | G7: 1333 | H7: 1290 | I7: 1333 | J7: 1333 | K7: 1290 | L7: 1333 | M7: 1290 | N7: 1333 | P7: 1302 | Q7: 1176 | R7: 1302 | S7: 1260 | T7: 1302 | U7: 1260 | V7: 1302 | W7: 1302 | X7: 1260 | Y7: 1302 | Z7: 1260 | AA7: 1302 | AC7: =C7/_xlfn.XLOOKUP(AC$5,'OC-Days'!$G:$G,'OC-Days'!$B:$B) -> 43 | AD7: =D7/_xlfn.XLOOKUP(AD$5,'OC-Days'!$G:$G,'OC-Days'!$B:$B) -> 43 | AE7: =E7/_xlfn.XLOOKUP(AE$5,'OC-Days'!$G:$G,'OC-Days'!$B:$B) -> 43 | AF7: =F7/_xlfn.XLOOKUP(AF$5,'OC-Days'!$G:$G,'OC-Days'!$B:$B) -> 43 | AG7: =G7/_xlfn.XLOOKUP(AG$5,'OC-Days'!$G:$G,'OC-Days'!$B:$B) -> 43 | AH7: =H7/_xlfn.XLOOKUP(AH$5,'OC-Days'!$G:$G,'OC-Days'!$B:$B) -> 43 | AI7: =I7/_xlfn.XLOOKUP(AI$5,'OC-Days'!$G:$G,'OC-Days'!$B:$B) -> 43 | AJ7: =J7/_xlfn.XLOOKUP(AJ$5,'OC-Days'!$G:$G,'OC-Days'!$B:$B) -> 43 | ... AN7: =N7/_xlfn.XLOOKUP(AN$5,'OC-Days'!$G:$G,'OC-Days'!$B:$B) -> 43 | AP7: =P7/_xlfn.XLOOKUP(AP$5,'OC-Days'!$G:$G,'OC-Days'!$B:$B) -> 42 | AQ7: =Q7/_xlfn.XLOOKUP(AQ$5,'OC-Days'!$G:$G,'OC-Days'!$B:$B) -> 42 | AR7: =R7/_xlfn.XLOOKUP(AR$5,'OC-Days'!$G:$G,'OC-Days'!$B:$B) -> 42 | AS7: =S7/_xlfn.XLOOKUP(AS$5,'OC-Days'!$G:$G,'OC-Days'!$B:$B) -> 42 | AT7: =T7/_xlfn.XLOOKUP(AT$5,'OC-Days'!$G:$G,'OC-Days'!$B:$B) -> 42 | AU7: =U7/_xlfn.XLOOKUP(AU$5,'OC-Days'!$G:$G,'OC-Days'!$B:$B) -> 42 | AV7: =V7/_xlfn.XLOOKUP(AV$5,'OC-Days'!$G:$G,'OC-Days'!$B:$B) -> 42 | AW7: =W7/_xlfn.XLOOKUP(AW$5,'OC-Days'!$G:$G,'OC-Days'!$B:$B) -> 42 | ... BA7: =AA7/_xlfn.XLOOKUP(BA$5,'OC-Days'!$G:$G,'OC-Days'!$B:$B) -> 42 | BC7: =_xlfn.XLOOKUP(BC$5,'OC-Days'!$G:$G,'OC-Days'!$F:$F) -> 45658 | BD7: =IF(AQ7=AP7,"na",_xlfn.XLOOKUP(BD$5,'OC-Days'!$G:$G,'OC-Days'!$F:$F)) -> na | BE7: =IF(AR7=AQ7,"na",_xlfn.XLOOKUP(BE$5,'OC-Days'!$G:$G,'OC-Days'!$F:$F)) -> na | BF7: =IF(AS7=AR7,"na",_xlfn.XLOOKUP(BF$5,'OC-Days'!$G:$G,'OC-Days'!$F:$F)) -> na | BG7: =IF(AT7=AS7,"na",_xlfn.XLOOKUP(BG$5,'OC-Days'!$G:$G,'OC-Days'!$F:$F)) -> na | BH7: =IF(AU7=AT7,"na",_xlfn.XLOOKUP(BH$5,'OC-Days'!$G:$G,'OC-Days'!$F:$F)) -> na | BI7: =IF(AV7=AU7,"na",_xlfn.XLOOKUP(BI$5,'OC-Days'!$G:$G,'OC-Days'!$F:$F)) -> na | BJ7: =IF(AW7=AV7,"na",_xlfn.XLOOKUP(BJ$5,'OC-Days'!$G:$G,'OC-Days'!$F:$F)) -> na | BK7: =IF(AX7=AW7,"na",_xlfn.XLOOKUP(BK$5,'OC-Days'!$G:$G,'OC-Days'!$F:$F)) -> na | ... BN7: =IF(BA7=AZ7,"na",_xlfn.XLOOKUP(BN$5,'OC-Days'!$G:$G,'OC-Days'!$F:$F)) -> na | BP7: =IF(BD7="na",BD7,BD7-1) -> na | BQ7: =IF(BE7="na",BE7,BE7-1) -> na | BR7: =IF(BF7="na",BF7,BF7-1) -> na | BS7: =IF(BG7="na",BG7,BG7-1) -> na | BT7: =IF(BH7="na",BH7,BH7-1) -> na | BU7: =IF(BI7="na",BI7,BI7-1) -> na | BV7: =IF(BJ7="na",BJ7,BJ7-1) -> na | BW7: =IF(BK7="na",BK7,BK7-1) -> na | ... BZ7: =IF(BN7="na",BN7,BN7-1) -> na | CA7: =DATE(VALUE(RIGHT($CA$5,4)),12,31) -> 46022 | CC7: =COUNT($BC7:BC7) -> 1 | CD7: =COUNT($BC7:BD7) -> 1 | CE7: =COUNT($BC7:BE7) -> 1 | CF7: =COUNT($BC7:BF7) -> 1 | CG7: =COUNT($BC7:BG7) -> 1 | CH7: =COUNT($BC7:BH7) -> 1 | CI7: =COUNT($BC7:BI7) -> 1 | CJ7: =COUNT($BC7:BJ7) -> 1 | ... CN7: =COUNT($BC7:BN7) -> 1 | CP7: =COUNT($BP7:BP7) -> 0 | CQ7: =COUNT($BP7:BQ7) -> 0 | CR7: =COUNT($BP7:BR7) -> 0 | CS7: =COUNT($BP7:BS7) -> 0 | CT7: =COUNT($BP7:BT7) -> 0 | CU7: =COUNT($BP7:BU7) -> 0 | CV7: =COUNT($BP7:BV7) -> 0 | CW7: =COUNT($BP7:BW7) -> 0 | ... DA7: =COUNT($BP7:CA7) -> 1 | DC7: =IF(ISNUMBER(VALUE(LEFT(B7,3))),VALUE(LEFT(B7,3)),"Entity") -> 100 | DD7: =IF(ISNUMBER(VALUE(MID(B7,5,2))),VALUE(MID(B7,5,2)),"Rollup") -> 22 | DE7: =DC7&"-"&DD7 -> 100-22 | DG7: =COUNT(BC7:BN7) -> 1 | DH7: =COUNT(BP7:CA7) -> 1 | DJ7: {=IF(DJ$5<=$DG7,INDEX($BC7:$BN7,1,_xlfn.XMATCH(DJ$5,$CC7:$CN7)),"na")} -> 45658 | DK7: {=IF(DK$5<=$DH7,INDEX($BP7:$CA7,1,_xlfn.XMATCH(DK$5,$CP7:$DA7)),"na")} -> 46022 | DL7: {=IF(DL$5<=$DG7,INDEX($AC7:$AN7,1,_xlfn.XMATCH(DL$5,$CC7:$CN7)),"na")} -> 43 | DM7: {=IF(DM$5<=$DG7,INDEX($AP7:$BA7,1,_xlfn.XMATCH(DM$5,$CC7:$CN7)),"na")} -> 42 | DN7: {=IF(DN$5<=$DG7,INDEX($BC7:$BN7,1,_xlfn.XMATCH(DN$5,$CC7:$CN7)),"na")} -> na | DO7: {=IF(DO$5<=$DH7,INDEX($BP7:$CA7,1,_xlfn.XMATCH(DO$5,$CP7:$DA7)),"na")} -> na | DP7: {=IF(DP$5<=$DG7,INDEX($AC7:$AN7,1,_xlfn.XMATCH(DP$5,$CC7:$CN7)),"na")} -> na | DQ7: {=IF(DQ$5<=$DG7,INDEX($AP7:$BA7,1,_xlfn.XMATCH(DQ$5,$CC7:$CN7)),"na")} -> na | DR7: {=IF(DR$5<=$DG7,INDEX($BC7:$BN7,1,_xlfn.XMATCH(DR$5,$CC7:$CN7)),"na")} -> na | DS7: {=IF(DS$5<=$DH7,INDEX($BP7:$CA7,1,_xlfn.XMATCH(DS$5,$CP7:$DA7)),"na")} -> na | DT7: {=IF(DT$5<=$DG7,INDEX($AC7:$AN7,1,_xlfn.XMATCH(DT$5,$CC7:$CN7)),"na")} -> na | DU7: {=IF(DU$5<=$DG7,INDEX($AP7:$BA7,1,_xlfn.XMATCH(DU$5,$CC7:$CN7)),"na")} -> na | DV7: {=IF(DV$5<=$DG7,INDEX($BC7:$BN7,1,_xlfn.XMATCH(DV$5,$CC7:$CN7)),"na")} -> na | DW7: {=IF(DW$5<=$DH7,INDEX($BP7:$CA7,1,_xlfn.XMATCH(DW$5,$CP7:$DA7)),"na")} -> na | DX7: {=IF(DX$5<=$DG7,INDEX($AC7:$AN7,1,_xlfn.XMATCH(DX$5,$CC7:$CN7)),"na")} -> na | DY7: {=IF(DY$5<=$DG7,INDEX($AP7:$BA7,1,_xlfn.XMATCH(DY$5,$CC7:$CN7)),"na")} -> na | DZ7: {=IF(DZ$5<=$DG7,INDEX($BC7:$BN7,1,_xlfn.XMATCH(DZ$5,$CC7:$CN7)),"na")} -> na | EA7: {=IF(EA$5<=$DH7,INDEX($BP7:$CA7,1,_xlfn.XMATCH(EA$5,$CP7:$DA7)),"na")} -> na | EB7: {=IF(EB$5<=$DG7,INDEX($AC7:$AN7,1,_xlfn.XMATCH(EB$5,$CC7:$CN7)),"na")} -> na | EC7: {=IF(EC$5<=$DG7,INDEX($AP7:$BA7,1,_xlfn.XMATCH(EC$5,$CC7:$CN7)),"na")} -> na | ED7: {=IF(ED$5<=$DG7,INDEX($BC7:$BN7,1,_xlfn.XMATCH(ED$5,$CC7:$CN7)),"na")} -> na | EE7: {=IF(EE$5<=$DH7,INDEX($BP7:$CA7,1,_xlfn.XMATCH(EE$5,$CP7:$DA7)),"na")} -> na | EF7: {=IF(EF$5<=$DG7,INDEX($AC7:$AN7,1,_xlfn.XMATCH(EF$5,$CC7:$CN7)),"na")} -> na | EG7: {=IF(EG$5<=$DG7,INDEX($AP7:$BA7,1,_xlfn.XMATCH(EG$5,$CC7:$CN7)),"na")} -> na | EH7: {=IF(EH$5<=$DG7,INDEX($BC7:$BN7,1,_xlfn.XMATCH(EH$5,$CC7:$CN7)),"na")} -> na | EI7: {=IF(EI$5<=$DH7,INDEX($BP7:$CA7,1,_xlfn.XMATCH(EI$5,$CP7:$DA7)),"na")} -> na | EJ7: {=IF(EJ$5<=$DG7,INDEX($AC7:$AN7,1,_xlfn.XMATCH(EJ$5,$CC7:$CN7)),"na")} -> na | EK7: {=IF(EK$5<=$DG7,INDEX($AP7:$BA7,1,_xlfn.XMATCH(EK$5,$CC7:$CN7)),"na")} -> na | EL7: {=IF(EL$5<=$DG7,INDEX($BC7:$BN7,1,_xlfn.XMATCH(EL$5,$CC7:$CN7)),"na")} -> na | EM7: {=IF(EM$5<=$DH7,INDEX($BP7:$CA7,1,_xlfn.XMATCH(EM$5,$CP7:$DA7)),"na")} -> na | EN7: {=IF(EN$5<=$DG7,INDEX($AC7:$AN7,1,_xlfn.XMATCH(EN$5,$CC7:$CN7)),"na")} -> na | EO7: {=IF(EO$5<=$DG7,INDEX($AP7:$BA7,1,_xlfn.XMATCH(EO$5,$CC7:$CN7)),"na")} -> na | EP7: {=IF(EP$5<=$DG7,INDEX($BC7:$BN7,1,_xlfn.XMATCH(EP$5,$CC7:$CN7)),"na")} -> na | EQ7: {=IF(EQ$5<=$DH7,INDEX($BP7:$CA7,1,_xlfn.XMATCH(EQ$5,$CP7:$DA7)),"na")} -> na | ER7: {=IF(ER$5<=$DG7,INDEX($AC7:$AN7,1,_xlfn.XMATCH(ER$5,$CC7:$CN7)),"na")} -> na | ES7: {=IF(ES$5<=$DG7,INDEX($AP7:$BA7,1,_xlfn.XMATCH(ES$5,$CC7:$CN7)),"na")} -> na | ET7: {=IF(ET$5<=$DG7,INDEX($BC7:$BN7,1,_xlfn.XMATCH(ET$5,$CC7:$CN7)),"na")} -> na | EU7: {=IF(EU$5<=$DH7,INDEX($BP7:$CA7,1,_xlfn.XMATCH(EU$5,$CP7:$DA7)),"na")} -> na | EV7: {=IF(EV$5<=$DG7,INDEX($AC7:$AN7,1,_xlfn.XMATCH(EV$5,$CC7:$CN7)),"na")} -> na | EW7: {=IF(EW$5<=$DG7,INDEX($AP7:$BA7,1,_xlfn.XMATCH(EW$5,$CC7:$CN7)),"na")} -> na | EX7: {=IF(EX$5<=$DG7,INDEX($BC7:$BN7,1,_xlfn.XMATCH(EX$5,$CC7:$CN7)),"na")} -> na | EY7: {=IF(EY$5<=$DH7,INDEX($BP7:$CA7,1,_xlfn.XMATCH(EY$5,$CP7:$DA7)),"na")} -> na | EZ7: {=IF(EZ$5<=$DG7,INDEX($AC7:$AN7,1,_xlfn.XMATCH(EZ$5,$CC7:$CN7)),"na")} -> na | FA7: {=IF(FA$5<=$DG7,INDEX($AP7:$BA7,1,_xlfn.XMATCH(FA$5,$CC7:$CN7)),"na")} -> na | FB7: {=IF(FB$5<=$DG7,INDEX($BC7:$BN7,1,_xlfn.XMATCH(FB$5,$CC7:$CN7)),"na")} -> na | FC7: {=IF(FC$5<=$DH7,INDEX($BP7:$CA7,1,_xlfn.XMATCH(FC$5,$CP7:$DA7)),"na")} -> na | FD7: {=IF(FD$5<=$DG7,INDEX($AC7:$AN7,1,_xlfn.XMATCH(FD$5,$CC7:$CN7)),"na")} -> na | FE7: {=IF(FE$5<=$DG7,INDEX($AP7:$BA7,1,_xlfn.XMATCH(FE$5,$CC7:$CN7)),"na")} -> na
