Workbook

Sheet CrossfireHiddenWorksheet
A3: e1e453d0-67f4-4098-ad1d-a87e7568f810 | B3: c12bf6ad-161d-474a-ae93-3487acc74e25 | C3: 2d163a86-cffd-43e5-8e01-bbf10c20e10d
A4: 1 | B4: 7 | C4: 13
A5: =OC!$7:$7 -> 100 Asbury Methodist Village | B5: 12 | C5: =OC!$B:$B -> Operating Ratio Revenue | D5: 1 | E5: =OC!$B$3 -> FY2025 | F5: 3 | G5: ='OC-Expand'!$69:$69 -> 0 | H5: 12 | I5: ='OC-Expand'!$B:$B -> Operating Ratio Revenue (New) | J5: 1 | K5: ='OC-Expand'!$B$3 -> FY2024 | L5: 3 | M5: ='OC-Monthly'!$25:$25 -> 499516.02 | N5: 11 | O5: ='OC-Monthly'!$N:$N -> Operating_Ratio_Revenue_Metric_New | P5: 1 | Q5: ='OC-Monthly'!$N$6 -> FY2025 | R5: 3
A6: =OC!$8:$8 -> 200 Asbury Solomons | B6: 13 | C6: =OC!$C:$C -> Operating_Ratio_Expenses_Metric_New | D6: 2 | E6: =OC!$C$3 -> FY2025 | F6: 4 | G6: ='OC-Expand'!$71:$71 -> 0 | H6: 1248 | I6: ='OC-Expand'!$C:$C -> Operating_Ratio_Expenses_Metric_New | J6: 2 | K6: ='OC-Expand'!$C$3 -> FY2024 | L6: 4 | M6: ='OC-Monthly'!$7:$7 -> 7620525.4 | N6: 12 | O6: ='OC-Monthly'!$AB:$AB -> FY2025 | P6: 2 | Q6: ='OC-Monthly'!$AB$6 -> FY2025 | R6: 4
A7: =OC!$9:$9 -> 210 Calvert County Nursing Center | B7: 14 | E7: =OC!$B$4 -> Budget 2025 | F7: 5 | G7: ='OC-Expand'!$72:$72 -> 0 | H7: 1249 | K7: ='OC-Expand'!$B$4 -> Budget 2024 | L7: 5 | M7: ='OC-Monthly'!$8:$8 -> 1872877.2 | N7: 13 | O7: ='OC-Monthly'!$B:$B -> 7381980.9 | P7: 60 | Q7: ='OC-Monthly'!$N$3 -> Budget 2025 | R7: 5
A8: =OC!$10:$10 -> 324 Springhill | B8: 15 | E8: =OC!$C$4 -> Budget 2025 | F8: 6 | G8: ='OC-Expand'!$68:$68 -> 0 | H8: 1250 | K8: ='OC-Expand'!$C$4 -> Budget 2024 | L8: 6 | M8: ='OC-Monthly'!$9:$9 -> 0 | N8: 14 | O8: ='OC-Monthly'!$C:$C -> 1766045 | P8: 61 | Q8: ='OC-Monthly'!$AB$3 -> Budget 2025 | R8: 6
A9: =OC!$11:$11 -> 400 Asbury Foundation, Inc. | B9: 16 | E9: =OC!$B$5 -> Operating Ratio Revenue | F9: 7 | G9: ='OC-Expand'!$67:$67 -> 0 | H9: 1251 | K9: ='OC-Expand'!$B$5 -> Operating Ratio Revenue (New) | L9: 7 | M9: ='OC-Monthly'!$10:$10 -> 1760294.8 | N9: 15 | O9: ='OC-Monthly'!$D:$D -> 0 | P9: 62 | Q9: ='OC-Monthly'!$N$4 -> Operating Ratio Revenue | R9: 7
A10: =OC!$12:$12 -> 500 Asbury Communities, Inc. | B10: 17 | E10: =OC!$C$5 -> Operating Ratio Expenses | F10: 8 | G10: ='OC-Expand'!$66:$66 -> 0 | H10: 1252 | K10: ='OC-Expand'!$C$5 -> Operating Ratio Expenses (New) | L10: 8 | M10: ='OC-Monthly'!$11:$11 -> 111913.78 | N10: 16 | O10: ='OC-Monthly'!$E:$E -> 1742303.9 | P10: 63 | Q10: ='OC-Monthly'!$AB$4 -> Operating Ratio Expenses | R10: 8
A11: =OC!$17:$17 -> 670 Forest Ridge Manor | B11: 22 | E11: =OC!$B$6 -> Operating_Ratio_Revenue_Metric_New | F11: 9 | G11: ='OC-Expand'!$65:$65 -> 0 | H11: 1253 | K11: ='OC-Expand'!$B$6 -> Operating_Ratio_Revenue_Metric_New | L11: 9 | M11: ='OC-Monthly'!$12:$12 -> 1676939 | N11: 17 | O11: ='OC-Monthly'!$F:$F -> 24828.067 | P11: 64 | Q11: ='OC-Monthly'!$N$5 -> Operating_Ratio_Revenue_Metric_New | R11: 9
A12: =OC!$42:$42 -> HCBS | B12: 23 | E12: =OC!$C$6 -> Operating_Ratio_Expenses_Metric_New | F12: 10 | G12: ='OC-Expand'!$64:$64 -> 0 | H12: 1254 | K12: ='OC-Expand'!$C$6 -> Operating_Ratio_Expenses_Metric_New | L12: 10 | M12: ='OC-Monthly'!$46:$46 -> 0 | N12: 18 | O12: ='OC-Monthly'!$G:$G -> 1683439 | P12: 65 | Q12: ='OC-Monthly'!$AB$5 -> Operating_Ratio_Expenses_Metric_New | R12: 10
A13: =OC!$18:$18 -> 716 Asbury Place at Home | B13: 24 | G13: ='OC-Expand'!$63:$63 -> 0 | H13: 1255 | M13: ='OC-Monthly'!$45:$45 -> 0 | N13: 19 | O13: ='OC-Monthly'!$H:$H -> 0 | P13: 66 | Q13: ='OC-Monthly'!$B$6 -> Jan-2025 | R13: 72
A14: =OC!$19:$19 -> 810 Bethany Village | B14: 25 | G14: ='OC-Expand'!$62:$62 -> 0 | H14: 1256 | M14: ='OC-Monthly'!$44:$44 -> 0 | N14: 20 | O14: ='OC-Monthly'!$I:$I -> 0 | P14: 67 | Q14: ='OC-Monthly'!$C$6 -> Feb-2025 | R14: 73
A15: =OC!$20:$20 -> 815 Bethany Development | B15: 26 | G15: ='OC-Expand'!$61:$61 -> 0 | H15: 1257 | M15: ='OC-Monthly'!$43:$43 -> 0 | N15: 21 | O15: ='OC-Monthly'!$J:$J -> 0 | P15: 68 | Q15: ='OC-Monthly'!$D$6 -> Mar-2025 | R15: 74
A16: =OC!$21:$21 -> 900 The Asbury Group | B16: 27 | G16: ='OC-Expand'!$60:$60 -> 0 | H16: 1258 | M16: ='OC-Monthly'!$17:$17 -> 29370.167 | N16: 22 | O16: ='OC-Monthly'!$K:$K -> 0 | P16: 69 | Q16: ='OC-Monthly'!$E$6 -> Apr-2025 | R16: 75
A17: =OC!$22:$22 -> 910 ThriveWell Tech | B17: 28 | G17: ='OC-Expand'!$59:$59 -> 0 | H17: 1259 | M17: ='OC-Monthly'!$42:$42 -> 7375 | N17: 23 | O17: ='OC-Monthly'!$L:$L -> 29370.167 | P17: 70 | Q17: ='OC-Monthly'!$F$6 -> May-2025 | R17: 76
A18: =OC!$23:$23 -> 916 Westview One, LLC | B18: 29 | G18: ='OC-Expand'!$58:$58 -> 0 | H18: 1260 | M18: ='OC-Monthly'!$18:$18 -> 0 | N18: 24 | O18: ='OC-Monthly'!$M:$M -> 0 | P18: 71 | Q18: ='OC-Monthly'!$G$6 -> Jun-2025 | R18: 77
A19: =OC!$24:$24 -> 925 Chandler Estate | B19: 30 | G19: ='OC-Expand'!$57:$57 -> 0 | H19: 1261 | M19: ='OC-Monthly'!$19:$19 -> 3312222.1 | N19: 25 | O19: ='OC-Monthly'!$P:$P -> 2997636.9 | P19: 120 | Q19: ='OC-Monthly'!$H$6 -> Jul-2025 | R19: 78
A20: =OC!$25:$25 -> 835 Riverwoods | B20: 31 | G20: ='OC-Expand'!$56:$56 -> 0 | H20: 1262 | M20: ='OC-Monthly'!$20:$20 -> 185326.5 | N20: 26 | O20: ='OC-Monthly'!$Q:$Q -> 106696.25 | P20: 121 | Q20: ='OC-Monthly'!$I$6 -> Aug-2025 | R20: 79
A21: =OC!$26:$26 -> 840 Normandie Ridge | B21: 32 | G21: ='OC-Expand'!$55:$55 -> 0 | H21: 1263 | M21: ='OC-Monthly'!$21:$21 -> -67576.333 | N21: 27 | O21: ='OC-Monthly'!$R:$R -> 21581.167 | P21: 122 | Q21: ='OC-Monthly'!$J$6 -> Sep-2025 | R21: 80
A22: =OC!$27:$27 -> 845 Normandie Ridge Home Health | B22: 33 | G22: ='OC-Expand'!$54:$54 -> 0 | H22: 1264 | M22: ='OC-Monthly'!$22:$22 -> 868940.77 | N22: 28 | O22: ='OC-Monthly'!$S:$S -> 662960.83 | P22: 123 | Q22: ='OC-Monthly'!$K$6 -> Oct-2025 | R22: 81
A23: =OC!$28:$28 -> 850 ACS Pharmacy | B23: 34 | G23: ='OC-Expand'!$53:$53 -> 0 | H23: 1265 | M23: ='OC-Monthly'!$23:$23 -> 0 | N23: 29 | O23: ='OC-Monthly'!$T:$T -> 416.66667 | P23: 124 | Q23: ='OC-Monthly'!$L$6 -> Nov-2025 | R23: 82
A24: =OC!$29:$29 -> 851 LIFE Lancaster | B24: 35 | G24: ='OC-Expand'!$52:$52 -> 0 | H24: 1266 | M24: ='OC-Monthly'!$24:$24 -> 287883.06 | N24: 30 | O24: ='OC-Monthly'!$U:$U -> 248030.99 | P24: 125 | Q24: ='OC-Monthly'!$M$6 -> Dec-2025 | R24: 83
A25: =OC!$30:$30 -> 852 LIFE Lycoming | B25: 36 | G25: ='OC-Expand'!$51:$51 -> 0 | H25: 1267 | M25: ='OC-Monthly'!$26:$26 -> 1422827.6 | N25: 31 | O25: ='OC-Monthly'!$V:$V -> 489184.8 | P25: 126 | Q25: ='OC-Monthly'!$B$3 -> Budget 2025 | R25: 84
A26: =OC!$31:$31 -> 853 LIFE Lebanon | B26: 37 | G26: ='OC-Expand'!$50:$50 -> 0 | H26: 1268 | M26: ='OC-Monthly'!$27:$27 -> 0 | N26: 32 | O26: ='OC-Monthly'!$W:$W -> 1399301.4 | P26: 127 | Q26: ='OC-Monthly'!$C$3 -> Budget 2025 | R26: 85
A27: =OC!$32:$32 -> 854 LIFE Chester | B27: 38 | G27: ='OC-Expand'!$49:$49 -> 0 | H27: 1269 | M27: ='OC-Monthly'!$28:$28 -> 956796.94 | N27: 33 | O27: ='OC-Monthly'!$X:$X -> 0 | P27: 128 | Q27: ='OC-Monthly'!$D$3 -> Budget 2025 | R27: 86
A28: =OC!$33:$33 -> 855 LIFE Cumberland | B28: 39 | G28: ='OC-Expand'!$48:$48 -> 0 | H28: 1270 | M28: ='OC-Monthly'!$29:$29 -> 640287 | N28: 34 | O28: ='OC-Monthly'!$Y:$Y -> 946261.95 | P28: 129 | Q28: ='OC-Monthly'!$E$3 -> Budget 2025 | R28: 87
A29: =OC!$34:$34 -> 856 LIFE Franklin | B29: 40 | G29: ='OC-Expand'!$47:$47 -> 0 | H29: 1271 | M29: ='OC-Monthly'!$30:$30 -> 623980 | N29: 35 | O29: ='OC-Monthly'!$Z:$Z -> 670272.34 | P29: 130 | Q29: ='OC-Monthly'!$F$3 -> Budget 2025 | R29: 88
A30: =OC!$35:$35 -> 859 LIFE Parent | B30: 41 | G30: ='OC-Expand'!$46:$46 -> 0 | H30: 1272 | M30: ='OC-Monthly'!$31:$31 -> 478172.97 | N30: 36 | O30: ='OC-Monthly'!$AA:$AA -> 637514.48 | P30: 131 | Q30: ='OC-Monthly'!$G$3 -> Budget 2025 | R30: 89
A31: =OC!$36:$36 -> 860 ACS Fund Development | B31: 42 | G31: ='OC-Expand'!$45:$45 -> 0 | H31: 1273 | M31: ='OC-Monthly'!$32:$32 -> 0 | N31: 37 | Q31: ='OC-Monthly'!$H$3 -> Budget 2025 | R31: 90
A32: =OC!$37:$37 -> 861 Meals on Wheels | B32: 43 | G32: ='OC-Expand'!$44:$44 -> 0 | H32: 1274 | M32: ='OC-Monthly'!$33:$33 -> 534440 | N32: 38 | Q32: ='OC-Monthly'!$I$3 -> Budget 2025 | R32: 91
A33: =OC!$38:$38 -> 862 Slifer Museum | B33: 44 | G33: ='OC-Expand'!$43:$43 -> 0 | H33: 1275 | M33: ='OC-Monthly'!$34:$34 -> 414294 | N33: 39 | Q33: ='OC-Monthly'!$J$3 -> Budget 2025 | R33: 92
A34: =OC!$39:$39 -> 865 Central Office | B34: 45 | G34: ='OC-Expand'!$42:$42 -> 0 | H34: 1276 | M34: ='OC-Monthly'!$35:$35 -> 0 | N34: 40 | Q34: ='OC-Monthly'!$K$3 -> Budget 2025 | R34: 93
A35: =OC!$40:$40 -> 870 Warrior Run Manor | B35: 46 | G35: ='OC-Expand'!$41:$41 -> 0 | H35: 1277 | M35: ='OC-Monthly'!$36:$36 -> -10483.67 | N35: 41 | Q35: ='OC-Monthly'!$L$3 -> Budget 2025 | R35: 94
A36: =OC!$43:$43 -> 701 Asbury Communities HCBS, Inc. | B36: 47 | G36: ='OC-Expand'!$40:$40 -> 0 | H36: 1278 | M36: ='OC-Monthly'!$37:$37 -> 0 | N36: 42 | Q36: ='OC-Monthly'!$M$3 -> Budget 2025 | R36: 95
A37: =OC!$44:$44 -> 702 Laboratory | B37: 48 | G37: ='OC-Expand'!$39:$39 -> 0 | H37: 1279 | M37: ='OC-Monthly'!$38:$38 -> 0 | N37: 43 | Q37: ='OC-Monthly'!$B$4 -> Operating Ratio Revenue | R37: 96
A38: =OC!$45:$45 -> 711 Inverness at Home | B38: 49 | G38: ='OC-Expand'!$38:$38 -> 0 | H38: 1280 | M38: ='OC-Monthly'!$39:$39 -> 0 | N38: 44 | Q38: ='OC-Monthly'!$C$4 -> Operating Ratio Revenue | R38: 97
A39: =OC!$46:$46 -> 712 Springhill at Home | B39: 50 | G39: ='OC-Expand'!$37:$37 -> 0 | H39: 1281 | M39: ='OC-Monthly'!$40:$40 -> 67010.472 | N39: 45 | Q39: ='OC-Monthly'!$D$4 -> Operating Ratio Revenue | R39: 98
A40: =OC!$47:$47 -> 713 Asbury Methodist Village at Home | B40: 51 | G40: ='OC-Expand'!$36:$36 -> 0 | H40: 1282 | M40: ='OC-Monthly'!$47:$47 -> 7375 | N40: 46 | Q40: ='OC-Monthly'!$E$4 -> Operating Ratio Revenue | R40: 99
A41: =OC!$48:$48 -> 714 Solomons at Home | B41: 52 | G41: ='OC-Expand'!$35:$35 -> 0 | H41: 1283 | M41: ='OC-Monthly'!$48:$48 -> 0 | N41: 47 | Q41: ='OC-Monthly'!$F$4 -> Operating Ratio Revenue | R41: 100
A42: =OC!$49:$49 -> 715 Bethany Village at Home | B42: 53 | G42: ='OC-Expand'!$34:$34 -> 0 | H42: 1284 | M42: ='OC-Monthly'!$49:$49 -> 0 | N42: 48 | Q42: ='OC-Monthly'!$G$4 -> Operating Ratio Revenue | R42: 101
...

Sheet OfficeConnectCellHighlights

Sheet 2025 Load
A1: Prep | E1: For Qlik Load
A2: text | B2: f(x) | C2: text | E2: text | F2: f(x) | G2: f(x) | H2: f(x) | I2: text | J2: text | K2: f(x)
C3: 2023 Name Format | M3: Check vs Monthly
A4: OC Name | B4: Ent | C4: Name for Qlik? | E4: Year | F4: Entity | G4: Target Operating Revenue | H4: Target Operating Expenses | I4: Item Type | J4: Path | K4: OR | M4: Rev | N4: Exp
A5: 100 Asbury Methodist Village | B5: =LEFT(A5,3) -> 100 | C5: 100 Asbury Methodist Village | E5: 2025 | F5: =C5 -> 100 Asbury Methodist Village | G5: =_xlfn.XLOOKUP($A5,OC!$A:$A,OC!B:B) -> 89288685 | H5: =_xlfn.XLOOKUP($A5,OC!$A:$A,OC!C:C) -> 84219595 | I5: Item | J5: ReportingandData/Dashboards/Lists/Entity Operating Ratio Target | K5: =IFERROR(H5/G5,"na") -> 0.94322809 | M5: =G5-SUMIFS('2025 Load-Monthly'!I$5:I$485,'2025 Load-Monthly'!$H$5:$H$485,$F5) -> 0 | N5: =H5-SUMIFS('2025 Load-Monthly'!J$5:J$485,'2025 Load-Monthly'!$H$5:$H$485,$F5) -> 0
A6: 200 Asbury Solomons | B6: =LEFT(A6,3) -> 200 | C6: 200 Asbury Solomons | E6: 2025 | F6: =C6 -> 200 Asbury Solomons | G6: =_xlfn.XLOOKUP($A6,OC!$A:$A,OC!B:B) -> 22201274 | H6: =_xlfn.XLOOKUP($A6,OC!$A:$A,OC!C:C) -> 20064427 | I6: Item | J6: ReportingandData/Dashboards/Lists/Entity Operating Ratio Target | K6: =IFERROR(H6/G6,"na") -> 0.90375116 | M6: =G6-SUMIFS('2025 Load-Monthly'!I$5:I$485,'2025 Load-Monthly'!$H$5:$H$485,$F6) -> 0 | N6: =H6-SUMIFS('2025 Load-Monthly'!J$5:J$485,'2025 Load-Monthly'!$H$5:$H$485,$F6) -> 0
A7: 324 Springhill | B7: =LEFT(A7,3) -> 324 | C7: 324 Springhill | E7: 2025 | F7: =C7 -> 324 Springhill | G7: =_xlfn.XLOOKUP($A7,OC!$A:$A,OC!B:B) -> 20835667 | H7: =_xlfn.XLOOKUP($A7,OC!$A:$A,OC!C:C) -> 20625422 | I7: Item | J7: ReportingandData/Dashboards/Lists/Entity Operating Ratio Target | K7: =IFERROR(H7/G7,"na") -> 0.98990937 | M7: =G7-SUMIFS('2025 Load-Monthly'!I$5:I$485,'2025 Load-Monthly'!$H$5:$H$485,$F7) -> 0 | N7: =H7-SUMIFS('2025 Load-Monthly'!J$5:J$485,'2025 Load-Monthly'!$H$5:$H$485,$F7) -> 0
A8: 400 Asbury Foundation, Inc. | B8: =LEFT(A8,3) -> 400 | C8: 400 Asbury Foundation | E8: 2025 | F8: =C8 -> 400 Asbury Foundation | G8: =_xlfn.XLOOKUP($A8,OC!$A:$A,OC!B:B) -> 791853 | H8: =_xlfn.XLOOKUP($A8,OC!$A:$A,OC!C:C) -> 770786.29 | I8: Item | J8: ReportingandData/Dashboards/Lists/Entity Operating Ratio Target | K8: =IFERROR(H8/G8,"na") -> 0.97339568 | M8: =G8-SUMIFS('2025 Load-Monthly'!I$5:I$485,'2025 Load-Monthly'!$H$5:$H$485,$F8) -> 0 | N8: =H8-SUMIFS('2025 Load-Monthly'!J$5:J$485,'2025 Load-Monthly'!$H$5:$H$485,$F8) -> 0
A9: 500 Asbury Communities, Inc. | B9: =LEFT(A9,3) -> 500 | C9: 500 Asbury Communities | E9: 2025 | F9: =C9 -> 500 Asbury Communities | G9: =_xlfn.XLOOKUP($A9,OC!$A:$A,OC!B:B) -> 20144995 | H9: =_xlfn.XLOOKUP($A9,OC!$A:$A,OC!C:C) -> 23461764 | I9: Item | J9: ReportingandData/Dashboards/Lists/Entity Operating Ratio Target | K9: =IFERROR(H9/G9,"na") -> 1.1646448 | M9: =G9-SUMIFS('2025 Load-Monthly'!I$5:I$485,'2025 Load-Monthly'!$H$5:$H$485,$F9) -> 0 | N9: =H9-SUMIFS('2025 Load-Monthly'!J$5:J$485,'2025 Load-Monthly'!$H$5:$H$485,$F9) -> 0
A10: 650 Asbury Place Maryville | B10: =LEFT(A10,3) -> 650 | C10: 650 Asbury Place Maryville | E10: 2025 | F10: =C10 -> 650 Asbury Place Maryville | G10: =_xlfn.XLOOKUP($A10,OC!$A:$A,OC!B:B) -> 0 | H10: =_xlfn.XLOOKUP($A10,OC!$A:$A,OC!C:C) -> 0 | I10: Item | J10: ReportingandData/Dashboards/Lists/Entity Operating Ratio Target | K10: =IFERROR(H10/G10,"na") -> na | M10: =G10-SUMIFS('2025 Load-Monthly'!I$5:I$485,'2025 Load-Monthly'!$H$5:$H$485,$F10) -> 0 | N10: =H10-SUMIFS('2025 Load-Monthly'!J$5:J$485,'2025 Load-Monthly'!$H$5:$H$485,$F10) -> 0
A11: 660 Asbury Place Kingsport | B11: =LEFT(A11,3) -> 660 | C11: 660 Asbury Place Kingsport | E11: 2025 | F11: =C11 -> 660 Asbury Place Kingsport | G11: =_xlfn.XLOOKUP($A11,OC!$A:$A,OC!B:B) -> 0 | H11: =_xlfn.XLOOKUP($A11,OC!$A:$A,OC!C:C) -> 0 | I11: Item | J11: ReportingandData/Dashboards/Lists/Entity Operating Ratio Target | K11: =IFERROR(H11/G11,"na") -> na | M11: =G11-SUMIFS('2025 Load-Monthly'!I$5:I$485,'2025 Load-Monthly'!$H$5:$H$485,$F11) -> 0 | N11: =H11-SUMIFS('2025 Load-Monthly'!J$5:J$485,'2025 Load-Monthly'!$H$5:$H$485,$F11) -> 0
A12: 670 Forest Ridge Manor | B12: =LEFT(A12,3) -> 670 | C12: 670 Forest Ridge Manor | E12: 2025 | F12: =C12 -> 670 Forest Ridge Manor | G12: =_xlfn.XLOOKUP($A12,OC!$A:$A,OC!B:B) -> 352442 | H12: =_xlfn.XLOOKUP($A12,OC!$A:$A,OC!C:C) -> 291393 | I12: Item | J12: ReportingandData/Dashboards/Lists/Entity Operating Ratio Target | K12: =IFERROR(H12/G12,"na") -> 0.82678285 | M12: =G12-SUMIFS('2025 Load-Monthly'!I$5:I$485,'2025 Load-Monthly'!$H$5:$H$485,$F12) -> 0 | N12: =H12-SUMIFS('2025 Load-Monthly'!J$5:J$485,'2025 Load-Monthly'!$H$5:$H$485,$F12) -> 0
A13: 716 Asbury Place at Home | B13: =LEFT(A13,3) -> 716 | C13: 716 Asbury Place at Home | E13: 2025 | F13: =C13 -> 716 Asbury Place at Home | G13: =_xlfn.XLOOKUP($A13,OC!$A:$A,OC!B:B) -> 0 | H13: =_xlfn.XLOOKUP($A13,OC!$A:$A,OC!C:C) -> 0 | I13: Item | J13: ReportingandData/Dashboards/Lists/Entity Operating Ratio Target | K13: =IFERROR(H13/G13,"na") -> na | M13: =G13-SUMIFS('2025 Load-Monthly'!I$5:I$485,'2025 Load-Monthly'!$H$5:$H$485,$F13) -> 0 | N13: =H13-SUMIFS('2025 Load-Monthly'!J$5:J$485,'2025 Load-Monthly'!$H$5:$H$485,$F13) -> 0
A14: 810 Bethany Village | B14: =LEFT(A14,3) -> 810 | C14: 810 Bethany Village | E14: 2025 | F14: =C14 -> 810 Bethany Village | G14: =_xlfn.XLOOKUP($A14,OC!$A:$A,OC!B:B) -> 38530793 | H14: =_xlfn.XLOOKUP($A14,OC!$A:$A,OC!C:C) -> 35404572 | I14: Item | J14: ReportingandData/Dashboards/Lists/Entity Operating Ratio Target | K14: =IFERROR(H14/G14,"na") -> 0.91886434 | M14: =G14-SUMIFS('2025 Load-Monthly'!I$5:I$485,'2025 Load-Monthly'!$H$5:$H$485,$F14) -> 0 | N14: =H14-SUMIFS('2025 Load-Monthly'!J$5:J$485,'2025 Load-Monthly'!$H$5:$H$485,$F14) -> 0
A15: 815 Bethany Development | B15: =LEFT(A15,3) -> 815 | C15: 815 Bethany Towers | E15: 2025 | F15: =C15 -> 815 Bethany Towers | G15: =_xlfn.XLOOKUP($A15,OC!$A:$A,OC!B:B) -> 2223918 | H15: =_xlfn.XLOOKUP($A15,OC!$A:$A,OC!C:C) -> 1280355 | I15: Item | J15: ReportingandData/Dashboards/Lists/Entity Operating Ratio Target | K15: =IFERROR(H15/G15,"na") -> 0.57572042 | M15: =G15-SUMIFS('2025 Load-Monthly'!I$5:I$485,'2025 Load-Monthly'!$H$5:$H$485,$F15) -> 0 | N15: =H15-SUMIFS('2025 Load-Monthly'!J$5:J$485,'2025 Load-Monthly'!$H$5:$H$485,$F15) -> 0
A16: 900 The Asbury Group | B16: =LEFT(A16,3) -> 900 | C16: 900 The Asbury Group | E16: 2025 | F16: =C16 -> 900 The Asbury Group | G16: =_xlfn.XLOOKUP($A16,OC!$A:$A,OC!B:B) -> -810916 | H16: =_xlfn.XLOOKUP($A16,OC!$A:$A,OC!C:C) -> 256403.06 | I16: Item | J16: ReportingandData/Dashboards/Lists/Entity Operating Ratio Target | K16: =IFERROR(H16/G16,"na") -> -0.31618942 | M16: =G16-SUMIFS('2025 Load-Monthly'!I$5:I$485,'2025 Load-Monthly'!$H$5:$H$485,$F16) -> 0 | N16: =H16-SUMIFS('2025 Load-Monthly'!J$5:J$485,'2025 Load-Monthly'!$H$5:$H$485,$F16) -> 0
... A43: 360 Ivy Gables | B43: =LEFT(A43,3) -> 360 | C43: 360 Ivy Gables | E43: 2025 | F43: =C43 -> 360 Ivy Gables | G43: =_xlfn.XLOOKUP($A43,OC!$A:$A,OC!B:B) -> 4040214.6 | H43: =_xlfn.XLOOKUP($A43,OC!$A:$A,OC!C:C) -> 4486071.9 | I43: Item | J43: ReportingandData/Dashboards/Lists/Entity Operating Ratio Target | K43: =IFERROR(H43/G43,"na") -> 1.1103548 | M43: =G43-SUMIFS('2025 Load-Monthly'!I$5:I$485,'2025 Load-Monthly'!$H$5:$H$485,$F43) -> 0 | N43: =H43-SUMIFS('2025 Load-Monthly'!J$5:J$485,'2025 Load-Monthly'!$H$5:$H$485,$F43) -> 0
E45: 2025 | F45: Asbury Communities | G45: =SUM(G5:G43) -> 2.4446165e+08 | H45: =SUM(H5:H43) -> 2.3924492e+08 | I45: Item | J45: ReportingandData/Dashboards/Lists/Entity Operating Ratio Target | K45: =IFERROR(H45/G45,"na") -> 0.97866032 | M45: =G45-SUMIFS('2025 Load-Monthly'!I$5:I$485,'2025 Load-Monthly'!$H$5:$H$485,$F45) -> 0 | N45: =H45-SUMIFS('2025 Load-Monthly'!J$5:J$485,'2025 Load-Monthly'!$H$5:$H$485,$F45) -> 0
F47: Check | G47: =G45-SUM(G5:G43) -> 0 | H47: =H45-SUM(H5:H43) -> 0

Sheet 2025 Load-Monthly
A1: Prep | F1: For Qlik Load
A2: text | B2: text | C2: f(x) | D2: f(x) | F2: text | G2: f(x) | H2: f(x) | I2: f(x) | J2: f(x) | K2: text | L2: text | M2: f(x)
D3: 2023 Name Format
A4: OC Name | B4: Month | C4: Ent | D4: Name for Qlik? | F4: Year | G4: Month | H4: Entity | I4: Target Operating Revenue | J4: Target Operating Expenses | K4: Item Type | L4: Path | M4: OR
A5: 100 Asbury Methodist Village | B5: 1 | C5: =LEFT(A5,3) -> 100 | D5: 100 Asbury Methodist Village | F5: 2025 | G5: =B5 -> 1 | H5: =D5 -> 100 Asbury Methodist Village | I5: {=INDEX('OC-Monthly'!$B$7:$N$65,_xlfn.XMATCH($A5,'OC-Monthly'!$A$7:$A$65),_xlfn.XMATCH($B5,'OC-Monthly'!$B$1:$N$1))} -> 7381980.9 | J5: {=INDEX('OC-Monthly'!$P$7:$AB$65,_xlfn.XMATCH($A5,'OC-Monthly'!$A$7:$A$65),_xlfn.XMATCH($B5,'OC-Monthly'!$P$1:$AB$1))} -> 6993133.2 | K5: Item | L5: ReportingandData/Dashboards/Lists/Entity Operating Ratio Target | M5: =IFERROR(J5/I5,"na") -> 0.94732475
A6: 100 Asbury Methodist Village | B6: 2 | C6: =LEFT(A6,3) -> 100 | D6: 100 Asbury Methodist Village | F6: 2025 | G6: =B6 -> 2 | H6: =D6 -> 100 Asbury Methodist Village | I6: {=INDEX('OC-Monthly'!$B$7:$N$65,_xlfn.XMATCH($A6,'OC-Monthly'!$A$7:$A$65),_xlfn.XMATCH($B6,'OC-Monthly'!$B$1:$N$1))} -> 6904590.2 | J6: {=INDEX('OC-Monthly'!$P$7:$AB$65,_xlfn.XMATCH($A6,'OC-Monthly'!$A$7:$A$65),_xlfn.XMATCH($B6,'OC-Monthly'!$P$1:$AB$1))} -> 6702047.3 | K6: Item | L6: ReportingandData/Dashboards/Lists/Entity Operating Ratio Target | M6: =IFERROR(J6/I6,"na") -> 0.97066548
A7: 100 Asbury Methodist Village | B7: 3 | C7: =LEFT(A7,3) -> 100 | D7: 100 Asbury Methodist Village | F7: 2025 | G7: =B7 -> 3 | H7: =D7 -> 100 Asbury Methodist Village | I7: {=INDEX('OC-Monthly'!$B$7:$N$65,_xlfn.XMATCH($A7,'OC-Monthly'!$A$7:$A$65),_xlfn.XMATCH($B7,'OC-Monthly'!$B$1:$N$1))} -> 7429922.9 | J7: {=INDEX('OC-Monthly'!$P$7:$AB$65,_xlfn.XMATCH($A7,'OC-Monthly'!$A$7:$A$65),_xlfn.XMATCH($B7,'OC-Monthly'!$P$1:$AB$1))} -> 7119523.6 | K7: Item | L7: ReportingandData/Dashboards/Lists/Entity Operating Ratio Target | M7: =IFERROR(J7/I7,"na") -> 0.95822308
A8: 100 Asbury Methodist Village | B8: 4 | C8: =LEFT(A8,3) -> 100 | D8: 100 Asbury Methodist Village | F8: 2025 | G8: =B8 -> 4 | H8: =D8 -> 100 Asbury Methodist Village | I8: {=INDEX('OC-Monthly'!$B$7:$N$65,_xlfn.XMATCH($A8,'OC-Monthly'!$A$7:$A$65),_xlfn.XMATCH($B8,'OC-Monthly'!$B$1:$N$1))} -> 7424602.3 | J8: {=INDEX('OC-Monthly'!$P$7:$AB$65,_xlfn.XMATCH($A8,'OC-Monthly'!$A$7:$A$65),_xlfn.XMATCH($B8,'OC-Monthly'!$P$1:$AB$1))} -> 6938577.3 | K8: Item | L8: ReportingandData/Dashboards/Lists/Entity Operating Ratio Target | M8: =IFERROR(J8/I8,"na") -> 0.93453858
A9: 100 Asbury Methodist Village | B9: 5 | C9: =LEFT(A9,3) -> 100 | D9: 100 Asbury Methodist Village | F9: 2025 | G9: =B9 -> 5 | H9: =D9 -> 100 Asbury Methodist Village | I9: {=INDEX('OC-Monthly'!$B$7:$N$65,_xlfn.XMATCH($A9,'OC-Monthly'!$A$7:$A$65),_xlfn.XMATCH($B9,'OC-Monthly'!$B$1:$N$1))} -> 7446333.5 | J9: {=INDEX('OC-Monthly'!$P$7:$AB$65,_xlfn.XMATCH($A9,'OC-Monthly'!$A$7:$A$65),_xlfn.XMATCH($B9,'OC-Monthly'!$P$1:$AB$1))} -> 7054113.8 | K9: Item | L9: ReportingandData/Dashboards/Lists/Entity Operating Ratio Target | M9: =IFERROR(J9/I9,"na") -> 0.94732714
A10: 100 Asbury Methodist Village | B10: 6 | C10: =LEFT(A10,3) -> 100 | D10: 100 Asbury Methodist Village | F10: 2025 | G10: =B10 -> 6 | H10: =D10 -> 100 Asbury Methodist Village | I10: {=INDEX('OC-Monthly'!$B$7:$N$65,_xlfn.XMATCH($A10,'OC-Monthly'!$A$7:$A$65),_xlfn.XMATCH($B10,'OC-Monthly'!$B$1:$N$1))} -> 7396584.4 | J10: {=INDEX('OC-Monthly'!$P$7:$AB$65,_xlfn.XMATCH($A10,'OC-Monthly'!$A$7:$A$65),_xlfn.XMATCH($B10,'OC-Monthly'!$P$1:$AB$1))} -> 7030665.6 | K10: Item | L10: ReportingandData/Dashboards/Lists/Entity Operating Ratio Target | M10: =IFERROR(J10/I10,"na") -> 0.95052868
A11: 100 Asbury Methodist Village | B11: 7 | C11: =LEFT(A11,3) -> 100 | D11: 100 Asbury Methodist Village | F11: 2025 | G11: =B11 -> 7 | H11: =D11 -> 100 Asbury Methodist Village | I11: {=INDEX('OC-Monthly'!$B$7:$N$65,_xlfn.XMATCH($A11,'OC-Monthly'!$A$7:$A$65),_xlfn.XMATCH($B11,'OC-Monthly'!$B$1:$N$1))} -> 7595365.5 | J11: {=INDEX('OC-Monthly'!$P$7:$AB$65,_xlfn.XMATCH($A11,'OC-Monthly'!$A$7:$A$65),_xlfn.XMATCH($B11,'OC-Monthly'!$P$1:$AB$1))} -> 7112593.4 | K11: Item | L11: ReportingandData/Dashboards/Lists/Entity Operating Ratio Target | M11: =IFERROR(J11/I11,"na") -> 0.93643859
A12: 100 Asbury Methodist Village | B12: 8 | C12: =LEFT(A12,3) -> 100 | D12: 100 Asbury Methodist Village | F12: 2025 | G12: =B12 -> 8 | H12: =D12 -> 100 Asbury Methodist Village | I12: {=INDEX('OC-Monthly'!$B$7:$N$65,_xlfn.XMATCH($A12,'OC-Monthly'!$A$7:$A$65),_xlfn.XMATCH($B12,'OC-Monthly'!$B$1:$N$1))} -> 7520910.7 | J12: {=INDEX('OC-Monthly'!$P$7:$AB$65,_xlfn.XMATCH($A12,'OC-Monthly'!$A$7:$A$65),_xlfn.XMATCH($B12,'OC-Monthly'!$P$1:$AB$1))} -> 7105823.6 | K12: Item | L12: ReportingandData/Dashboards/Lists/Entity Operating Ratio Target | M12: =IFERROR(J12/I12,"na") -> 0.94480892
A13: 100 Asbury Methodist Village | B13: 9 | C13: =LEFT(A13,3) -> 100 | D13: 100 Asbury Methodist Village | F13: 2025 | G13: =B13 -> 9 | H13: =D13 -> 100 Asbury Methodist Village | I13: {=INDEX('OC-Monthly'!$B$7:$N$65,_xlfn.XMATCH($A13,'OC-Monthly'!$A$7:$A$65),_xlfn.XMATCH($B13,'OC-Monthly'!$B$1:$N$1))} -> 7448387.7 | J13: {=INDEX('OC-Monthly'!$P$7:$AB$65,_xlfn.XMATCH($A13,'OC-Monthly'!$A$7:$A$65),_xlfn.XMATCH($B13,'OC-Monthly'!$P$1:$AB$1))} -> 7045077.2 | K13: Item | L13: ReportingandData/Dashboards/Lists/Entity Operating Ratio Target | M13: =IFERROR(J13/I13,"na") -> 0.94585265
A14: 100 Asbury Methodist Village | B14: 10 | C14: =LEFT(A14,3) -> 100 | D14: 100 Asbury Methodist Village | F14: 2025 | G14: =B14 -> 10 | H14: =D14 -> 100 Asbury Methodist Village | I14: {=INDEX('OC-Monthly'!$B$7:$N$65,_xlfn.XMATCH($A14,'OC-Monthly'!$A$7:$A$65),_xlfn.XMATCH($B14,'OC-Monthly'!$B$1:$N$1))} -> 7694093.4 | J14: {=INDEX('OC-Monthly'!$P$7:$AB$65,_xlfn.XMATCH($A14,'OC-Monthly'!$A$7:$A$65),_xlfn.XMATCH($B14,'OC-Monthly'!$P$1:$AB$1))} -> 7106093.6 | K14: Item | L14: ReportingandData/Dashboards/Lists/Entity Operating Ratio Target | M14: =IFERROR(J14/I14,"na") -> 0.92357777
A15: 100 Asbury Methodist Village | B15: 11 | C15: =LEFT(A15,3) -> 100 | D15: 100 Asbury Methodist Village | F15: 2025 | G15: =B15 -> 11 | H15: =D15 -> 100 Asbury Methodist Village | I15: {=INDEX('OC-Monthly'!$B$7:$N$65,_xlfn.XMATCH($A15,'OC-Monthly'!$A$7:$A$65),_xlfn.XMATCH($B15,'OC-Monthly'!$B$1:$N$1))} -> 7425387.8 | J15: {=INDEX('OC-Monthly'!$P$7:$AB$65,_xlfn.XMATCH($A15,'OC-Monthly'!$A$7:$A$65),_xlfn.XMATCH($B15,'OC-Monthly'!$P$1:$AB$1))} -> 6927751.3 | K15: Item | L15: ReportingandData/Dashboards/Lists/Entity Operating Ratio Target | M15: =IFERROR(J15/I15,"na") -> 0.93298175
A16: 100 Asbury Methodist Village | B16: 12 | C16: =LEFT(A16,3) -> 100 | D16: 100 Asbury Methodist Village | F16: 2025 | G16: =B16 -> 12 | H16: =D16 -> 100 Asbury Methodist Village | I16: {=INDEX('OC-Monthly'!$B$7:$N$65,_xlfn.XMATCH($A16,'OC-Monthly'!$A$7:$A$65),_xlfn.XMATCH($B16,'OC-Monthly'!$B$1:$N$1))} -> 7620525.4 | J16: {=INDEX('OC-Monthly'!$P$7:$AB$65,_xlfn.XMATCH($A16,'OC-Monthly'!$A$7:$A$65),_xlfn.XMATCH($B16,'OC-Monthly'!$P$1:$AB$1))} -> 7084195.4 | K16: Item | L16: ReportingandData/Dashboards/Lists/Entity Operating Ratio Target | M16: =IFERROR(J16/I16,"na") -> 0.92962034
... A472: 925 Chandler Estate | B472: 12 | C472: =LEFT(A472,3) -> 925 | D472: 925 Chandler Estate | F472: 2025 | G472: =B472 -> 12 | H472: =D472 -> 925 Chandler Estate | I472: {=INDEX('OC-Monthly'!$B$7:$N$65,_xlfn.XMATCH($A472,'OC-Monthly'!$A$7:$A$65),_xlfn.XMATCH($B472,'OC-Monthly'!$B$1:$N$1))} -> 287883.06 | J472: {=INDEX('OC-Monthly'!$P$7:$AB$65,_xlfn.XMATCH($A472,'OC-Monthly'!$A$7:$A$65),_xlfn.XMATCH($B472,'OC-Monthly'!$P$1:$AB$1))} -> 264982.5 | K472: Item | L472: ReportingandData/Dashboards/Lists/Entity Operating Ratio Target | M472: =IFERROR(J472/I472,"na") -> 0.92045186
F474: 2025 | G474: 1 | H474: Asbury Communities | I474: =SUMIFS(I$5:I$472,$G$5:$G$472,$G474) -> 19982277 | J474: =SUMIFS(J$5:J$472,$G$5:$G$472,$G474) -> 20192415 | K474: Item | L474: ReportingandData/Dashboards/Lists/Entity Operating Ratio Target | M474: =IFERROR(J474/I474,"na") -> 1.0105162
F475: 2025 | G475: 2 | H475: Asbury Communities | I475: =SUMIFS(I$5:I$472,$G$5:$G$472,$G475) -> 18937465 | J475: =SUMIFS(J$5:J$472,$G$5:$G$472,$G475) -> 19020105 | K475: Item | L475: ReportingandData/Dashboards/Lists/Entity Operating Ratio Target | M475: =IFERROR(J475/I475,"na") -> 1.0043639
F476: 2025 | G476: 3 | H476: Asbury Communities | I476: =SUMIFS(I$5:I$472,$G$5:$G$472,$G476) -> 20353280 | J476: =SUMIFS(J$5:J$472,$G$5:$G$472,$G476) -> 20043061 | K476: Item | L476: ReportingandData/Dashboards/Lists/Entity Operating Ratio Target | M476: =IFERROR(J476/I476,"na") -> 0.9847583
F477: 2025 | G477: 4 | H477: Asbury Communities | I477: =SUMIFS(I$5:I$472,$G$5:$G$472,$G477) -> 20227290 | J477: =SUMIFS(J$5:J$472,$G$5:$G$472,$G477) -> 19938572 | K477: Item | L477: ReportingandData/Dashboards/Lists/Entity Operating Ratio Target | M477: =IFERROR(J477/I477,"na") -> 0.98572635
F478: 2025 | G478: 5 | H478: Asbury Communities | I478: =SUMIFS(I$5:I$472,$G$5:$G$472,$G478) -> 20270642 | J478: =SUMIFS(J$5:J$472,$G$5:$G$472,$G478) -> 20211385 | K478: Item | L478: ReportingandData/Dashboards/Lists/Entity Operating Ratio Target | M478: =IFERROR(J478/I478,"na") -> 0.99707674
F479: 2025 | G479: 6 | H479: Asbury Communities | I479: =SUMIFS(I$5:I$472,$G$5:$G$472,$G479) -> 20312142 | J479: =SUMIFS(J$5:J$472,$G$5:$G$472,$G479) -> 19707875 | K479: Item | L479: ReportingandData/Dashboards/Lists/Entity Operating Ratio Target | M479: =IFERROR(J479/I479,"na") -> 0.97025092
F480: 2025 | G480: 7 | H480: Asbury Communities | I480: =SUMIFS(I$5:I$472,$G$5:$G$472,$G480) -> 20613811 | J480: =SUMIFS(J$5:J$472,$G$5:$G$472,$G480) -> 20131110 | K480: Item | L480: ReportingandData/Dashboards/Lists/Entity Operating Ratio Target | M480: =IFERROR(J480/I480,"na") -> 0.97658361
F481: 2025 | G481: 8 | H481: Asbury Communities | I481: =SUMIFS(I$5:I$472,$G$5:$G$472,$G481) -> 20571277 | J481: =SUMIFS(J$5:J$472,$G$5:$G$472,$G481) -> 20210643 | K481: Item | L481: ReportingandData/Dashboards/Lists/Entity Operating Ratio Target | M481: =IFERROR(J481/I481,"na") -> 0.98246906
F482: 2025 | G482: 9 | H482: Asbury Communities | I482: =SUMIFS(I$5:I$472,$G$5:$G$472,$G482) -> 20644502 | J482: =SUMIFS(J$5:J$472,$G$5:$G$472,$G482) -> 19735118 | K482: Item | L482: ReportingandData/Dashboards/Lists/Entity Operating Ratio Target | M482: =IFERROR(J482/I482,"na") -> 0.95595032
F483: 2025 | G483: 10 | H483: Asbury Communities | I483: =SUMIFS(I$5:I$472,$G$5:$G$472,$G483) -> 20966178 | J483: =SUMIFS(J$5:J$472,$G$5:$G$472,$G483) -> 20323289 | K483: Item | L483: ReportingandData/Dashboards/Lists/Entity Operating Ratio Target | M483: =IFERROR(J483/I483,"na") -> 0.96933685
F484: 2025 | G484: 11 | H484: Asbury Communities | I484: =SUMIFS(I$5:I$472,$G$5:$G$472,$G484) -> 20483709 | J484: =SUMIFS(J$5:J$472,$G$5:$G$472,$G484) -> 19753326 | K484: Item | L484: ReportingandData/Dashboards/Lists/Entity Operating Ratio Target | M484: =IFERROR(J484/I484,"na") -> 0.9643432
F485: 2025 | G485: 12 | H485: Asbury Communities | I485: =SUMIFS(I$5:I$472,$G$5:$G$472,$G485) -> 21099080 | J485: =SUMIFS(J$5:J$472,$G$5:$G$472,$G485) -> 19978020 | K485: Item | L485: ReportingandData/Dashboards/Lists/Entity Operating Ratio Target | M485: =IFERROR(J485/I485,"na") -> 0.94686689
H488: Check1 | I488: =SUM(I5:I472)-SUM('2025 Load'!G5:G43) -> 0 | J488: =SUM(J5:J472)-SUM('2025 Load'!H5:H43) -> 0
H489: Check2 | I489: =SUM(I474:I485)-'2025 Load'!G45 -> 0 | J489: =SUM(J474:J485)-'2025 Load'!H45 -> 0

Sheet OC
B3: FY2025 | C3: FY2025
B4: Budget 2025 | C4: Budget 2025
B5: Operating Ratio Revenue | C5: Operating Ratio Expenses
B6: Operating_Ratio_Revenue_Metric_New | C6: Operating_Ratio_Expenses_Metric_New
A7: 100 Asbury Methodist Village | B7: 89288685 | C7: 84219595
A8: 200 Asbury Solomons | B8: 22201274 | C8: 20064427
A9: 210 Calvert County Nursing Center | B9: 0 | C9: 0
A10: 324 Springhill | B10: 20835667 | C10: 20625422
A11: 400 Asbury Foundation, Inc. | B11: 791853 | C11: 770786.29
A12: 500 Asbury Communities, Inc. | B12: 20144995 | C12: 23461764
A13: 610 Inverness Village | B13: 0 | C13: 0
A14: 640 Asbury Place Support Center | B14: 0 | C14: 0
A15: 650 Asbury Place Maryville | B15: 0 | C15: 0
A16: 660 Asbury Place Kingsport | B16: 0 | C16: 0
A17: 670 Forest Ridge Manor | B17: 352442 | C17: 291393
A18: 716 Asbury Place at Home | B18: 0 | C18: 0
... A65: 635 MFA Steadman Opco, LLC | B65: 0 | C65: 0

Sheet OC-Monthly
B1: 1 | C1: 2 | D1: 3 | E1: 4 | F1: 5 | G1: 6 | H1: 7 | I1: 8 | J1: 9 | K1: 10 | L1: 11 | M1: 12 | N1: Annual | P1: 1 | Q1: 2 | R1: 3 | S1: 4 | T1: 5 | U1: 6 | V1: 7 | W1: 8 | X1: 9 | Y1: 10 | Z1: 11 | AA1: 12 | AB1: Annual
B2: Operating Ratio Revenue-Month (current+2)-Budget 2025 | C2: Operating Ratio Revenue-Month (current+3)-Budget 2025 | D2: Operating Ratio Revenue-Month (current+4)-Budget 2025 | E2: Operating Ratio Revenue-Month (current+5)-Budget 2025 | F2: Operating Ratio Revenue-Month (current+6)-Budget 2025 | G2: Operating Ratio Revenue-Month (current+7)-Budget 2025 | H2: Operating Ratio Revenue-Month (current+8)-Budget 2025 | I2: Operating Ratio Revenue-Month (current+9)-Budget 2025 | J2: Operating Ratio Revenue-Month (current+10)-Budget 2025 | K2: Operating Ratio Revenue-Month (current+11)-Budget 2025 | L2: Operating Ratio Revenue-Month (current+12)-Budget 2025 | M2: Operating Ratio Revenue-Month (current+13)-Budget 2025 | N2: Year (current+1)-Operating Ratio Revenue-Budget 2025 | P2: Operating Ratio Expenses-Month (current+2)-Budget 2025 | Q2: Operating Ratio Expenses-Month (current+3)-Budget 2025 | R2: Operating Ratio Expenses-Month (current+4)-Budget 2025 | S2: Operating Ratio Expenses-Month (current+5)-Budget 2025 | T2: Operating Ratio Expenses-Month (current+6)-Budget 2025 | U2: Operating Ratio Expenses-Month (current+7)-Budget 2025 | V2: Operating Ratio Expenses-Month (current+8)-Budget 2025 | W2: Operating Ratio Expenses-Month (current+9)-Budget 2025 | X2: Operating Ratio Expenses-Month (current+10)-Budget 2025 | Y2: Operating Ratio Expenses-Month (current+11)-Budget 2025 | Z2: Operating Ratio Expenses-Month (current+12)-Budget 2025 | AA2: Operating Ratio Expenses-Month (current+13)-Budget 2025 | AB2: Year (current+1)-Operating Ratio Expenses-Budget 2025
B3: Budget 2025 | C3: Budget 2025 | D3: Budget 2025 | E3: Budget 2025 | F3: Budget 2025 | G3: Budget 2025 | H3: Budget 2025 | I3: Budget 2025 | J3: Budget 2025 | K3: Budget 2025 | L3: Budget 2025 | M3: Budget 2025 | N3: Budget 2025 | P3: Budget 2025 | Q3: Budget 2025 | R3: Budget 2025 | S3: Budget 2025 | T3: Budget 2025 | U3: Budget 2025 | V3: Budget 2025 | W3: Budget 2025 | X3: Budget 2025 | Y3: Budget 2025 | Z3: Budget 2025 | AA3: Budget 2025 | AB3: Budget 2025
B4: Operating Ratio Revenue | C4: Operating Ratio Revenue | D4: Operating Ratio Revenue | E4: Operating Ratio Revenue | F4: Operating Ratio Revenue | G4: Operating Ratio Revenue | H4: Operating Ratio Revenue | I4: Operating Ratio Revenue | J4: Operating Ratio Revenue | K4: Operating Ratio Revenue | L4: Operating Ratio Revenue | M4: Operating Ratio Revenue | N4: Operating Ratio Revenue | P4: Operating Ratio Expenses | Q4: Operating Ratio Expenses | R4: Operating Ratio Expenses | S4: Operating Ratio Expenses | T4: Operating Ratio Expenses | U4: Operating Ratio Expenses | V4: Operating Ratio Expenses | W4: Operating Ratio Expenses | X4: Operating Ratio Expenses | Y4: Operating Ratio Expenses | Z4: Operating Ratio Expenses | AA4: Operating Ratio Expenses | AB4: Operating Ratio Expenses
B5: Operating_Ratio_Revenue_Metric_New | C5: Operating_Ratio_Revenue_Metric_New | D5: Operating_Ratio_Revenue_Metric_New | E5: Operating_Ratio_Revenue_Metric_New | F5: Operating_Ratio_Revenue_Metric_New | G5: Operating_Ratio_Revenue_Metric_New | H5: Operating_Ratio_Revenue_Metric_New | I5: Operating_Ratio_Revenue_Metric_New | J5: Operating_Ratio_Revenue_Metric_New | K5: Operating_Ratio_Revenue_Metric_New | L5: Operating_Ratio_Revenue_Metric_New | M5: Operating_Ratio_Revenue_Metric_New | N5: Operating_Ratio_Revenue_Metric_New | P5: Operating_Ratio_Expenses_Metric_New | Q5: Operating_Ratio_Expenses_Metric_New | R5: Operating_Ratio_Expenses_Metric_New | S5: Operating_Ratio_Expenses_Metric_New | T5: Operating_Ratio_Expenses_Metric_New | U5: Operating_Ratio_Expenses_Metric_New | V5: Operating_Ratio_Expenses_Metric_New | W5: Operating_Ratio_Expenses_Metric_New | X5: Operating_Ratio_Expenses_Metric_New | Y5: Operating_Ratio_Expenses_Metric_New | Z5: Operating_Ratio_Expenses_Metric_New | AA5: Operating_Ratio_Expenses_Metric_New | AB5: Operating_Ratio_Expenses_Metric_New
B6: Jan-2025 | C6: Feb-2025 | D6: Mar-2025 | E6: Apr-2025 | F6: May-2025 | G6: Jun-2025 | H6: Jul-2025 | I6: Aug-2025 | J6: Sep-2025 | K6: Oct-2025 | L6: Nov-2025 | M6: Dec-2025 | N6: FY2025 | P6: Jan-2025 | Q6: Feb-2025 | R6: Mar-2025 | S6: Apr-2025 | T6: May-2025 | U6: Jun-2025 | V6: Jul-2025 | W6: Aug-2025 | X6: Sep-2025 | Y6: Oct-2025 | Z6: Nov-2025 | AA6: Dec-2025 | AB6: FY2025
A7: 100 Asbury Methodist Village | B7: 7381980.9 | C7: 6904590.2 | D7: 7429922.9 | E7: 7424602.3 | F7: 7446333.5 | G7: 7396584.4 | H7: 7595365.5 | I7: 7520910.7 | J7: 7448387.7 | K7: 7694093.4 | L7: 7425387.8 | M7: 7620525.4 | N7: 89288685 | P7: 6993133.2 | Q7: 6702047.3 | R7: 7119523.6 | S7: 6938577.3 | T7: 7054113.8 | U7: 7030665.6 | V7: 7112593.4 | W7: 7105823.6 | X7: 7045077.2 | Y7: 7106093.6 | Z7: 6927751.3 | AA7: 7084195.4 | AB7: 84219595
A8: 200 Asbury Solomons | B8: 1844823.9 | C8: 1766045 | D8: 1845144.9 | E8: 1851617.4 | F8: 1853627.1 | G8: 1838351.4 | H8: 1872556.2 | I8: 1867430.2 | J8: 1846380.6 | K8: 1892239.3 | L8: 1850180.6 | M8: 1872877.2 | N8: 22201274 | P8: 1708053.3 | Q8: 1586887.6 | R8: 1688150.3 | S8: 1740940.8 | T8: 1678743.8 | U8: 1647167.4 | V8: 1669199.8 | W8: 1678112.9 | X8: 1645394.1 | Y8: 1689450.1 | Z8: 1630651 | AA8: 1701675.9 | AB8: 20064427
A9: 210 Calvert County Nursing Center | B9: 0 | C9: 0 | D9: 0 | E9: 0 | F9: 0 | G9: 0 | H9: 0 | I9: 0 | J9: 0 | K9: 0 | L9: 0 | M9: 0 | N9: 0 | P9: 0 | Q9: 0 | R9: 0 | S9: 0 | T9: 0 | U9: 0 | V9: 0 | W9: 0 | X9: 0 | Y9: 0 | Z9: 0 | AA9: 0 | AB9: 0
A10: 324 Springhill | B10: 1748791.9 | C10: 1635222.6 | D10: 1749235.1 | E10: 1742303.9 | F10: 1752793.7 | G10: 1717311.9 | H10: 1760603.6 | I10: 1758231.2 | J10: 1723403.5 | K10: 1765575.6 | L10: 1721899.5 | M10: 1760294.8 | N10: 20835667 | P10: 1756903 | Q10: 1633260.7 | R10: 1755568.3 | S10: 1703734.8 | T10: 1724704.9 | U10: 1724033.8 | V10: 1724097.2 | W10: 1710088.7 | X10: 1743260.6 | Y10: 1720062 | Z10: 1704948.1 | AA10: 1724759.9 | AB10: 20625422
A11: 400 Asbury Foundation, Inc. | B11: 35474.884 | C11: 59973.685 | D11: 147474.27 | E11: 14620.277 | F11: 24828.067 | G11: 134609.65 | H11: 10069.453 | I11: 27632.427 | J11: 192182.44 | K11: 10007.638 | L11: 23066.418 | M11: 111913.78 | N11: 791853 | P11: 56252.842 | Q11: 54596.282 | R11: 58314.522 | S11: 64948.612 | T11: 60754.522 | U11: 57427.612 | V11: 62104.022 | W11: 66188.342 | X11: 103578.86 | Y11: 63600.022 | Z11: 58452.612 | AA11: 64568.042 | AB11: 770786.29
A12: 500 Asbury Communities, Inc. | B12: 1676489 | C12: 1670325 | D12: 1679439 | E12: 1692824 | F12: 1675913 | G12: 1683439 | H12: 1682989 | I12: 1675825 | J12: 1681439 | K12: 1678961 | L12: 1670413 | M12: 1676939 | N12: 20144995 | P12: 1997369.2 | Q12: 1852131.9 | R12: 1954143.1 | S12: 1966593.5 | T12: 2098029.6 | U12: 1917468 | V12: 1991042.4 | W12: 1992841.4 | X12: 1892249.4 | Y12: 2024939 | Z12: 1862936.5 | AA12: 1912020.2 | AB12: 23461764
A13: 610 Inverness Village | B13: 0 | C13: 0 | D13: 0 | E13: 0 | F13: 0 | G13: 0 | H13: 0 | I13: 0 | J13: 0 | K13: 0 | L13: 0 | M13: 0 | N13: 0 | P13: 0 | Q13: 0 | R13: 0 | S13: 0 | T13: 0 | U13: 0 | V13: 0 | W13: 0 | X13: 0 | Y13: 0 | Z13: 0 | AA13: 0 | AB13: 0
A14: 640 Asbury Place Support Center | B14: 0 | C14: 0 | D14: 0 | E14: 0 | F14: 0 | G14: 0 | H14: 0 | I14: 0 | J14: 0 | K14: 0 | L14: 0 | M14: 0 | N14: 0 | P14: 0 | Q14: 0 | R14: 0 | S14: 0 | T14: 0 | U14: 0 | V14: 0 | W14: 0 | X14: 0 | Y14: 0 | Z14: 0 | AA14: 0 | AB14: 0
A15: 650 Asbury Place Maryville | B15: 0 | C15: 0 | D15: 0 | E15: 0 | F15: 0 | G15: 0 | H15: 0 | I15: 0 | J15: 0 | K15: 0 | L15: 0 | M15: 0 | N15: 0 | P15: 0 | Q15: 0 | R15: 0 | S15: 0 | T15: 0 | U15: 0 | V15: 0 | W15: 0 | X15: 0 | Y15: 0 | Z15: 0 | AA15: 0 | AB15: 0
A16: 660 Asbury Place Kingsport | B16: 0 | C16: 0 | D16: 0 | E16: 0 | F16: 0 | G16: 0 | H16: 0 | I16: 0 | J16: 0 | K16: 0 | L16: 0 | M16: 0 | N16: 0 | P16: 0 | Q16: 0 | R16: 0 | S16: 0 | T16: 0 | U16: 0 | V16: 0 | W16: 0 | X16: 0 | Y16: 0 | Z16: 0 | AA16: 0 | AB16: 0
A17: 670 Forest Ridge Manor | B17: 29370.167 | C17: 29370.167 | D17: 29370.167 | E17: 29370.167 | F17: 29370.167 | G17: 29370.167 | H17: 29370.167 | I17: 29370.167 | J17: 29370.167 | K17: 29370.167 | L17: 29370.167 | M17: 29370.167 | N17: 352442 | P17: 24282.75 | Q17: 24282.75 | R17: 24282.75 | S17: 24282.75 | T17: 24282.75 | U17: 24282.75 | V17: 24282.75 | W17: 24282.75 | X17: 24282.75 | Y17: 24282.75 | Z17: 24282.75 | AA17: 24282.75 | AB17: 291393
A18: 716 Asbury Place at Home | B18: 0 | C18: 0 | D18: 0 | E18: 0 | F18: 0 | G18: 0 | H18: 0 | I18: 0 | J18: 0 | K18: 0 | L18: 0 | M18: 0 | N18: 0 | P18: 0 | Q18: 0 | R18: 0 | S18: 0 | T18: 0 | U18: 0 | V18: 0 | W18: 0 | X18: 0 | Y18: 0 | Z18: 0 | AA18: 0 | AB18: 0
... A65: 635 MFA Steadman Opco, LLC | B65: 0 | C65: 0 | D65: 0 | E65: 0 | F65: 0 | G65: 0 | H65: 0 | I65: 0 | J65: 0 | K65: 0 | L65: 0 | M65: 0 | N65: 0 | P65: 0 | Q65: 0 | R65: 0 | S65: 0 | T65: 0 | U65: 0 | V65: 0 | W65: 0 | X65: 0 | Y65: 0 | Z65: 0 | AA65: 0 | AB65: 0

Sheet OC-Expand
B3: FY2024 | C3: FY2024
B4: Budget 2024 | C4: Budget 2024
B5: Operating Ratio Revenue (New) | C5: Operating Ratio Expenses (New)
B6: Operating_Ratio_Revenue_Metric_New | C6: Operating_Ratio_Expenses_Metric_New
A7: Asbury Communities (Consolidated) | B7: 0 | C7: 0
A8: 100 Asbury Methodist Village | B8: 86330003 | C8: 82361701
A9: 200 Asbury Solomons | B9: 21711006 | C9: 19911453
A10: 324 Springhill | B10: 19839419 | C10: 20055198
A11: 350 Grace Park | B11: 5728998.9 | C11: 4412622.3
A12: 360 Ivy Gables | B12: 3420164.2 | C12: 3815932.4
A13: 400 Asbury Foundation, Inc. | B13: 769971.38 | C13: 743635.44
A14: 500 Asbury Communities, Inc. | B14: 22122239 | C14: 23402190
A15: 610 Inverness Village | B15: 0 | C15: 0
A16: 640 Asbury Place Support Center | B16: 0 | C16: 0
A17: 650 Asbury Place Maryville | B17: 0 | C17: 0
A18: 660 Asbury Place Kingsport | B18: 0 | C18: 0
... A72: 360 Ivy Gables | B72: 3420164.2 | C72: 3815932.4
